Workbook

Sheet INPUT DAFTAR PESERTA
A1: PROGRAM STUDI : TEKNIK ELEKTRO
A2: NO | B2: NIM | C2: Nama | E2: WORKSHEET TEMPLATE
A3: 1 | B3: 2409076001 | C3: Muhammad Jodika | E3: SISTEM PENILAIAN PRAKTIKUM
A4: 2 | B4: 2409076002 | C4: Muhammad Rifqi Maulana | E4: LABORATORIUM ELEKTRO DASAR
A5: 3 | B5: 2409076003 | C5: Andhika Pratama
A6: 4 | B6: 2409076004 | C6: Nur Aqmarina
A7: 5 | B7: 2409076005 | C7: Rias Prihatanto
A8: 6 | B8: 2409076006 | C8: Muhammad Maulana Bhagaskara
A9: 7 | B9: 2409076007 | C9: Chelsi Kamera
A10: 8 | B10: 2409076008 | C10: Riyan Maulana
A11: 9 | B11: 2409076009 | C11: Dimas Prasetyo Wibowo | E11: VER 2 (April 2025)
A12: 10 | B12: 2409076010 | C12: Najwa Dwi Maylani
A13: 11 | B13: 2409076011 | C13: Surya Ardhian Mokodongan
A14: 12 | B14: 2409076012 | C14: Ahmad Irfani Ananda Putra Hariawan | E14: Petunjuk Penggunaan Template
A15: 13 | B15: 2409076013 | C15: Afif Rizqi Ramadhan
A16: 14 | B16: 2409076014 | C16: Julius Simamora | E16: 1. Isikan daftar peserta praktikum pada sheet "INPUT DAFTAR PESERTA"
A17: 15 | B17: 2409076015 | C17: Gea Novtry | E17: (Disarankan untuk menyesuaikan dengan template disamping)
A18: 16 | B18: 2409076016 | C18: Najmi habibi | E18: 2. Isian Nama dan NIM pada sheet selanjutnya akan terinput secara otomatis sesuai dengan isian sheet "INPUT DAFTAR PESERTA"
A19: 17 | B19: 2409076017 | C19: Muhammad Reza Aulia | E19: 3. Nilai praktikum diisikan pada sheet "PENULISAN LAPORAN", "LAPORAN RESMI", "KEMAMPUAN PRAKTIKUM dan "NILAI HARIAN"
A20: 18 | B20: 2409076018 | C20: Omar maulana ibnu rahman | E20: 4. Rekapitulasi nilai praktikum permodul akan terakumulasi secara otomatis pada sheet "NILAI AKHIR" dan PIE-CHART"
A21: 19 | B21: 2409076019 | C21: F. Agung Setyawan. L | E21: 5. Perubahan formula pada sistem menyesuaikan dengan aturan dan SOP terbaru penilaian praktikum Lab Elektro Dasar
A22: 20 | B22: 2409076020 | C22: Muhammad Rafi Ramadhan | E22: 6. Link akses Surat Keterangan Lulus Praktikum sebagai berikut:
A23: 21 | B23: 2409076021 | C23: Farras Alwan Putra Setyo | E23: 7. Link akses Sheet perkomponen sebagai berikut:
A24: 22 | B24: 2409076022 | C24: Dewo Dzaki | E24: Penulisan Laporan
A25: 23 | B25: 2409076023 | C25: Yusr Gavrila | E25: Laporan Resmi
A26: 24 | B26: 2409076025 | C26: Fahrizal Prasetya | E26: Kemampuan Praktikum
A27: 25 | B27: 2409076026 | C27: Ariya Kema Maulana | E27: Nilai Harian
... A29: 27 | B29: 2409076028 | C29: Carlos Immanuel Simanjuntak | E29: Pie Chart
A30: 28 | B30: 2409076029 | C30: Ardhian Arif Ananda
A31: 29 | B31: 2409076030 | C31: Ahmad Fikri Tri Utomo
A32: 30 | B32: 2409076031 | C32: Muhammad Alfin Alfanfa
A33: 31 | B33: 2409076032 | C33: Faizal Haqi
A34: 32 | B34: 2409076033 | C34: Joinicius Pasalin
A35: 33 | B35: 2409076034 | C35: Alwi Rudiansyah
A36: 34 | B36: 2409076035 | C36: Muhammad Rizki Nauval Alim
A37: 35 | B37: 2409076036 | C37: Muhammad Rico Setiawan
A38: 36 | B38: 2409076037 | C38: Muhammad Ananda Ryan Nur Rahman
A39: 37 | B39: 2409076038 | C39: Muhammad Alif Rahmat Syakir
A40: 38 | B40: 2409076039 | C40: Christopher Mahesa Aditama
A41: 39 | B41: 2409076040 | C41: Muhammad Rafli Ramadhani
...

Sheet LAPORAN RESMI
A3: NO | B3: NIM | C3: NAMA | D3: Laporan Resmi | J3: Rata-rata
D4: Modul 1 | E4: Modul 2 | F4: Modul 3 | G4: Modul 4 | H4: Modul 5 | I4: Modul 6
A5: ='INPUT DAFTAR PESERTA'!A3 -> 1 | B5: ='INPUT DAFTAR PESERTA'!B3 -> 2409076001 | C5: ='INPUT DAFTAR PESERTA'!C3 -> Muhammad Jodika | D5: 89 | E5: 90 | F5: 96 | G5: 90 | H5: 95 | I5: 100 | J5: =(D5+E5+F5+G5+H5+I5)/6 -> 93.333333
A6: ='INPUT DAFTAR PESERTA'!A4 -> 2 | B6: ='INPUT DAFTAR PESERTA'!B4 -> 2409076002 | C6: ='INPUT DAFTAR PESERTA'!C4 -> Muhammad Rifqi Maulana | D6: 82.5 | E6: 92 | F6: 90 | G6: 89 | H6: 85 | I6: 89 | J6: =(D6+E6+F6+G6+H6+I6)/6 -> 87.916667
A7: ='INPUT DAFTAR PESERTA'!A5 -> 3 | B7: ='INPUT DAFTAR PESERTA'!B5 -> 2409076003 | C7: ='INPUT DAFTAR PESERTA'!C5 -> Andhika Pratama | D7: 84 | E7: 72 | F7: 90 | G7: 80 | H7: 85 | I7: 55 | J7: =(D7+E7+F7+G7+H7+I7)/6 -> 77.666667
A8: ='INPUT DAFTAR PESERTA'!A6 -> 4 | B8: ='INPUT DAFTAR PESERTA'!B6 -> 2409076004 | C8: ='INPUT DAFTAR PESERTA'!C6 -> Nur Aqmarina | D8: 89 | E8: 91 | F8: 94 | G8: 95 | H8: 90 | I8: 96 | J8: =(D8+E8+F8+G8+H8+I8)/6 -> 92.5
A9: ='INPUT DAFTAR PESERTA'!A7 -> 5 | B9: ='INPUT DAFTAR PESERTA'!B7 -> 2409076005 | C9: ='INPUT DAFTAR PESERTA'!C7 -> Rias Prihatanto | D9: 91 | E9: 89 | F9: 94 | G9: 93 | H9: 90 | I9: 100 | J9: =(D9+E9+F9+G9+H9+I9)/6 -> 92.833333
A10: ='INPUT DAFTAR PESERTA'!A8 -> 6 | B10: ='INPUT DAFTAR PESERTA'!B8 -> 2409076006 | C10: ='INPUT DAFTAR PESERTA'!C8 -> Muhammad Maulana Bhagaskara | D10: 90 | E10: 92 | F10: 94 | G10: 95 | H10: 90 | I10: 92 | J10: =(D10+E10+F10+G10+H10+I10)/6 -> 92.166667
A11: ='INPUT DAFTAR PESERTA'!A9 -> 7 | B11: ='INPUT DAFTAR PESERTA'!B9 -> 2409076007 | C11: ='INPUT DAFTAR PESERTA'!C9 -> Chelsi Kamera | D11: 89.5 | E11: 93 | F11: 94 | G11: 96 | H11: 90 | I11: 96 | J11: =(D11+E11+F11+G11+H11+I11)/6 -> 93.083333
A12: ='INPUT DAFTAR PESERTA'!A10 -> 8 | B12: ='INPUT DAFTAR PESERTA'!B10 -> 2409076008 | C12: ='INPUT DAFTAR PESERTA'!C10 -> Riyan Maulana | D12: 89 | E12: 87 | F12: 94 | G12: 84 | H12: 85 | I12: 91 | J12: =(D12+E12+F12+G12+H12+I12)/6 -> 88.333333
A13: ='INPUT DAFTAR PESERTA'!A11 -> 9 | B13: ='INPUT DAFTAR PESERTA'!B11 -> 2409076009 | C13: ='INPUT DAFTAR PESERTA'!C11 -> Dimas Prasetyo Wibowo | D13: 92 | E13: 91 | F13: 94 | G13: 92 | H13: 90 | I13: 89 | J13: =(D13+E13+F13+G13+H13+I13)/6 -> 91.333333
A14: ='INPUT DAFTAR PESERTA'!A12 -> 10 | B14: ='INPUT DAFTAR PESERTA'!B12 -> 2409076010 | C14: ='INPUT DAFTAR PESERTA'!C12 -> Najwa Dwi Maylani | D14: 91 | E14: 92 | F14: 94 | G14: 89 | H14: 90 | I14: 92 | J14: =(D14+E14+F14+G14+H14+I14)/6 -> 91.333333
A15: ='INPUT DAFTAR PESERTA'!A13 -> 11 | B15: ='INPUT DAFTAR PESERTA'!B13 -> 2409076011 | C15: ='INPUT DAFTAR PESERTA'!C13 -> Surya Ardhian Mokodongan | D15: 91 | E15: 89 | F15: 94 | G15: 80 | H15: 95 | I15: 92 | J15: =(D15+E15+F15+G15+H15+I15)/6 -> 90.166667
A16: ='INPUT DAFTAR PESERTA'!A14 -> 12 | B16: ='INPUT DAFTAR PESERTA'!B14 -> 2409076012 | C16: ='INPUT DAFTAR PESERTA'!C14 -> Ahmad Irfani Ananda Putra Hariawan | D16: 89.5 | E16: 92 | F16: 92 | G16: 85 | H16: 80 | I16: 86 | J16: =(D16+E16+F16+G16+H16+I16)/6 -> 87.416667
... A38: ='INPUT DAFTAR PESERTA'!A36 -> 34 | B38: ='INPUT DAFTAR PESERTA'!B36 -> 2409076035 | C38: ='INPUT DAFTAR PESERTA'!C36 -> Muhammad Rizki Nauval Alim | D38: 90 | E38: 91 | F38: 94 | G38: 90 | H38: 90 | I38: 92 | J38: =(D38+E38+F38+G38+H38+I38)/6 -> 91.166667
A39: ='INPUT DAFTAR PESERTA'!A37 -> 35 | B39: ='INPUT DAFTAR PESERTA'!B37 -> 2409076036 | C39: ='INPUT DAFTAR PESERTA'!C37 -> Muhammad Rico Setiawan | J39: =(D39+E39+F39+G39+H39+I39)/6 -> 0
A40: ='INPUT DAFTAR PESERTA'!A38 -> 36 | B40: ='INPUT DAFTAR PESERTA'!B38 -> 2409076037 | C40: ='INPUT DAFTAR PESERTA'!C38 -> Muhammad Ananda Ryan Nur Rahman | D40: 92.5 | E40: 80 | F40: 70 | G40: 73 | H40: 20 | I40: 40 | J40: =(D40+E40+F40+G40+H40+I40)/6 -> 62.583333
A41: ='INPUT DAFTAR PESERTA'!A39 -> 37 | B41: ='INPUT DAFTAR PESERTA'!B39 -> 2409076038 | C41: ='INPUT DAFTAR PESERTA'!C39 -> Muhammad Alif Rahmat Syakir | J41: =(D41+E41+F41+G41+H41+I41)/6 -> 0
A42: ='INPUT DAFTAR PESERTA'!A40 -> 38 | B42: ='INPUT DAFTAR PESERTA'!B40 -> 2409076039 | C42: ='INPUT DAFTAR PESERTA'!C40 -> Christopher Mahesa Aditama | D42: 86.5 | E42: 93 | F42: 93 | G42: 93 | H42: 90 | I42: 95 | J42: =(D42+E42+F42+G42+H42+I42)/6 -> 91.75
A43: ='INPUT DAFTAR PESERTA'!A41 -> 39 | B43: ='INPUT DAFTAR PESERTA'!B41 -> 2409076040 | C43: ='INPUT DAFTAR PESERTA'!C41 -> Muhammad Rafli Ramadhani | D43: 91.5 | E43: 91 | F43: 93 | G43: 93 | H43: 98 | I43: 91 | J43: =(D43+E43+F43+G43+H43+I43)/6 -> 92.916667
A44: ='INPUT DAFTAR PESERTA'!A42 -> 40 | B44: ='INPUT DAFTAR PESERTA'!B42 -> 2409076041 | C44: ='INPUT DAFTAR PESERTA'!C42 -> Muhammad Rindhan Amarna | D44: 88.5 | E44: 92 | F44: 90 | G44: 95 | H44: 95 | I44: 72 | J44: =(D44+E44+F44+G44+H44+I44)/6 -> 88.75
A45: ='INPUT DAFTAR PESERTA'!A43 -> 41 | B45: ='INPUT DAFTAR PESERTA'!B43 -> 2409076043 | C45: ='INPUT DAFTAR PESERTA'!C43 -> Bima Angga Pratama | J45: =(D45+E45+F45+G45+H45+I45)/6 -> 0
A46: ='INPUT DAFTAR PESERTA'!A44 -> 42 | B46: ='INPUT DAFTAR PESERTA'!B44 -> 2409076044 | C46: ='INPUT DAFTAR PESERTA'!C44 -> Muhammad Daffa Dzakwan | D46: 85.5 | E46: 91 | F46: 94 | G46: 87 | H46: 90 | I46: 0 | J46: =(D46+E46+F46+G46+H46+I46)/6 -> 74.583333
A47: ='INPUT DAFTAR PESERTA'!A45 -> 43 | B47: ='INPUT DAFTAR PESERTA'!B45 -> 2409076045 | C47: ='INPUT DAFTAR PESERTA'!C45 -> Ahmad Purwono Aji | D47: 84.5 | E47: 59 | F47: 80 | G47: 60 | H47: 20 | I47: 0 | J47: =(D47+E47+F47+G47+H47+I47)/6 -> 50.583333
A48: ='INPUT DAFTAR PESERTA'!A46 -> 44 | B48: ='INPUT DAFTAR PESERTA'!B46 -> 2409076046 | C48: ='INPUT DAFTAR PESERTA'!C46 -> Muhammad Hasan Hanif | D48: 0 | E48: 60 | F48: 70 | G48: 60 | H48: 20 | I48: 0 | J48: =(D48+E48+F48+G48+H48+I48)/6 -> 35
A49: ='INPUT DAFTAR PESERTA'!A47 -> 45 | B49: ='INPUT DAFTAR PESERTA'!B47 -> 2409076047 | C49: ='INPUT DAFTAR PESERTA'!C47 -> Gilbert Pasolon | D49: 91 | E49: 91 | F49: 94 | G49: 83 | H49: 88 | I49: 0 | J49: =(D49+E49+F49+G49+H49+I49)/6 -> 74.5
A50: ='INPUT DAFTAR PESERTA'!A48 -> 46 | B50: ='INPUT DAFTAR PESERTA'!B48 -> 2409076048 | C50: ='INPUT DAFTAR PESERTA'!C48 -> Achmad Fauzan At-Tamimi | D50: 88 | E50: 90 | F50: 94 | G50: 95 | H50: 95 | I50: 91 | J50: =(D50+E50+F50+G50+H50+I50)/6 -> 92.166667
A51: ='INPUT DAFTAR PESERTA'!A49 -> 47 | B51: ='INPUT DAFTAR PESERTA'!B49 -> 2409076049 | C51: ='INPUT DAFTAR PESERTA'!C49 -> Mahmud Abdul Aziz Qoby | D51: 84 | E51: 88 | F51: 90 | G51: 78 | H51: 20 | I51: 90 | J51: =(D51+E51+F51+G51+H51+I51)/6 -> 75
A52: ='INPUT DAFTAR PESERTA'!A50 -> 48 | B52: ='INPUT DAFTAR PESERTA'!B50 -> 2409076050 | C52: ='INPUT DAFTAR PESERTA'!C50 -> Gde Nookie Carl Arya Susila | D52: 88 | E52: 90 | F52: 94 | G52: 87 | H52: 95 | I52: 95 | J52: =(D52+E52+F52+G52+H52+I52)/6 -> 91.5
A53: ='INPUT DAFTAR PESERTA'!A51 -> 49 | B53: ='INPUT DAFTAR PESERTA'!B51 -> 2409076051 | C53: ='INPUT DAFTAR PESERTA'!C51 -> Muhammad Afrizal | J53: =(D53+E53+F53+G53+H53+I53)/6 -> 0
A54: ='INPUT DAFTAR PESERTA'!A52 -> 50 | B54: ='INPUT DAFTAR PESERTA'!B52 -> 2409076052 | C54: ='INPUT DAFTAR PESERTA'!C52 -> Rezky Yutabse | D54: 89.5 | E54: 92 | F54: 90 | G54: 86 | H54: 85 | I54: 85 | J54: =(D54+E54+F54+G54+H54+I54)/6 -> 87.916667
A55: ='INPUT DAFTAR PESERTA'!A53 -> 51 | B55: ='INPUT DAFTAR PESERTA'!B53 -> 2409076053 | C55: ='INPUT DAFTAR PESERTA'!C53 -> Dimas Wijaya Muliangto | D55: 88.5 | E55: 84 | F55: 90 | G55: 83 | H55: 90 | I55: 65 | J55: =(D55+E55+F55+G55+H55+I55)/6 -> 83.416667
A56: ='INPUT DAFTAR PESERTA'!A54 -> 52 | B56: ='INPUT DAFTAR PESERTA'!B54 -> 2409076054 | C56: ='INPUT DAFTAR PESERTA'!C54 -> Muhammad Aldi | D56: 91 | E56: 88 | F56: 94 | G56: 84 | H56: 90 | I56: 87 | J56: =(D56+E56+F56+G56+H56+I56)/6 -> 89
A57: ='INPUT DAFTAR PESERTA'!A55 -> 53 | B57: ='INPUT DAFTAR PESERTA'!B55 -> 2409076056 | C57: ='INPUT DAFTAR PESERTA'!C55 -> Rivaldy Paredanun | D57: 72 | E57: 75 | F57: 60 | G57: 71 | H57: 20 | I57: 22 | J57: =(D57+E57+F57+G57+H57+I57)/6 -> 53.333333
A58: ='INPUT DAFTAR PESERTA'!A56 -> 54 | B58: ='INPUT DAFTAR PESERTA'!B56 -> 2409076024 | C58: ='INPUT DAFTAR PESERTA'!C56 -> Muhammad Zacky | D58: 90.5 | E58: 92 | F58: 94 | G58: 89 | H58: 90 | I58: 97 | J58: =(D58+E58+F58+G58+H58+I58)/6 -> 92.083333

Sheet PENULISAN LAPORAN
A1: HOME
A3: NO | B3: NIM | C3: NAMA | D3: Laporan Mingguan | J3: Rata-rata | K3: Resmi | L3: Nilai Akhir
D4: Modul 1 | E4: Modul 2 | F4: Modul 3 | G4: Modul 4 | H4: Modul 5 | I4: Modul 6 | J4: 0.5 | K4: 0.5
A5: ='INPUT DAFTAR PESERTA'!A3 -> 1 | B5: ='INPUT DAFTAR PESERTA'!B3 -> 2409076001 | C5: ='INPUT DAFTAR PESERTA'!C3 -> Muhammad Jodika | D5: 86 | E5: 83 | F5: 96 | G5: 90 | H5: 90 | I5: 91 | J5: =(D5+E5+F5+G5+H5+I5)/6 -> 89.333333 | K5: ='LAPORAN RESMI'!J5 -> 93.333333 | L5: =(J5*$J$4)+(K5*$K$4) -> 91.333333
A6: ='INPUT DAFTAR PESERTA'!A4 -> 2 | B6: ='INPUT DAFTAR PESERTA'!B4 -> 2409076002 | C6: ='INPUT DAFTAR PESERTA'!C4 -> Muhammad Rifqi Maulana | D6: 64 | E6: 75 | F6: 80 | G6: 80 | H6: 72 | I6: 63 | J6: =(D6+E6+F6+G6+H6+I6)/6 -> 72.333333 | K6: ='LAPORAN RESMI'!J6 -> 87.916667 | L6: =(J6*$J$4)+(K6*$K$4) -> 80.125
A7: ='INPUT DAFTAR PESERTA'!A5 -> 3 | B7: ='INPUT DAFTAR PESERTA'!B5 -> 2409076003 | C7: ='INPUT DAFTAR PESERTA'!C5 -> Andhika Pratama | D7: 72 | E7: 40 | F7: 63 | G7: 80 | H7: 57 | I7: 55 | J7: =(D7+E7+F7+G7+H7+I7)/6 -> 61.166667 | K7: ='LAPORAN RESMI'!J7 -> 77.666667 | L7: =(J7*$J$4)+(K7*$K$4) -> 69.416667
A8: ='INPUT DAFTAR PESERTA'!A6 -> 4 | B8: ='INPUT DAFTAR PESERTA'!B6 -> 2409076004 | C8: ='INPUT DAFTAR PESERTA'!C6 -> Nur Aqmarina | D8: 89 | E8: 59 | F8: 92 | G8: 87 | H8: 88 | I8: 81 | J8: =(D8+E8+F8+G8+H8+I8)/6 -> 82.666667 | K8: ='LAPORAN RESMI'!J8 -> 92.5 | L8: =(J8*$J$4)+(K8*$K$4) -> 87.583333
A9: ='INPUT DAFTAR PESERTA'!A7 -> 5 | B9: ='INPUT DAFTAR PESERTA'!B7 -> 2409076005 | C9: ='INPUT DAFTAR PESERTA'!C7 -> Rias Prihatanto | D9: 91 | E9: 50 | F9: 94 | G9: 89 | H9: 72 | I9: 95 | J9: =(D9+E9+F9+G9+H9+I9)/6 -> 81.833333 | K9: ='LAPORAN RESMI'!J9 -> 92.833333 | L9: =(J9*$J$4)+(K9*$K$4) -> 87.333333
A10: ='INPUT DAFTAR PESERTA'!A8 -> 6 | B10: ='INPUT DAFTAR PESERTA'!B8 -> 2409076006 | C10: ='INPUT DAFTAR PESERTA'!C8 -> Muhammad Maulana Bhagaskara | D10: 78 | E10: 77 | F10: 84 | G10: 86 | H10: 71 | I10: 72.5 | J10: =(D10+E10+F10+G10+H10+I10)/6 -> 78.083333 | K10: ='LAPORAN RESMI'!J10 -> 92.166667 | L10: =(J10*$J$4)+(K10*$K$4) -> 85.125
A11: ='INPUT DAFTAR PESERTA'!A9 -> 7 | B11: ='INPUT DAFTAR PESERTA'!B9 -> 2409076007 | C11: ='INPUT DAFTAR PESERTA'!C9 -> Chelsi Kamera | D11: 87 | E11: 75 | F11: 85 | G11: 88 | H11: 73 | I11: 89.5 | J11: =(D11+E11+F11+G11+H11+I11)/6 -> 82.916667 | K11: ='LAPORAN RESMI'!J11 -> 93.083333 | L11: =(J11*$J$4)+(K11*$K$4) -> 88
A12: ='INPUT DAFTAR PESERTA'!A10 -> 8 | B12: ='INPUT DAFTAR PESERTA'!B10 -> 2409076008 | C12: ='INPUT DAFTAR PESERTA'!C10 -> Riyan Maulana | D12: 41.5 | E12: 26 | F12: 88 | G12: 84 | H12: 87 | I12: 53 | J12: =(D12+E12+F12+G12+H12+I12)/6 -> 63.25 | K12: ='LAPORAN RESMI'!J12 -> 88.333333 | L12: =(J12*$J$4)+(K12*$K$4) -> 75.791667
A13: ='INPUT DAFTAR PESERTA'!A11 -> 9 | B13: ='INPUT DAFTAR PESERTA'!B11 -> 2409076009 | C13: ='INPUT DAFTAR PESERTA'!C11 -> Dimas Prasetyo Wibowo | D13: 81 | E13: 71 | F13: 71 | G13: 87 | H13: 66 | I13: 75.5 | J13: =(D13+E13+F13+G13+H13+I13)/6 -> 75.25 | K13: ='LAPORAN RESMI'!J13 -> 91.333333 | L13: =(J13*$J$4)+(K13*$K$4) -> 83.291667
A14: ='INPUT DAFTAR PESERTA'!A12 -> 10 | B14: ='INPUT DAFTAR PESERTA'!B12 -> 2409076010 | C14: ='INPUT DAFTAR PESERTA'!C12 -> Najwa Dwi Maylani | D14: 86.5 | E14: 71 | F14: 77 | G14: 92 | H14: 66 | I14: 81 | J14: =(D14+E14+F14+G14+H14+I14)/6 -> 78.916667 | K14: ='LAPORAN RESMI'!J14 -> 91.333333 | L14: =(J14*$J$4)+(K14*$K$4) -> 85.125
A15: ='INPUT DAFTAR PESERTA'!A13 -> 11 | B15: ='INPUT DAFTAR PESERTA'!B13 -> 2409076011 | C15: ='INPUT DAFTAR PESERTA'!C13 -> Surya Ardhian Mokodongan | D15: 91 | E15: 86 | F15: 86 | G15: 69 | H15: 76 | I15: 73.5 | J15: =(D15+E15+F15+G15+H15+I15)/6 -> 80.25 | K15: ='LAPORAN RESMI'!J15 -> 90.166667 | L15: =(J15*$J$4)+(K15*$K$4) -> 85.208333
A16: ='INPUT DAFTAR PESERTA'!A14 -> 12 | B16: ='INPUT DAFTAR PESERTA'!B14 -> 2409076012 | C16: ='INPUT DAFTAR PESERTA'!C14 -> Ahmad Irfani Ananda Putra Hariawan | D16: 80.5 | E16: 84 | F16: 72 | G16: 69 | H16: 72 | I16: 60 | J16: =(D16+E16+F16+G16+H16+I16)/6 -> 72.916667 | K16: ='LAPORAN RESMI'!J16 -> 87.416667 | L16: =(J16*$J$4)+(K16*$K$4) -> 80.166667
... A38: ='INPUT DAFTAR PESERTA'!A36 -> 34 | B38: ='INPUT DAFTAR PESERTA'!B36 -> 2409076035 | C38: ='INPUT DAFTAR PESERTA'!C36 -> Muhammad Rizki Nauval Alim | D38: 90 | E38: 74 | F38: 84 | G38: 82 | H38: 77 | I38: 80 | J38: =(D38+E38+F38+G38+H38+I38)/6 -> 81.166667 | K38: ='LAPORAN RESMI'!J38 -> 91.166667 | L38: =(J38*$J$4)+(K38*$K$4) -> 86.166667
A39: ='INPUT DAFTAR PESERTA'!A37 -> 35 | B39: ='INPUT DAFTAR PESERTA'!B37 -> 2409076036 | C39: ='INPUT DAFTAR PESERTA'!C37 -> Muhammad Rico Setiawan | E39: 0 | J39: =(D39+E39+F39+G39+H39+I39)/6 -> 0 | K39: ='LAPORAN RESMI'!J39 -> 0 | L39: =(J39*$J$4)+(K39*$K$4) -> 0
A40: ='INPUT DAFTAR PESERTA'!A38 -> 36 | B40: ='INPUT DAFTAR PESERTA'!B38 -> 2409076037 | C40: ='INPUT DAFTAR PESERTA'!C38 -> Muhammad Ananda Ryan Nur Rahman | D40: 92.5 | E40: 85 | F40: 70 | G40: 73 | H40: 48 | I40: 0 | J40: =(D40+E40+F40+G40+H40+I40)/6 -> 61.416667 | K40: ='LAPORAN RESMI'!J40 -> 62.583333 | L40: =(J40*$J$4)+(K40*$K$4) -> 62
A41: ='INPUT DAFTAR PESERTA'!A39 -> 37 | B41: ='INPUT DAFTAR PESERTA'!B39 -> 2409076038 | C41: ='INPUT DAFTAR PESERTA'!C39 -> Muhammad Alif Rahmat Syakir | E41: 59 | J41: =(D41+E41+F41+G41+H41+I41)/6 -> 9.8333333 | K41: ='LAPORAN RESMI'!J41 -> 0 | L41: =(J41*$J$4)+(K41*$K$4) -> 4.9166667
A42: ='INPUT DAFTAR PESERTA'!A40 -> 38 | B42: ='INPUT DAFTAR PESERTA'!B40 -> 2409076039 | C42: ='INPUT DAFTAR PESERTA'!C40 -> Christopher Mahesa Aditama | D42: 86.5 | E42: 85 | F42: 81 | G42: 83 | H42: 61 | I42: 62 | J42: =(D42+E42+F42+G42+H42+I42)/6 -> 76.416667 | K42: ='LAPORAN RESMI'!J42 -> 91.75 | L42: =(J42*$J$4)+(K42*$K$4) -> 84.083333
A43: ='INPUT DAFTAR PESERTA'!A41 -> 39 | B43: ='INPUT DAFTAR PESERTA'!B41 -> 2409076040 | C43: ='INPUT DAFTAR PESERTA'!C41 -> Muhammad Rafli Ramadhani | D43: 91.5 | E43: 89 | F43: 81 | G43: 86 | H43: 95 | I43: 65 | J43: =(D43+E43+F43+G43+H43+I43)/6 -> 84.583333 | K43: ='LAPORAN RESMI'!J43 -> 92.916667 | L43: =(J43*$J$4)+(K43*$K$4) -> 88.75
A44: ='INPUT DAFTAR PESERTA'!A42 -> 40 | B44: ='INPUT DAFTAR PESERTA'!B42 -> 2409076041 | C44: ='INPUT DAFTAR PESERTA'!C42 -> Muhammad Rindhan Amarna | D44: 81.5 | E44: 74 | F44: 58 | G44: 83 | H44: 65 | I44: 36.5 | J44: =(D44+E44+F44+G44+H44+I44)/6 -> 66.333333 | K44: ='LAPORAN RESMI'!J44 -> 88.75 | L44: =(J44*$J$4)+(K44*$K$4) -> 77.541667
A45: ='INPUT DAFTAR PESERTA'!A43 -> 41 | B45: ='INPUT DAFTAR PESERTA'!B43 -> 2409076043 | C45: ='INPUT DAFTAR PESERTA'!C43 -> Bima Angga Pratama | D45: 41.5 | E45: 47 | H45: 39 | J45: =(D45+E45+F45+G45+H45+I45)/6 -> 21.25 | K45: ='LAPORAN RESMI'!J45 -> 0 | L45: =(J45*$J$4)+(K45*$K$4) -> 10.625
A46: ='INPUT DAFTAR PESERTA'!A44 -> 42 | B46: ='INPUT DAFTAR PESERTA'!B44 -> 2409076044 | C46: ='INPUT DAFTAR PESERTA'!C44 -> Muhammad Daffa Dzakwan | D46: 78 | E46: 82 | F46: 88 | G46: 80 | H46: 81 | I46: 0 | J46: =(D46+E46+F46+G46+H46+I46)/6 -> 68.166667 | K46: ='LAPORAN RESMI'!J46 -> 74.583333 | L46: =(J46*$J$4)+(K46*$K$4) -> 71.375
A47: ='INPUT DAFTAR PESERTA'!A45 -> 43 | B47: ='INPUT DAFTAR PESERTA'!B45 -> 2409076045 | C47: ='INPUT DAFTAR PESERTA'!C45 -> Ahmad Purwono Aji | D47: 79 | E47: 59 | F47: 63 | G47: 60 | H47: 69 | I47: 0 | J47: =(D47+E47+F47+G47+H47+I47)/6 -> 55 | K47: ='LAPORAN RESMI'!J47 -> 50.583333 | L47: =(J47*$J$4)+(K47*$K$4) -> 52.791667
A48: ='INPUT DAFTAR PESERTA'!A46 -> 44 | B48: ='INPUT DAFTAR PESERTA'!B46 -> 2409076046 | C48: ='INPUT DAFTAR PESERTA'!C46 -> Muhammad Hasan Hanif | D48: 0 | E48: 0 | F48: 65 | G48: 60 | H48: 70 | I48: 0 | J48: =(D48+E48+F48+G48+H48+I48)/6 -> 32.5 | K48: ='LAPORAN RESMI'!J48 -> 35 | L48: =(J48*$J$4)+(K48*$K$4) -> 33.75
A49: ='INPUT DAFTAR PESERTA'!A47 -> 45 | B49: ='INPUT DAFTAR PESERTA'!B47 -> 2409076047 | C49: ='INPUT DAFTAR PESERTA'!C47 -> Gilbert Pasolon | D49: 76 | E49: 85 | F49: 73 | G49: 75 | H49: 77 | I49: 0 | J49: =(D49+E49+F49+G49+H49+I49)/6 -> 64.333333 | K49: ='LAPORAN RESMI'!J49 -> 74.5 | L49: =(J49*$J$4)+(K49*$K$4) -> 69.416667
A50: ='INPUT DAFTAR PESERTA'!A48 -> 46 | B50: ='INPUT DAFTAR PESERTA'!B48 -> 2409076048 | C50: ='INPUT DAFTAR PESERTA'!C48 -> Achmad Fauzan At-Tamimi | D50: 85.5 | E50: 85 | F50: 89 | G50: 86 | H50: 72 | I50: 51 | J50: =(D50+E50+F50+G50+H50+I50)/6 -> 78.083333 | K50: ='LAPORAN RESMI'!J50 -> 92.166667 | L50: =(J50*$J$4)+(K50*$K$4) -> 85.125
A51: ='INPUT DAFTAR PESERTA'!A49 -> 47 | B51: ='INPUT DAFTAR PESERTA'!B49 -> 2409076049 | C51: ='INPUT DAFTAR PESERTA'!C49 -> Mahmud Abdul Aziz Qoby | D51: 38.5 | E51: 38 | F51: 74 | G51: 74 | H51: 45 | I51: 51.5 | J51: =(D51+E51+F51+G51+H51+I51)/6 -> 53.5 | K51: ='LAPORAN RESMI'!J51 -> 75 | L51: =(J51*$J$4)+(K51*$K$4) -> 64.25
A52: ='INPUT DAFTAR PESERTA'!A50 -> 48 | B52: ='INPUT DAFTAR PESERTA'!B50 -> 2409076050 | C52: ='INPUT DAFTAR PESERTA'!C50 -> Gde Nookie Carl Arya Susila | D52: 80.5 | E52: 87 | F52: 94 | G52: 85 | H52: 77 | I52: 49 | J52: =(D52+E52+F52+G52+H52+I52)/6 -> 78.75 | K52: ='LAPORAN RESMI'!J52 -> 91.5 | L52: =(J52*$J$4)+(K52*$K$4) -> 85.125
A53: ='INPUT DAFTAR PESERTA'!A51 -> 49 | B53: ='INPUT DAFTAR PESERTA'!B51 -> 2409076051 | C53: ='INPUT DAFTAR PESERTA'!C51 -> Muhammad Afrizal | E53: 0 | J53: =(D53+E53+F53+G53+H53+I53)/6 -> 0 | K53: ='LAPORAN RESMI'!J53 -> 0 | L53: =(J53*$J$4)+(K53*$K$4) -> 0
A54: ='INPUT DAFTAR PESERTA'!A52 -> 50 | B54: ='INPUT DAFTAR PESERTA'!B52 -> 2409076052 | C54: ='INPUT DAFTAR PESERTA'!C52 -> Rezky Yutabse | D54: 65 | E54: 84 | F54: 70 | G54: 79 | H54: 67 | I54: 0 | J54: =(D54+E54+F54+G54+H54+I54)/6 -> 60.833333 | K54: ='LAPORAN RESMI'!J54 -> 87.916667 | L54: =(J54*$J$4)+(K54*$K$4) -> 74.375
A55: ='INPUT DAFTAR PESERTA'!A53 -> 51 | B55: ='INPUT DAFTAR PESERTA'!B53 -> 2409076053 | C55: ='INPUT DAFTAR PESERTA'!C53 -> Dimas Wijaya Muliangto | D55: 83 | E55: 78 | F55: 89 | G55: 76 | H55: 75 | I55: 26 | J55: =(D55+E55+F55+G55+H55+I55)/6 -> 71.166667 | K55: ='LAPORAN RESMI'!J55 -> 83.416667 | L55: =(J55*$J$4)+(K55*$K$4) -> 77.291667
A56: ='INPUT DAFTAR PESERTA'!A54 -> 52 | B56: ='INPUT DAFTAR PESERTA'!B54 -> 2409076054 | C56: ='INPUT DAFTAR PESERTA'!C54 -> Muhammad Aldi | D56: 75 | E56: 81 | F56: 92 | G56: 69 | H56: 71 | I56: 59 | J56: =(D56+E56+F56+G56+H56+I56)/6 -> 74.5 | K56: ='LAPORAN RESMI'!J56 -> 89 | L56: =(J56*$J$4)+(K56*$K$4) -> 81.75
A57: ='INPUT DAFTAR PESERTA'!A55 -> 53 | B57: ='INPUT DAFTAR PESERTA'!B55 -> 2409076056 | C57: ='INPUT DAFTAR PESERTA'!C55 -> Rivaldy Paredanun | D57: 72 | E57: 69 | F57: 44 | G57: 71 | H57: 70 | I57: 22 | J57: =(D57+E57+F57+G57+H57+I57)/6 -> 58 | K57: ='LAPORAN RESMI'!J57 -> 53.333333 | L57: =(J57*$J$4)+(K57*$K$4) -> 55.666667
A58: ='INPUT DAFTAR PESERTA'!A56 -> 54 | B58: ='INPUT DAFTAR PESERTA'!B56 -> 2409076024 | C58: ='INPUT DAFTAR PESERTA'!C56 -> Muhammad Zacky | D58: 90 | E58: 82 | F58: 93 | G58: 74 | H58: 90 | I58: 71 | J58: =(D58+E58+F58+G58+H58+I58)/6 -> 83.333333 | K58: ='LAPORAN RESMI'!J58 -> 92.083333 | L58: =(J58*$J$4)+(K58*$K$4) -> 87.708333

Sheet KEMAMPUAN PRAKTIKUM
A1: HOME
A3: NO | B3: NIM | C3: NAMA | D3: Modul 1 | I3: Modul 2 | N3: Modul 3 | S3: Modul 4 | X3: Modul 5 | AC3: Modul 6
D4: K1 | E4: K2 | F4: K3 | G4: K4 | H4: Rerata | I4: K1 | J4: K2 | K4: K3 | L4: K4 | M4: Rerata | N4: K1 | O4: K2 | P4: K3 | Q4: K4 | R4: Rerata | S4: K1 | T4: K2 | U4: K3 | V4: K4 | W4: Rerata | X4: K1 | Y4: K2 | Z4: K3 | AA4: K4 | AB4: Rerata | AC4: K1 | AD4: K2 | AE4: K3 | AF4: K4 | AG4: Rerata
D5: 0.1 | E5: 0.2 | F5: 0.2 | G5: 0.5 | H5: 1 | I5: 0.1 | J5: 0.2 | K5: 0.2 | L5: 0.5 | M5: 1 | N5: 0.1 | O5: 0.2 | P5: 0.2 | Q5: 0.5 | R5: 1 | S5: 0.1 | T5: 0.2 | U5: 0.2 | V5: 0.5 | W5: 1 | X5: 0.1 | Y5: 0.2 | Z5: 0.2 | AA5: 0.5 | AB5: 1 | AC5: 0.1 | AD5: 0.2 | AE5: 0.2 | AF5: 0.5 | AG5: 1
A6: ='INPUT DAFTAR PESERTA'!A3 -> 1 | B6: ='INPUT DAFTAR PESERTA'!B3 -> 2409076001 | C6: ='INPUT DAFTAR PESERTA'!C3 -> Muhammad Jodika | D6: 3 | E6: 2 | F6: 2 | G6: 3 | H6: =((D6*$D$5/3)+(E6*$E$5/3)+(F6*$F$5/3)+(G6*$G$5/3))*90 -> 78 | I6: 3 | J6: 2 | K6: 3 | L6: 3 | M6: =((I6*$D$5/3)+(J6*$E$5/3)+(K6*$F$5/3)+(L6*$G$5/3))*90 -> 84 | N6: 3 | O6: 3 | P6: 3 | Q6: 3 | R6: =((N6*$D$5/3)+(O6*$E$5/3)+(P6*$F$5/3)+(Q6*$G$5/3))*90 -> 90 | S6: 2 | T6: 3 | U6: 2 | V6: 3 | W6: =((S6*$D$5/3)+(T6*$E$5/3)+(U6*$F$5/3)+(V6*$G$5/3))*90 -> 81 | X6: 3 | Y6: 3 | Z6: 3 | AA6: 3 | AB6: =((X6*$D$5/3)+(Y6*$E$5/3)+(Z6*$F$5/3)+(AA6*$G$5/3))*90 -> 90 | AC6: 3 | AD6: 3 | AE6: 3 | AF6: 3 | AG6: =((AC6*$D$5/3)+(AD6*$E$5/3)+(AE6*$F$5/3)+(AF6*$G$5/3))*90 -> 90
A7: ='INPUT DAFTAR PESERTA'!A4 -> 2 | B7: ='INPUT DAFTAR PESERTA'!B4 -> 2409076002 | C7: ='INPUT DAFTAR PESERTA'!C4 -> Muhammad Rifqi Maulana | D7: 3 | E7: 3 | F7: 2 | G7: 3 | H7: =((D7*$D$5/3)+(E7*$E$5/3)+(F7*$F$5/3)+(G7*$G$5/3))*90 -> 84 | I7: 3 | J7: 2 | K7: 3 | L7: 2 | M7: =((I7*$D$5/3)+(J7*$E$5/3)+(K7*$F$5/3)+(L7*$G$5/3))*90 -> 69 | N7: 3 | O7: 3 | P7: 3 | Q7: 3 | R7: =((N7*$D$5/3)+(O7*$E$5/3)+(P7*$F$5/3)+(Q7*$G$5/3))*90 -> 90 | S7: 2 | T7: 3 | U7: 2 | V7: 3 | W7: =((S7*$D$5/3)+(T7*$E$5/3)+(U7*$F$5/3)+(V7*$G$5/3))*90 -> 81 | X7: 3 | Y7: 3 | Z7: 3 | AA7: 3 | AB7: =((X7*$D$5/3)+(Y7*$E$5/3)+(Z7*$F$5/3)+(AA7*$G$5/3))*90 -> 90 | AC7: 2 | AD7: 2 | AE7: 2 | AF7: 1 | AG7: =((AC7*$D$5/3)+(AD7*$E$5/3)+(AE7*$F$5/3)+(AF7*$G$5/3))*90 -> 45
A8: ='INPUT DAFTAR PESERTA'!A5 -> 3 | B8: ='INPUT DAFTAR PESERTA'!B5 -> 2409076003 | C8: ='INPUT DAFTAR PESERTA'!C5 -> Andhika Pratama | D8: 3 | E8: 3 | F8: 2 | G8: 3 | H8: =((D8*$D$5/3)+(E8*$E$5/3)+(F8*$F$5/3)+(G8*$G$5/3))*90 -> 84 | I8: 2 | J8: 3 | K8: 3 | L8: 1 | M8: =((I8*$D$5/3)+(J8*$E$5/3)+(K8*$F$5/3)+(L8*$G$5/3))*90 -> 57 | N8: 3 | O8: 3 | P8: 3 | Q8: 1 | R8: =((N8*$D$5/3)+(O8*$E$5/3)+(P8*$F$5/3)+(Q8*$G$5/3))*90 -> 60 | S8: 2 | T8: 2 | U8: 2 | V8: 3 | W8: =((S8*$D$5/3)+(T8*$E$5/3)+(U8*$F$5/3)+(V8*$G$5/3))*90 -> 75 | X8: 3 | Y8: 3 | Z8: 3 | AA8: 3 | AB8: =((X8*$D$5/3)+(Y8*$E$5/3)+(Z8*$F$5/3)+(AA8*$G$5/3))*90 -> 90 | AC8: 2 | AD8: 2 | AE8: 2 | AF8: 1 | AG8: =((AC8*$D$5/3)+(AD8*$E$5/3)+(AE8*$F$5/3)+(AF8*$G$5/3))*90 -> 45
A9: ='INPUT DAFTAR PESERTA'!A6 -> 4 | B9: ='INPUT DAFTAR PESERTA'!B6 -> 2409076004 | C9: ='INPUT DAFTAR PESERTA'!C6 -> Nur Aqmarina | D9: 3 | E9: 2 | F9: 2 | G9: 3 | H9: =((D9*$D$5/3)+(E9*$E$5/3)+(F9*$F$5/3)+(G9*$G$5/3))*90 -> 78 | I9: 3 | J9: 2 | K9: 3 | L9: 1 | M9: =((I9*$D$5/3)+(J9*$E$5/3)+(K9*$F$5/3)+(L9*$G$5/3))*90 -> 54 | N9: 3 | O9: 3 | P9: 3 | Q9: 3 | R9: =((N9*$D$5/3)+(O9*$E$5/3)+(P9*$F$5/3)+(Q9*$G$5/3))*90 -> 90 | S9: 2 | T9: 3 | U9: 2 | V9: 3 | W9: =((S9*$D$5/3)+(T9*$E$5/3)+(U9*$F$5/3)+(V9*$G$5/3))*90 -> 81 | X9: 3 | Y9: 3 | Z9: 3 | AA9: 3 | AB9: =((X9*$D$5/3)+(Y9*$E$5/3)+(Z9*$F$5/3)+(AA9*$G$5/3))*90 -> 90 | AC9: 3 | AD9: 2 | AE9: 2 | AF9: 2 | AG9: =((AC9*$D$5/3)+(AD9*$E$5/3)+(AE9*$F$5/3)+(AF9*$G$5/3))*90 -> 63
A10: ='INPUT DAFTAR PESERTA'!A7 -> 5 | B10: ='INPUT DAFTAR PESERTA'!B7 -> 2409076005 | C10: ='INPUT DAFTAR PESERTA'!C7 -> Rias Prihatanto | D10: 3 | E10: 3 | F10: 3 | G10: 3 | H10: =((D10*$D$5/3)+(E10*$E$5/3)+(F10*$F$5/3)+(G10*$G$5/3))*90 -> 90 | I10: 3 | J10: 2 | K10: 3 | L10: 1 | M10: =((I10*$D$5/3)+(J10*$E$5/3)+(K10*$F$5/3)+(L10*$G$5/3))*90 -> 54 | N10: 3 | O10: 3 | P10: 3 | Q10: 3 | R10: =((N10*$D$5/3)+(O10*$E$5/3)+(P10*$F$5/3)+(Q10*$G$5/3))*90 -> 90 | S10: 2 | T10: 2 | U10: 3 | V10: 3 | W10: =((S10*$D$5/3)+(T10*$E$5/3)+(U10*$F$5/3)+(V10*$G$5/3))*90 -> 81 | X10: 3 | Y10: 3 | Z10: 3 | AA10: 3 | AB10: =((X10*$D$5/3)+(Y10*$E$5/3)+(Z10*$F$5/3)+(AA10*$G$5/3))*90 -> 90 | AC10: 3 | AD10: 3 | AE10: 3 | AF10: 3 | AG10: =((AC10*$D$5/3)+(AD10*$E$5/3)+(AE10*$F$5/3)+(AF10*$G$5/3))*90 -> 90
A11: ='INPUT DAFTAR PESERTA'!A8 -> 6 | B11: ='INPUT DAFTAR PESERTA'!B8 -> 2409076006 | C11: ='INPUT DAFTAR PESERTA'!C8 -> Muhammad Maulana Bhagaskara | D11: 3 | E11: 3 | F11: 3 | G11: 3 | H11: =((D11*$D$5/3)+(E11*$E$5/3)+(F11*$F$5/3)+(G11*$G$5/3))*90 -> 90 | I11: 3 | J11: 2 | K11: 3 | L11: 2 | M11: =((I11*$D$5/3)+(J11*$E$5/3)+(K11*$F$5/3)+(L11*$G$5/3))*90 -> 69 | N11: 3 | O11: 3 | P11: 3 | Q11: 3 | R11: =((N11*$D$5/3)+(O11*$E$5/3)+(P11*$F$5/3)+(Q11*$G$5/3))*90 -> 90 | S11: 2 | T11: 3 | U11: 2 | V11: 3 | W11: =((S11*$D$5/3)+(T11*$E$5/3)+(U11*$F$5/3)+(V11*$G$5/3))*90 -> 81 | X11: 3 | Y11: 3 | Z11: 3 | AA11: 3 | AB11: =((X11*$D$5/3)+(Y11*$E$5/3)+(Z11*$F$5/3)+(AA11*$G$5/3))*90 -> 90 | AC11: 2 | AD11: 3 | AE11: 3 | AF11: 2 | AG11: =((AC11*$D$5/3)+(AD11*$E$5/3)+(AE11*$F$5/3)+(AF11*$G$5/3))*90 -> 72
A12: ='INPUT DAFTAR PESERTA'!A9 -> 7 | B12: ='INPUT DAFTAR PESERTA'!B9 -> 2409076007 | C12: ='INPUT DAFTAR PESERTA'!C9 -> Chelsi Kamera | D12: 3 | E12: 3 | F12: 3 | G12: 3 | H12: =((D12*$D$5/3)+(E12*$E$5/3)+(F12*$F$5/3)+(G12*$G$5/3))*90 -> 90 | I12: 3 | J12: 2 | K12: 3 | L12: 2 | M12: =((I12*$D$5/3)+(J12*$E$5/3)+(K12*$F$5/3)+(L12*$G$5/3))*90 -> 69 | N12: 3 | O12: 3 | P12: 3 | Q12: 3 | R12: =((N12*$D$5/3)+(O12*$E$5/3)+(P12*$F$5/3)+(Q12*$G$5/3))*90 -> 90 | S12: 2 | T12: 3 | U12: 3 | V12: 3 | W12: =((S12*$D$5/3)+(T12*$E$5/3)+(U12*$F$5/3)+(V12*$G$5/3))*90 -> 87 | X12: 3 | Y12: 3 | Z12: 3 | AA12: 3 | AB12: =((X12*$D$5/3)+(Y12*$E$5/3)+(Z12*$F$5/3)+(AA12*$G$5/3))*90 -> 90 | AC12: 3 | AD12: 3 | AE12: 3 | AF12: 3 | AG12: =((AC12*$D$5/3)+(AD12*$E$5/3)+(AE12*$F$5/3)+(AF12*$G$5/3))*90 -> 90
A13: ='INPUT DAFTAR PESERTA'!A10 -> 8 | B13: ='INPUT DAFTAR PESERTA'!B10 -> 2409076008 | C13: ='INPUT DAFTAR PESERTA'!C10 -> Riyan Maulana | D13: 3 | E13: 3 | F13: 3 | G13: 1 | H13: =((D13*$D$5/3)+(E13*$E$5/3)+(F13*$F$5/3)+(G13*$G$5/3))*90 -> 60 | I13: 3 | J13: 3 | K13: 3 | L13: 1 | M13: =((I13*$D$5/3)+(J13*$E$5/3)+(K13*$F$5/3)+(L13*$G$5/3))*90 -> 60 | N13: 3 | O13: 3 | P13: 3 | Q13: 3 | R13: =((N13*$D$5/3)+(O13*$E$5/3)+(P13*$F$5/3)+(Q13*$G$5/3))*90 -> 90 | S13: 2 | T13: 2 | U13: 2 | V13: 3 | W13: =((S13*$D$5/3)+(T13*$E$5/3)+(U13*$F$5/3)+(V13*$G$5/3))*90 -> 75 | X13: 3 | Y13: 3 | Z13: 3 | AA13: 3 | AB13: =((X13*$D$5/3)+(Y13*$E$5/3)+(Z13*$F$5/3)+(AA13*$G$5/3))*90 -> 90 | AC13: 3 | AD13: 3 | AE13: 3 | AF13: 2 | AG13: =((AC13*$D$5/3)+(AD13*$E$5/3)+(AE13*$F$5/3)+(AF13*$G$5/3))*90 -> 75
A14: ='INPUT DAFTAR PESERTA'!A11 -> 9 | B14: ='INPUT DAFTAR PESERTA'!B11 -> 2409076009 | C14: ='INPUT DAFTAR PESERTA'!C11 -> Dimas Prasetyo Wibowo | D14: 3 | E14: 3 | F14: 3 | G14: 3 | H14: =((D14*$D$5/3)+(E14*$E$5/3)+(F14*$F$5/3)+(G14*$G$5/3))*90 -> 90 | I14: 3 | J14: 2 | K14: 3 | L14: 2 | M14: =((I14*$D$5/3)+(J14*$E$5/3)+(K14*$F$5/3)+(L14*$G$5/3))*90 -> 69 | N14: 3 | O14: 3 | P14: 3 | Q14: 2 | R14: =((N14*$D$5/3)+(O14*$E$5/3)+(P14*$F$5/3)+(Q14*$G$5/3))*90 -> 75 | S14: 2 | T14: 3 | U14: 2 | V14: 3 | W14: =((S14*$D$5/3)+(T14*$E$5/3)+(U14*$F$5/3)+(V14*$G$5/3))*90 -> 81 | X14: 3 | Y14: 3 | Z14: 3 | AA14: 3 | AB14: =((X14*$D$5/3)+(Y14*$E$5/3)+(Z14*$F$5/3)+(AA14*$G$5/3))*90 -> 90 | AC14: 3 | AD14: 3 | AE14: 3 | AF14: 2 | AG14: =((AC14*$D$5/3)+(AD14*$E$5/3)+(AE14*$F$5/3)+(AF14*$G$5/3))*90 -> 75
A15: ='INPUT DAFTAR PESERTA'!A12 -> 10 | B15: ='INPUT DAFTAR PESERTA'!B12 -> 2409076010 | C15: ='INPUT DAFTAR PESERTA'!C12 -> Najwa Dwi Maylani | D15: 3 | E15: 3 | F15: 3 | G15: 3 | H15: =((D15*$D$5/3)+(E15*$E$5/3)+(F15*$F$5/3)+(G15*$G$5/3))*90 -> 90 | I15: 3 | J15: 2 | K15: 3 | L15: 2 | M15: =((I15*$D$5/3)+(J15*$E$5/3)+(K15*$F$5/3)+(L15*$G$5/3))*90 -> 69 | N15: 3 | O15: 3 | P15: 3 | Q15: 3 | R15: =((N15*$D$5/3)+(O15*$E$5/3)+(P15*$F$5/3)+(Q15*$G$5/3))*90 -> 90 | S15: 2 | T15: 3 | U15: 3 | V15: 3 | W15: =((S15*$D$5/3)+(T15*$E$5/3)+(U15*$F$5/3)+(V15*$G$5/3))*90 -> 87 | X15: 3 | Y15: 3 | Z15: 3 | AA15: 3 | AB15: =((X15*$D$5/3)+(Y15*$E$5/3)+(Z15*$F$5/3)+(AA15*$G$5/3))*90 -> 90 | AC15: 2 | AD15: 2 | AE15: 2 | AF15: 3 | AG15: =((AC15*$D$5/3)+(AD15*$E$5/3)+(AE15*$F$5/3)+(AF15*$G$5/3))*90 -> 75
A16: ='INPUT DAFTAR PESERTA'!A13 -> 11 | B16: ='INPUT DAFTAR PESERTA'!B13 -> 2409076011 | C16: ='INPUT DAFTAR PESERTA'!C13 -> Surya Ardhian Mokodongan | D16: 3 | E16: 3 | F16: 3 | G16: 3 | H16: =((D16*$D$5/3)+(E16*$E$5/3)+(F16*$F$5/3)+(G16*$G$5/3))*90 -> 90 | I16: 3 | J16: 3 | K16: 3 | L16: 3 | M16: =((I16*$D$5/3)+(J16*$E$5/3)+(K16*$F$5/3)+(L16*$G$5/3))*90 -> 90 | N16: 3 | O16: 3 | P16: 3 | Q16: 3 | R16: =((N16*$D$5/3)+(O16*$E$5/3)+(P16*$F$5/3)+(Q16*$G$5/3))*90 -> 90 | S16: 2 | T16: 3 | U16: 3 | V16: 1 | W16: =((S16*$D$5/3)+(T16*$E$5/3)+(U16*$F$5/3)+(V16*$G$5/3))*90 -> 57 | X16: 3 | Y16: 3 | Z16: 3 | AA16: 3 | AB16: =((X16*$D$5/3)+(Y16*$E$5/3)+(Z16*$F$5/3)+(AA16*$G$5/3))*90 -> 90 | AC16: 3 | AD16: 3 | AE16: 3 | AF16: 2 | AG16: =((AC16*$D$5/3)+(AD16*$E$5/3)+(AE16*$F$5/3)+(AF16*$G$5/3))*90 -> 75
A17: ='INPUT DAFTAR PESERTA'!A14 -> 12 | B17: ='INPUT DAFTAR PESERTA'!B14 -> 2409076012 | C17: ='INPUT DAFTAR PESERTA'!C14 -> Ahmad Irfani Ananda Putra Hariawan | D17: 3 | E17: 3 | F17: 3 | G17: 3 | H17: =((D17*$D$5/3)+(E17*$E$5/3)+(F17*$F$5/3)+(G17*$G$5/3))*90 -> 90 | I17: 3 | J17: 3 | K17: 3 | L17: 3 | M17: =((I17*$D$5/3)+(J17*$E$5/3)+(K17*$F$5/3)+(L17*$G$5/3))*90 -> 90 | N17: 3 | O17: 3 | P17: 3 | Q17: 2 | R17: =((N17*$D$5/3)+(O17*$E$5/3)+(P17*$F$5/3)+(Q17*$G$5/3))*90 -> 75 | S17: 2 | T17: 3 | U17: 3 | V17: 1 | W17: =((S17*$D$5/3)+(T17*$E$5/3)+(U17*$F$5/3)+(V17*$G$5/3))*90 -> 57 | X17: 3 | Y17: 3 | Z17: 3 | AA17: 3 | AB17: =((X17*$D$5/3)+(Y17*$E$5/3)+(Z17*$F$5/3)+(AA17*$G$5/3))*90 -> 90 | AC17: 3 | AD17: 3 | AE17: 3 | AF17: 1 | AG17: =((AC17*$D$5/3)+(AD17*$E$5/3)+(AE17*$F$5/3)+(AF17*$G$5/3))*90 -> 60
... A39: ='INPUT DAFTAR PESERTA'!A36 -> 34 | B39: ='INPUT DAFTAR PESERTA'!B36 -> 2409076035 | C39: ='INPUT DAFTAR PESERTA'!C36 -> Muhammad Rizki Nauval Alim | D39: 3 | E39: 3 | F39: 3 | G39: 3 | H39: =((D39*$D$5/3)+(E39*$E$5/3)+(F39*$F$5/3)+(G39*$G$5/3))*90 -> 90 | I39: 2 | J39: 3 | K39: 3 | L39: 2 | M39: =((I39*$D$5/3)+(J39*$E$5/3)+(K39*$F$5/3)+(L39*$G$5/3))*90 -> 72 | N39: 3 | O39: 3 | P39: 3 | Q39: 3 | R39: =((N39*$D$5/3)+(O39*$E$5/3)+(P39*$F$5/3)+(Q39*$G$5/3))*90 -> 90 | S39: 3 | T39: 3 | U39: 3 | V39: 3 | W39: =((S39*$D$5/3)+(T39*$E$5/3)+(U39*$F$5/3)+(V39*$G$5/3))*90 -> 90 | X39: 3 | Y39: 3 | Z39: 3 | AA39: 3 | AB39: =((X39*$D$5/3)+(Y39*$E$5/3)+(Z39*$F$5/3)+(AA39*$G$5/3))*90 -> 90 | AC39: 2 | AD39: 3 | AE39: 3 | AF39: 2 | AG39: =((AC39*$D$5/3)+(AD39*$E$5/3)+(AE39*$F$5/3)+(AF39*$G$5/3))*90 -> 72
A40: ='INPUT DAFTAR PESERTA'!A37 -> 35 | B40: ='INPUT DAFTAR PESERTA'!B37 -> 2409076036 | C40: ='INPUT DAFTAR PESERTA'!C37 -> Muhammad Rico Setiawan | D40: 3 | E40: 3 | F40: 3 | G40: 3 | H40: =((D40*$D$5/3)+(E40*$E$5/3)+(F40*$F$5/3)+(G40*$G$5/3))*90 -> 90 | M40: =((I40*$D$5/3)+(J40*$E$5/3)+(K40*$F$5/3)+(L40*$G$5/3))*90 -> 0 | R40: =((N40*$D$5/3)+(O40*$E$5/3)+(P40*$F$5/3)+(Q40*$G$5/3))*90 -> 0 | W40: =((S40*$D$5/3)+(T40*$E$5/3)+(U40*$F$5/3)+(V40*$G$5/3))*90 -> 0 | AB40: =((X40*$D$5/3)+(Y40*$E$5/3)+(Z40*$F$5/3)+(AA40*$G$5/3))*90 -> 0 | AG40: =((AC40*$D$5/3)+(AD40*$E$5/3)+(AE40*$F$5/3)+(AF40*$G$5/3))*90 -> 0
A41: ='INPUT DAFTAR PESERTA'!A38 -> 36 | B41: ='INPUT DAFTAR PESERTA'!B38 -> 2409076037 | C41: ='INPUT DAFTAR PESERTA'!C38 -> Muhammad Ananda Ryan Nur Rahman | D41: 3 | E41: 3 | F41: 3 | G41: 3 | H41: =((D41*$D$5/3)+(E41*$E$5/3)+(F41*$F$5/3)+(G41*$G$5/3))*90 -> 90 | I41: 2 | J41: 3 | K41: 3 | L41: 2 | M41: =((I41*$D$5/3)+(J41*$E$5/3)+(K41*$F$5/3)+(L41*$G$5/3))*90 -> 72 | N41: 3 | O41: 3 | P41: 3 | Q41: 1 | R41: =((N41*$D$5/3)+(O41*$E$5/3)+(P41*$F$5/3)+(Q41*$G$5/3))*90 -> 60 | S41: 2 | T41: 3 | U41: 3 | V41: 2 | W41: =((S41*$D$5/3)+(T41*$E$5/3)+(U41*$F$5/3)+(V41*$G$5/3))*90 -> 72 | X41: 1 | Y41: 1 | Z41: 1 | AA41: 1 | AB41: =((X41*$D$5/3)+(Y41*$E$5/3)+(Z41*$F$5/3)+(AA41*$G$5/3))*90 -> 30 | AC41: 3 | AD41: 3 | AE41: 2 | AF41: 1 | AG41: =((AC41*$D$5/3)+(AD41*$E$5/3)+(AE41*$F$5/3)+(AF41*$G$5/3))*90 -> 54
A42: ='INPUT DAFTAR PESERTA'!A39 -> 37 | B42: ='INPUT DAFTAR PESERTA'!B39 -> 2409076038 | C42: ='INPUT DAFTAR PESERTA'!C39 -> Muhammad Alif Rahmat Syakir | H42: =((D42*$D$5/3)+(E42*$E$5/3)+(F42*$F$5/3)+(G42*$G$5/3))*90 -> 0 | I42: 3 | J42: 3 | K42: 3 | L42: 1 | M42: =((I42*$D$5/3)+(J42*$E$5/3)+(K42*$F$5/3)+(L42*$G$5/3))*90 -> 60 | R42: =((N42*$D$5/3)+(O42*$E$5/3)+(P42*$F$5/3)+(Q42*$G$5/3))*90 -> 0 | W42: =((S42*$D$5/3)+(T42*$E$5/3)+(U42*$F$5/3)+(V42*$G$5/3))*90 -> 0 | AB42: =((X42*$D$5/3)+(Y42*$E$5/3)+(Z42*$F$5/3)+(AA42*$G$5/3))*90 -> 0 | AG42: =((AC42*$D$5/3)+(AD42*$E$5/3)+(AE42*$F$5/3)+(AF42*$G$5/3))*90 -> 0
A43: ='INPUT DAFTAR PESERTA'!A40 -> 38 | B43: ='INPUT DAFTAR PESERTA'!B40 -> 2409076039 | C43: ='INPUT DAFTAR PESERTA'!C40 -> Christopher Mahesa Aditama | D43: 3 | E43: 3 | F43: 3 | G43: 3 | H43: =((D43*$D$5/3)+(E43*$E$5/3)+(F43*$F$5/3)+(G43*$G$5/3))*90 -> 90 | I43: 3 | J43: 3 | K43: 3 | L43: 3 | M43: =((I43*$D$5/3)+(J43*$E$5/3)+(K43*$F$5/3)+(L43*$G$5/3))*90 -> 90 | N43: 3 | O43: 3 | P43: 3 | Q43: 3 | R43: =((N43*$D$5/3)+(O43*$E$5/3)+(P43*$F$5/3)+(Q43*$G$5/3))*90 -> 90 | S43: 2 | T43: 3 | U43: 2 | V43: 3 | W43: =((S43*$D$5/3)+(T43*$E$5/3)+(U43*$F$5/3)+(V43*$G$5/3))*90 -> 81 | X43: 3 | Y43: 3 | Z43: 3 | AA43: 3 | AB43: =((X43*$D$5/3)+(Y43*$E$5/3)+(Z43*$F$5/3)+(AA43*$G$5/3))*90 -> 90 | AC43: 3 | AD43: 3 | AE43: 3 | AF43: 1 | AG43: =((AC43*$D$5/3)+(AD43*$E$5/3)+(AE43*$F$5/3)+(AF43*$G$5/3))*90 -> 60
A44: ='INPUT DAFTAR PESERTA'!A41 -> 39 | B44: ='INPUT DAFTAR PESERTA'!B41 -> 2409076040 | C44: ='INPUT DAFTAR PESERTA'!C41 -> Muhammad Rafli Ramadhani | D44: 3 | E44: 3 | F44: 3 | G44: 3 | H44: =((D44*$D$5/3)+(E44*$E$5/3)+(F44*$F$5/3)+(G44*$G$5/3))*90 -> 90 | I44: 3 | J44: 3 | K44: 3 | L44: 3 | M44: =((I44*$D$5/3)+(J44*$E$5/3)+(K44*$F$5/3)+(L44*$G$5/3))*90 -> 90 | N44: 3 | O44: 3 | P44: 3 | Q44: 3 | R44: =((N44*$D$5/3)+(O44*$E$5/3)+(P44*$F$5/3)+(Q44*$G$5/3))*90 -> 90 | S44: 3 | T44: 2 | U44: 3 | V44: 3 | W44: =((S44*$D$5/3)+(T44*$E$5/3)+(U44*$F$5/3)+(V44*$G$5/3))*90 -> 84 | X44: 3 | Y44: 3 | Z44: 3 | AA44: 3 | AB44: =((X44*$D$5/3)+(Y44*$E$5/3)+(Z44*$F$5/3)+(AA44*$G$5/3))*90 -> 90 | AC44: 3 | AD44: 3 | AE44: 3 | AF44: 1 | AG44: =((AC44*$D$5/3)+(AD44*$E$5/3)+(AE44*$F$5/3)+(AF44*$G$5/3))*90 -> 60
A45: ='INPUT DAFTAR PESERTA'!A42 -> 40 | B45: ='INPUT DAFTAR PESERTA'!B42 -> 2409076041 | C45: ='INPUT DAFTAR PESERTA'!C42 -> Muhammad Rindhan Amarna | D45: 3 | E45: 3 | F45: 3 | G45: 3 | H45: =((D45*$D$5/3)+(E45*$E$5/3)+(F45*$F$5/3)+(G45*$G$5/3))*90 -> 90 | I45: 3 | J45: 3 | K45: 3 | L45: 2 | M45: =((I45*$D$5/3)+(J45*$E$5/3)+(K45*$F$5/3)+(L45*$G$5/3))*90 -> 75 | N45: 3 | O45: 2 | P45: 3 | Q45: 1 | R45: =((N45*$D$5/3)+(O45*$E$5/3)+(P45*$F$5/3)+(Q45*$G$5/3))*90 -> 54 | S45: 3 | T45: 3 | U45: 3 | V45: 3 | W45: =((S45*$D$5/3)+(T45*$E$5/3)+(U45*$F$5/3)+(V45*$G$5/3))*90 -> 90 | X45: 3 | Y45: 3 | Z45: 3 | AA45: 3 | AB45: =((X45*$D$5/3)+(Y45*$E$5/3)+(Z45*$F$5/3)+(AA45*$G$5/3))*90 -> 90 | AC45: 3 | AD45: 3 | AE45: 3 | AF45: 1 | AG45: =((AC45*$D$5/3)+(AD45*$E$5/3)+(AE45*$F$5/3)+(AF45*$G$5/3))*90 -> 60
A46: ='INPUT DAFTAR PESERTA'!A43 -> 41 | B46: ='INPUT DAFTAR PESERTA'!B43 -> 2409076043 | C46: ='INPUT DAFTAR PESERTA'!C43 -> Bima Angga Pratama | D46: 3 | E46: 3 | F46: 3 | G46: 1 | H46: =((D46*$D$5/3)+(E46*$E$5/3)+(F46*$F$5/3)+(G46*$G$5/3))*90 -> 60 | I46: 3 | J46: 3 | K46: 3 | L46: 1 | M46: =((I46*$D$5/3)+(J46*$E$5/3)+(K46*$F$5/3)+(L46*$G$5/3))*90 -> 60 | R46: =((N46*$D$5/3)+(O46*$E$5/3)+(P46*$F$5/3)+(Q46*$G$5/3))*90 -> 0 | W46: =((S46*$D$5/3)+(T46*$E$5/3)+(U46*$F$5/3)+(V46*$G$5/3))*90 -> 0 | AB46: =((X46*$D$5/3)+(Y46*$E$5/3)+(Z46*$F$5/3)+(AA46*$G$5/3))*90 -> 0 | AG46: =((AC46*$D$5/3)+(AD46*$E$5/3)+(AE46*$F$5/3)+(AF46*$G$5/3))*90 -> 0
A47: ='INPUT DAFTAR PESERTA'!A44 -> 42 | B47: ='INPUT DAFTAR PESERTA'!B44 -> 2409076044 | C47: ='INPUT DAFTAR PESERTA'!C44 -> Muhammad Daffa Dzakwan | D47: 3 | E47: 3 | F47: 3 | G47: 2 | H47: =((D47*$D$5/3)+(E47*$E$5/3)+(F47*$F$5/3)+(G47*$G$5/3))*90 -> 75 | I47: 2 | J47: 3 | K47: 3 | L47: 2 | M47: =((I47*$D$5/3)+(J47*$E$5/3)+(K47*$F$5/3)+(L47*$G$5/3))*90 -> 72 | N47: 3 | O47: 3 | P47: 3 | Q47: 2 | R47: =((N47*$D$5/3)+(O47*$E$5/3)+(P47*$F$5/3)+(Q47*$G$5/3))*90 -> 75 | S47: 2 | T47: 3 | U47: 3 | V47: 2 | W47: =((S47*$D$5/3)+(T47*$E$5/3)+(U47*$F$5/3)+(V47*$G$5/3))*90 -> 72 | X47: 3 | Y47: 3 | Z47: 3 | AA47: 2 | AB47: =((X47*$D$5/3)+(Y47*$E$5/3)+(Z47*$F$5/3)+(AA47*$G$5/3))*90 -> 75 | AC47: 0 | AD47: 0 | AE47: 0 | AF47: 0 | AG47: =((AC47*$D$5/3)+(AD47*$E$5/3)+(AE47*$F$5/3)+(AF47*$G$5/3))*90 -> 0
A48: ='INPUT DAFTAR PESERTA'!A45 -> 43 | B48: ='INPUT DAFTAR PESERTA'!B45 -> 2409076045 | C48: ='INPUT DAFTAR PESERTA'!C45 -> Ahmad Purwono Aji | D48: 3 | E48: 3 | F48: 3 | G48: 2 | H48: =((D48*$D$5/3)+(E48*$E$5/3)+(F48*$F$5/3)+(G48*$G$5/3))*90 -> 75 | I48: 2 | J48: 3 | K48: 3 | L48: 1 | M48: =((I48*$D$5/3)+(J48*$E$5/3)+(K48*$F$5/3)+(L48*$G$5/3))*90 -> 57 | N48: 3 | O48: 3 | P48: 2 | Q48: 1 | R48: =((N48*$D$5/3)+(O48*$E$5/3)+(P48*$F$5/3)+(Q48*$G$5/3))*90 -> 54 | S48: 2 | T48: 3 | U48: 2 | V48: 2 | W48: =((S48*$D$5/3)+(T48*$E$5/3)+(U48*$F$5/3)+(V48*$G$5/3))*90 -> 66 | X48: 1 | Y48: 1 | Z48: 1 | AA48: 1 | AB48: =((X48*$D$5/3)+(Y48*$E$5/3)+(Z48*$F$5/3)+(AA48*$G$5/3))*90 -> 30 | AC48: 0 | AD48: 0 | AE48: 0 | AF48: 0 | AG48: =((AC48*$D$5/3)+(AD48*$E$5/3)+(AE48*$F$5/3)+(AF48*$G$5/3))*90 -> 0
A49: ='INPUT DAFTAR PESERTA'!A46 -> 44 | B49: ='INPUT DAFTAR PESERTA'!B46 -> 2409076046 | C49: ='INPUT DAFTAR PESERTA'!C46 -> Muhammad Hasan Hanif | D49: 3 | E49: 3 | F49: 3 | G49: 2 | H49: =((D49*$D$5/3)+(E49*$E$5/3)+(F49*$F$5/3)+(G49*$G$5/3))*90 -> 75 | I49: 2 | J49: 3 | K49: 3 | L49: 0 | M49: =((I49*$D$5/3)+(J49*$E$5/3)+(K49*$F$5/3)+(L49*$G$5/3))*90 -> 42 | N49: 2 | O49: 2 | P49: 2 | Q49: 2 | R49: =((N49*$D$5/3)+(O49*$E$5/3)+(P49*$F$5/3)+(Q49*$G$5/3))*90 -> 60 | S49: 2 | T49: 2 | U49: 3 | V49: 1 | W49: =((S49*$D$5/3)+(T49*$E$5/3)+(U49*$F$5/3)+(V49*$G$5/3))*90 -> 51 | X49: 1 | Y49: 1 | Z49: 1 | AA49: 1 | AB49: =((X49*$D$5/3)+(Y49*$E$5/3)+(Z49*$F$5/3)+(AA49*$G$5/3))*90 -> 30 | AC49: 0 | AD49: 0 | AE49: 0 | AF49: 0 | AG49: =((AC49*$D$5/3)+(AD49*$E$5/3)+(AE49*$F$5/3)+(AF49*$G$5/3))*90 -> 0
A50: ='INPUT DAFTAR PESERTA'!A47 -> 45 | B50: ='INPUT DAFTAR PESERTA'!B47 -> 2409076047 | C50: ='INPUT DAFTAR PESERTA'!C47 -> Gilbert Pasolon | D50: 3 | E50: 3 | F50: 3 | G50: 2 | H50: =((D50*$D$5/3)+(E50*$E$5/3)+(F50*$F$5/3)+(G50*$G$5/3))*90 -> 75 | I50: 2 | J50: 3 | K50: 3 | L50: 2 | M50: =((I50*$D$5/3)+(J50*$E$5/3)+(K50*$F$5/3)+(L50*$G$5/3))*90 -> 72 | N50: 3 | O50: 3 | P50: 3 | Q50: 2 | R50: =((N50*$D$5/3)+(O50*$E$5/3)+(P50*$F$5/3)+(Q50*$G$5/3))*90 -> 75 | S50: 2 | T50: 3 | U50: 3 | V50: 2 | W50: =((S50*$D$5/3)+(T50*$E$5/3)+(U50*$F$5/3)+(V50*$G$5/3))*90 -> 72 | X50: 3 | Y50: 3 | Z50: 3 | AA50: 2 | AB50: =((X50*$D$5/3)+(Y50*$E$5/3)+(Z50*$F$5/3)+(AA50*$G$5/3))*90 -> 75 | AC50: 0 | AD50: 0 | AE50: 0 | AF50: 0 | AG50: =((AC50*$D$5/3)+(AD50*$E$5/3)+(AE50*$F$5/3)+(AF50*$G$5/3))*90 -> 0
A51: ='INPUT DAFTAR PESERTA'!A48 -> 46 | B51: ='INPUT DAFTAR PESERTA'!B48 -> 2409076048 | C51: ='INPUT DAFTAR PESERTA'!C48 -> Achmad Fauzan At-Tamimi | D51: 3 | E51: 2 | F51: 3 | G51: 3 | H51: =((D51*$D$5/3)+(E51*$E$5/3)+(F51*$F$5/3)+(G51*$G$5/3))*90 -> 84 | I51: 3 | J51: 3 | K51: 3 | L51: 3 | M51: =((I51*$D$5/3)+(J51*$E$5/3)+(K51*$F$5/3)+(L51*$G$5/3))*90 -> 90 | N51: 3 | O51: 3 | P51: 3 | Q51: 3 | R51: =((N51*$D$5/3)+(O51*$E$5/3)+(P51*$F$5/3)+(Q51*$G$5/3))*90 -> 90 | S51: 3 | T51: 3 | U51: 3 | V51: 3 | W51: =((S51*$D$5/3)+(T51*$E$5/3)+(U51*$F$5/3)+(V51*$G$5/3))*90 -> 90 | X51: 3 | Y51: 3 | Z51: 3 | AA51: 3 | AB51: =((X51*$D$5/3)+(Y51*$E$5/3)+(Z51*$F$5/3)+(AA51*$G$5/3))*90 -> 90 | AC51: 1 | AD51: 2 | AE51: 2 | AF51: 1 | AG51: =((AC51*$D$5/3)+(AD51*$E$5/3)+(AE51*$F$5/3)+(AF51*$G$5/3))*90 -> 42
A52: ='INPUT DAFTAR PESERTA'!A49 -> 47 | B52: ='INPUT DAFTAR PESERTA'!B49 -> 2409076049 | C52: ='INPUT DAFTAR PESERTA'!C49 -> Mahmud Abdul Aziz Qoby | D52: 3 | E52: 2 | F52: 3 | G52: 3 | H52: =((D52*$D$5/3)+(E52*$E$5/3)+(F52*$F$5/3)+(G52*$G$5/3))*90 -> 84 | I52: 3 | J52: 3 | K52: 3 | L52: 1 | M52: =((I52*$D$5/3)+(J52*$E$5/3)+(K52*$F$5/3)+(L52*$G$5/3))*90 -> 60 | N52: 3 | O52: 3 | P52: 3 | Q52: 2 | R52: =((N52*$D$5/3)+(O52*$E$5/3)+(P52*$F$5/3)+(Q52*$G$5/3))*90 -> 75 | S52: 2 | T52: 3 | U52: 2 | V52: 3 | W52: =((S52*$D$5/3)+(T52*$E$5/3)+(U52*$F$5/3)+(V52*$G$5/3))*90 -> 81 | X52: 1 | Y52: 1 | Z52: 1 | AA52: 1 | AB52: =((X52*$D$5/3)+(Y52*$E$5/3)+(Z52*$F$5/3)+(AA52*$G$5/3))*90 -> 30 | AC52: 2 | AD52: 3 | AE52: 2 | AF52: 1 | AG52: =((AC52*$D$5/3)+(AD52*$E$5/3)+(AE52*$F$5/3)+(AF52*$G$5/3))*90 -> 51
A53: ='INPUT DAFTAR PESERTA'!A50 -> 48 | B53: ='INPUT DAFTAR PESERTA'!B50 -> 2409076050 | C53: ='INPUT DAFTAR PESERTA'!C50 -> Gde Nookie Carl Arya Susila | D53: 3 | E53: 2 | F53: 3 | G53: 3 | H53: =((D53*$D$5/3)+(E53*$E$5/3)+(F53*$F$5/3)+(G53*$G$5/3))*90 -> 84 | I53: 3 | J53: 3 | K53: 3 | L53: 2 | M53: =((I53*$D$5/3)+(J53*$E$5/3)+(K53*$F$5/3)+(L53*$G$5/3))*90 -> 75 | N53: 3 | O53: 3 | P53: 3 | Q53: 3 | R53: =((N53*$D$5/3)+(O53*$E$5/3)+(P53*$F$5/3)+(Q53*$G$5/3))*90 -> 90 | S53: 2 | T53: 3 | U53: 2 | V53: 3 | W53: =((S53*$D$5/3)+(T53*$E$5/3)+(U53*$F$5/3)+(V53*$G$5/3))*90 -> 81 | X53: 3 | Y53: 3 | Z53: 3 | AA53: 3 | AB53: =((X53*$D$5/3)+(Y53*$E$5/3)+(Z53*$F$5/3)+(AA53*$G$5/3))*90 -> 90 | AC53: 2 | AD53: 3 | AE53: 3 | AF53: 1 | AG53: =((AC53*$D$5/3)+(AD53*$E$5/3)+(AE53*$F$5/3)+(AF53*$G$5/3))*90 -> 57
A54: ='INPUT DAFTAR PESERTA'!A51 -> 49 | B54: ='INPUT DAFTAR PESERTA'!B51 -> 2409076051 | C54: ='INPUT DAFTAR PESERTA'!C51 -> Muhammad Afrizal | H54: =((D54*$D$5/3)+(E54*$E$5/3)+(F54*$F$5/3)+(G54*$G$5/3))*90 -> 0 | M54: =((I54*$D$5/3)+(J54*$E$5/3)+(K54*$F$5/3)+(L54*$G$5/3))*90 -> 0 | R54: =((N54*$D$5/3)+(O54*$E$5/3)+(P54*$F$5/3)+(Q54*$G$5/3))*90 -> 0 | W54: =((S54*$D$5/3)+(T54*$E$5/3)+(U54*$F$5/3)+(V54*$G$5/3))*90 -> 0 | AB54: =((X54*$D$5/3)+(Y54*$E$5/3)+(Z54*$F$5/3)+(AA54*$G$5/3))*90 -> 0 | AG54: =((AC54*$D$5/3)+(AD54*$E$5/3)+(AE54*$F$5/3)+(AF54*$G$5/3))*90 -> 0
A55: ='INPUT DAFTAR PESERTA'!A52 -> 50 | B55: ='INPUT DAFTAR PESERTA'!B52 -> 2409076052 | C55: ='INPUT DAFTAR PESERTA'!C52 -> Rezky Yutabse | D55: 3 | E55: 3 | F55: 3 | G55: 3 | H55: =((D55*$D$5/3)+(E55*$E$5/3)+(F55*$F$5/3)+(G55*$G$5/3))*90 -> 90 | I55: 3 | J55: 3 | K55: 3 | L55: 2 | M55: =((I55*$D$5/3)+(J55*$E$5/3)+(K55*$F$5/3)+(L55*$G$5/3))*90 -> 75 | N55: 3 | O55: 3 | P55: 3 | Q55: 2 | R55: =((N55*$D$5/3)+(O55*$E$5/3)+(P55*$F$5/3)+(Q55*$G$5/3))*90 -> 75 | S55: 2 | T55: 3 | U55: 3 | V55: 3 | W55: =((S55*$D$5/3)+(T55*$E$5/3)+(U55*$F$5/3)+(V55*$G$5/3))*90 -> 87 | X55: 3 | Y55: 3 | Z55: 3 | AA55: 3 | AB55: =((X55*$D$5/3)+(Y55*$E$5/3)+(Z55*$F$5/3)+(AA55*$G$5/3))*90 -> 90 | AC55: 3 | AD55: 3 | AE55: 2 | AF55: 1 | AG55: =((AC55*$D$5/3)+(AD55*$E$5/3)+(AE55*$F$5/3)+(AF55*$G$5/3))*90 -> 54
A56: ='INPUT DAFTAR PESERTA'!A53 -> 51 | B56: ='INPUT DAFTAR PESERTA'!B53 -> 2409076053 | C56: ='INPUT DAFTAR PESERTA'!C53 -> Dimas Wijaya Muliangto | D56: 3 | E56: 3 | F56: 3 | G56: 3 | H56: =((D56*$D$5/3)+(E56*$E$5/3)+(F56*$F$5/3)+(G56*$G$5/3))*90 -> 90 | I56: 3 | J56: 3 | K56: 3 | L56: 2 | M56: =((I56*$D$5/3)+(J56*$E$5/3)+(K56*$F$5/3)+(L56*$G$5/3))*90 -> 75 | N56: 3 | O56: 3 | P56: 3 | Q56: 3 | R56: =((N56*$D$5/3)+(O56*$E$5/3)+(P56*$F$5/3)+(Q56*$G$5/3))*90 -> 90 | S56: 2 | T56: 3 | U56: 2 | V56: 3 | W56: =((S56*$D$5/3)+(T56*$E$5/3)+(U56*$F$5/3)+(V56*$G$5/3))*90 -> 81 | X56: 3 | Y56: 3 | Z56: 3 | AA56: 3 | AB56: =((X56*$D$5/3)+(Y56*$E$5/3)+(Z56*$F$5/3)+(AA56*$G$5/3))*90 -> 90 | AC56: 3 | AD56: 3 | AE56: 2 | AF56: 1 | AG56: =((AC56*$D$5/3)+(AD56*$E$5/3)+(AE56*$F$5/3)+(AF56*$G$5/3))*90 -> 54
A57: ='INPUT DAFTAR PESERTA'!A54 -> 52 | B57: ='INPUT DAFTAR PESERTA'!B54 -> 2409076054 | C57: ='INPUT DAFTAR PESERTA'!C54 -> Muhammad Aldi | D57: 3 | E57: 3 | F57: 3 | G57: 3 | H57: =((D57*$D$5/3)+(E57*$E$5/3)+(F57*$F$5/3)+(G57*$G$5/3))*90 -> 90 | I57: 3 | J57: 3 | K57: 3 | L57: 3 | M57: =((I57*$D$5/3)+(J57*$E$5/3)+(K57*$F$5/3)+(L57*$G$5/3))*90 -> 90 | N57: 3 | O57: 3 | P57: 3 | Q57: 3 | R57: =((N57*$D$5/3)+(O57*$E$5/3)+(P57*$F$5/3)+(Q57*$G$5/3))*90 -> 90 | S57: 2 | T57: 3 | U57: 3 | V57: 2 | W57: =((S57*$D$5/3)+(T57*$E$5/3)+(U57*$F$5/3)+(V57*$G$5/3))*90 -> 72 | X57: 3 | Y57: 3 | Z57: 3 | AA57: 3 | AB57: =((X57*$D$5/3)+(Y57*$E$5/3)+(Z57*$F$5/3)+(AA57*$G$5/3))*90 -> 90 | AC57: 2 | AD57: 2 | AE57: 3 | AF57: 1 | AG57: =((AC57*$D$5/3)+(AD57*$E$5/3)+(AE57*$F$5/3)+(AF57*$G$5/3))*90 -> 51
A58: ='INPUT DAFTAR PESERTA'!A55 -> 53 | B58: ='INPUT DAFTAR PESERTA'!B55 -> 2409076056 | C58: ='INPUT DAFTAR PESERTA'!C55 -> Rivaldy Paredanun | D58: 3 | E58: 3 | F58: 3 | G58: 3 | H58: =((D58*$D$5/3)+(E58*$E$5/3)+(F58*$F$5/3)+(G58*$G$5/3))*90 -> 90 | I58: 3 | J58: 3 | K58: 3 | L58: 2 | M58: =((I58*$D$5/3)+(J58*$E$5/3)+(K58*$F$5/3)+(L58*$G$5/3))*90 -> 75 | N58: 3 | O58: 3 | P58: 3 | Q58: 1 | R58: =((N58*$D$5/3)+(O58*$E$5/3)+(P58*$F$5/3)+(Q58*$G$5/3))*90 -> 60 | S58: 2 | T58: 2 | U58: 2 | V58: 2 | W58: =((S58*$D$5/3)+(T58*$E$5/3)+(U58*$F$5/3)+(V58*$G$5/3))*90 -> 60 | X58: 1 | Y58: 1 | Z58: 1 | AA58: 1 | AB58: =((X58*$D$5/3)+(Y58*$E$5/3)+(Z58*$F$5/3)+(AA58*$G$5/3))*90 -> 30 | AC58: 1 | AD58: 2 | AE58: 2 | AF58: 1 | AG58: =((AC58*$D$5/3)+(AD58*$E$5/3)+(AE58*$F$5/3)+(AF58*$G$5/3))*90 -> 42
A59: ='INPUT DAFTAR PESERTA'!A56 -> 54 | B59: ='INPUT DAFTAR PESERTA'!B56 -> 2409076024 | C59: ='INPUT DAFTAR PESERTA'!C56 -> Muhammad Zacky | D59: 3 | E59: 3 | F59: 3 | G59: 3 | H59: =((D59*$D$5/3)+(E59*$E$5/3)+(F59*$F$5/3)+(G59*$G$5/3))*90 -> 90 | I59: 3 | J59: 3 | K59: 3 | L59: 3 | M59: =((I59*$D$5/3)+(J59*$E$5/3)+(K59*$F$5/3)+(L59*$G$5/3))*90 -> 90 | N59: 3 | O59: 3 | P59: 3 | Q59: 3 | R59: =((N59*$D$5/3)+(O59*$E$5/3)+(P59*$F$5/3)+(Q59*$G$5/3))*90 -> 90 | S59: 2 | T59: 3 | U59: 2 | V59: 3 | W59: =((S59*$D$5/3)+(T59*$E$5/3)+(U59*$F$5/3)+(V59*$G$5/3))*90 -> 81 | X59: 3 | Y59: 3 | Z59: 3 | AA59: 3 | AB59: =((X59*$D$5/3)+(Y59*$E$5/3)+(Z59*$F$5/3)+(AA59*$G$5/3))*90 -> 90 | AC59: 3 | AD59: 3 | AE59: 2 | AF59: 2 | AG59: =((AC59*$D$5/3)+(AD59*$E$5/3)+(AE59*$F$5/3)+(AF59*$G$5/3))*90 -> 69

Sheet NILAI HARIAN
A1: HOME
A3: NO | B3: NIM | C3: NAMA | D3: Afektif | L3: Kognitif | Z3: Psikomotorik
D4: Kehadiran | K4: Laporan | L4: Responsi | S4: Proses Asistensi | Z4: Kemampuan Praktek
D5: 1 | E5: 2 | F5: 3 | G5: 4 | H5: 5 | I5: 6 | J5: Rata-rata | K5: Rata-rata | L5: 1 | M5: 2 | N5: 3 | O5: 4 | P5: 5 | Q5: 6 | R5: Rata-rata | S5: 1 | T5: 2 | U5: 3 | V5: 4 | W5: 5 | X5: 6 | Y5: Rata-rata | Z5: 1 | AA5: 2 | AB5: 3 | AC5: 4 | AD5: 5 | AE5: 6 | AF5: Rata-rata
A6: ='INPUT DAFTAR PESERTA'!A3 -> 1 | B6: ='INPUT DAFTAR PESERTA'!B3 -> 2409076001 | C6: ='INPUT DAFTAR PESERTA'!C3 -> Muhammad Jodika | D6: 100 | E6: 100 | F6: 100 | G6: 100 | H6: 100 | I6: 100 | J6: =(D6+E6+F6+G6+H6+I6)/6 -> 100 | K6: ='PENULISAN LAPORAN'!L5 -> 91.333333 | L6: 94 | M6: 94 | N6: 94 | O6: 94 | P6: 94 | Q6: 94 | R6: =(L6+M6+N6+O6+P6+Q6)/6 -> 94 | S6: 80 | T6: 80 | U6: 100 | V6: 30 | W6: 80 | X6: 80 | Y6: =(S6+T6+U6+V6+X6+W6)/6 -> 75 | Z6: ='KEMAMPUAN PRAKTIKUM'!H6 -> 78 | AA6: ='KEMAMPUAN PRAKTIKUM'!M6 -> 84 | AB6: ='KEMAMPUAN PRAKTIKUM'!R6 -> 90 | AC6: ='KEMAMPUAN PRAKTIKUM'!W6 -> 81 | AD6: ='KEMAMPUAN PRAKTIKUM'!AB6 -> 90 | AE6: ='KEMAMPUAN PRAKTIKUM'!AG6 -> 90 | AF6: =AVERAGE(Z6:AE6) -> 85.5
A7: ='INPUT DAFTAR PESERTA'!A4 -> 2 | B7: ='INPUT DAFTAR PESERTA'!B4 -> 2409076002 | C7: ='INPUT DAFTAR PESERTA'!C4 -> Muhammad Rifqi Maulana | D7: 100 | E7: 100 | F7: 100 | G7: 100 | H7: 100 | I7: 100 | J7: =(D7+E7+F7+G7+H7+I7)/6 -> 100 | K7: ='PENULISAN LAPORAN'!L6 -> 80.125 | L7: 54 | M7: 54 | N7: 54 | O7: 54 | P7: 54 | Q7: 54 | R7: =(L7+M7+N7+O7+P7+Q7)/6 -> 54 | S7: 70 | T7: 70 | U7: 100 | V7: 60 | W7: 70 | X7: 70 | Y7: =(S7+T7+U7+V7+X7+W7)/6 -> 73.333333 | Z7: ='KEMAMPUAN PRAKTIKUM'!H7 -> 84 | AA7: ='KEMAMPUAN PRAKTIKUM'!M7 -> 69 | AB7: ='KEMAMPUAN PRAKTIKUM'!R7 -> 90 | AC7: ='KEMAMPUAN PRAKTIKUM'!W7 -> 81 | AD7: ='KEMAMPUAN PRAKTIKUM'!AB7 -> 90 | AE7: ='KEMAMPUAN PRAKTIKUM'!AG7 -> 45 | AF7: =AVERAGE(Z7:AE7) -> 76.5
A8: ='INPUT DAFTAR PESERTA'!A5 -> 3 | B8: ='INPUT DAFTAR PESERTA'!B5 -> 2409076003 | C8: ='INPUT DAFTAR PESERTA'!C5 -> Andhika Pratama | D8: 100 | E8: 100 | F8: 100 | G8: 100 | H8: 100 | I8: 100 | J8: =(D8+E8+F8+G8+H8+I8)/6 -> 100 | K8: ='PENULISAN LAPORAN'!L7 -> 69.416667 | L8: 86 | M8: 86 | N8: 86 | O8: 86 | P8: 86 | Q8: 86 | R8: =(L8+M8+N8+O8+P8+Q8)/6 -> 86 | S8: 70 | T8: 0 | U8: 80 | V8: 30 | W8: 70 | X8: 30 | Y8: =(S8+T8+U8+V8+X8+W8)/6 -> 46.666667 | Z8: ='KEMAMPUAN PRAKTIKUM'!H8 -> 84 | AA8: ='KEMAMPUAN PRAKTIKUM'!M8 -> 57 | AB8: ='KEMAMPUAN PRAKTIKUM'!R8 -> 60 | AC8: ='KEMAMPUAN PRAKTIKUM'!W8 -> 75 | AD8: ='KEMAMPUAN PRAKTIKUM'!AB8 -> 90 | AE8: ='KEMAMPUAN PRAKTIKUM'!AG8 -> 45 | AF8: =AVERAGE(Z8:AE8) -> 68.5
A9: ='INPUT DAFTAR PESERTA'!A6 -> 4 | B9: ='INPUT DAFTAR PESERTA'!B6 -> 2409076004 | C9: ='INPUT DAFTAR PESERTA'!C6 -> Nur Aqmarina | D9: 100 | E9: 100 | F9: 100 | G9: 100 | H9: 100 | I9: 100 | J9: =(D9+E9+F9+G9+H9+I9)/6 -> 100 | K9: ='PENULISAN LAPORAN'!L8 -> 87.583333 | L9: 94 | M9: 94 | N9: 94 | O9: 94 | P9: 94 | Q9: 94 | R9: =(L9+M9+N9+O9+P9+Q9)/6 -> 94 | S9: 80 | T9: 80 | U9: 80 | V9: 70 | W9: 80 | X9: 80 | Y9: =(S9+T9+U9+V9+X9+W9)/6 -> 78.333333 | Z9: ='KEMAMPUAN PRAKTIKUM'!H9 -> 78 | AA9: ='KEMAMPUAN PRAKTIKUM'!M9 -> 54 | AB9: ='KEMAMPUAN PRAKTIKUM'!R9 -> 90 | AC9: ='KEMAMPUAN PRAKTIKUM'!W9 -> 81 | AD9: ='KEMAMPUAN PRAKTIKUM'!AB9 -> 90 | AE9: ='KEMAMPUAN PRAKTIKUM'!AG9 -> 63 | AF9: =AVERAGE(Z9:AE9) -> 76
A10: ='INPUT DAFTAR PESERTA'!A7 -> 5 | B10: ='INPUT DAFTAR PESERTA'!B7 -> 2409076005 | C10: ='INPUT DAFTAR PESERTA'!C7 -> Rias Prihatanto | D10: 100 | E10: 100 | F10: 100 | G10: 100 | H10: 100 | I10: 100 | J10: =(D10+E10+F10+G10+H10+I10)/6 -> 100 | K10: ='PENULISAN LAPORAN'!L9 -> 87.333333 | L10: 88 | M10: 88 | N10: 88 | O10: 88 | P10: 88 | Q10: 88 | R10: =(L10+M10+N10+O10+P10+Q10)/6 -> 88 | S10: 80 | T10: 70 | U10: 80 | V10: 70 | W10: 80 | X10: 80 | Y10: =(S10+T10+U10+V10+X10+W10)/6 -> 76.666667 | Z10: ='KEMAMPUAN PRAKTIKUM'!H10 -> 90 | AA10: ='KEMAMPUAN PRAKTIKUM'!M10 -> 54 | AB10: ='KEMAMPUAN PRAKTIKUM'!R10 -> 90 | AC10: ='KEMAMPUAN PRAKTIKUM'!W10 -> 81 | AD10: ='KEMAMPUAN PRAKTIKUM'!AB10 -> 90 | AE10: ='KEMAMPUAN PRAKTIKUM'!AG10 -> 90 | AF10: =AVERAGE(Z10:AE10) -> 82.5
A11: ='INPUT DAFTAR PESERTA'!A8 -> 6 | B11: ='INPUT DAFTAR PESERTA'!B8 -> 2409076006 | C11: ='INPUT DAFTAR PESERTA'!C8 -> Muhammad Maulana Bhagaskara | D11: 100 | E11: 100 | F11: 100 | G11: 100 | H11: 100 | I11: 100 | J11: =(D11+E11+F11+G11+H11+I11)/6 -> 100 | K11: ='PENULISAN LAPORAN'!L10 -> 85.125 | L11: 64 | M11: 64 | N11: 64 | O11: 64 | P11: 64 | Q11: 64 | R11: =(L11+M11+N11+O11+P11+Q11)/6 -> 64 | S11: 80 | T11: 80 | U11: 80 | V11: 60 | W11: 80 | X11: 70 | Y11: =(S11+T11+U11+V11+X11+W11)/6 -> 75 | Z11: ='KEMAMPUAN PRAKTIKUM'!H11 -> 90 | AA11: ='KEMAMPUAN PRAKTIKUM'!M11 -> 69 | AB11: ='KEMAMPUAN PRAKTIKUM'!R11 -> 90 | AC11: ='KEMAMPUAN PRAKTIKUM'!W11 -> 81 | AD11: ='KEMAMPUAN PRAKTIKUM'!AB11 -> 90 | AE11: ='KEMAMPUAN PRAKTIKUM'!AG11 -> 72 | AF11: =AVERAGE(Z11:AE11) -> 82
A12: ='INPUT DAFTAR PESERTA'!A9 -> 7 | B12: ='INPUT DAFTAR PESERTA'!B9 -> 2409076007 | C12: ='INPUT DAFTAR PESERTA'!C9 -> Chelsi Kamera | D12: 100 | E12: 100 | F12: 100 | G12: 100 | H12: 100 | I12: 100 | J12: =(D12+E12+F12+G12+H12+I12)/6 -> 100 | K12: ='PENULISAN LAPORAN'!L11 -> 88 | L12: 92 | M12: 92 | N12: 92 | O12: 92 | P12: 92 | Q12: 92 | R12: =(L12+M12+N12+O12+P12+Q12)/6 -> 92 | S12: 80 | T12: 80 | U12: 80 | V12: 60 | W12: 80 | X12: 80 | Y12: =(S12+T12+U12+V12+X12+W12)/6 -> 76.666667 | Z12: ='KEMAMPUAN PRAKTIKUM'!H12 -> 90 | AA12: ='KEMAMPUAN PRAKTIKUM'!M12 -> 69 | AB12: ='KEMAMPUAN PRAKTIKUM'!R12 -> 90 | AC12: ='KEMAMPUAN PRAKTIKUM'!W12 -> 87 | AD12: ='KEMAMPUAN PRAKTIKUM'!AB12 -> 90 | AE12: ='KEMAMPUAN PRAKTIKUM'!AG12 -> 90 | AF12: =AVERAGE(Z12:AE12) -> 86
A13: ='INPUT DAFTAR PESERTA'!A10 -> 8 | B13: ='INPUT DAFTAR PESERTA'!B10 -> 2409076008 | C13: ='INPUT DAFTAR PESERTA'!C10 -> Riyan Maulana | D13: 100 | E13: 100 | F13: 100 | G13: 100 | H13: 100 | I13: 100 | J13: =(D13+E13+F13+G13+H13+I13)/6 -> 100 | K13: ='PENULISAN LAPORAN'!L12 -> 75.791667 | L13: 92 | M13: 92 | N13: 92 | O13: 92 | P13: 92 | Q13: 92 | R13: =(L13+M13+N13+O13+P13+Q13)/6 -> 92 | S13: 80 | T13: 80 | U13: 80 | V13: 60 | W13: 70 | X13: 30 | Y13: =(S13+T13+U13+V13+X13+W13)/6 -> 66.666667 | Z13: ='KEMAMPUAN PRAKTIKUM'!H13 -> 60 | AA13: ='KEMAMPUAN PRAKTIKUM'!M13 -> 60 | AB13: ='KEMAMPUAN PRAKTIKUM'!R13 -> 90 | AC13: ='KEMAMPUAN PRAKTIKUM'!W13 -> 75 | AD13: ='KEMAMPUAN PRAKTIKUM'!AB13 -> 90 | AE13: ='KEMAMPUAN PRAKTIKUM'!AG13 -> 75 | AF13: =AVERAGE(Z13:AE13) -> 75
A14: ='INPUT DAFTAR PESERTA'!A11 -> 9 | B14: ='INPUT DAFTAR PESERTA'!B11 -> 2409076009 | C14: ='INPUT DAFTAR PESERTA'!C11 -> Dimas Prasetyo Wibowo | D14: 100 | E14: 100 | F14: 100 | G14: 100 | H14: 100 | I14: 100 | J14: =(D14+E14+F14+G14+H14+I14)/6 -> 100 | K14: ='PENULISAN LAPORAN'!L13 -> 83.291667 | L14: 94 | M14: 94 | N14: 94 | O14: 94 | P14: 94 | Q14: 94 | R14: =(L14+M14+N14+O14+P14+Q14)/6 -> 94 | S14: 80 | T14: 70 | U14: 80 | V14: 60 | W14: 80 | X14: 80 | Y14: =(S14+T14+U14+V14+X14+W14)/6 -> 75 | Z14: ='KEMAMPUAN PRAKTIKUM'!H14 -> 90 | AA14: ='KEMAMPUAN PRAKTIKUM'!M14 -> 69 | AB14: ='KEMAMPUAN PRAKTIKUM'!R14 -> 75 | AC14: ='KEMAMPUAN PRAKTIKUM'!W14 -> 81 | AD14: ='KEMAMPUAN PRAKTIKUM'!AB14 -> 90 | AE14: ='KEMAMPUAN PRAKTIKUM'!AG14 -> 75 | AF14: =AVERAGE(Z14:AE14) -> 80
A15: ='INPUT DAFTAR PESERTA'!A12 -> 10 | B15: ='INPUT DAFTAR PESERTA'!B12 -> 2409076010 | C15: ='INPUT DAFTAR PESERTA'!C12 -> Najwa Dwi Maylani | D15: 100 | E15: 100 | F15: 100 | G15: 100 | H15: 100 | I15: 100 | J15: =(D15+E15+F15+G15+H15+I15)/6 -> 100 | K15: ='PENULISAN LAPORAN'!L14 -> 85.125 | L15: 80 | M15: 80 | N15: 80 | O15: 80 | P15: 80 | Q15: 80 | R15: =(L15+M15+N15+O15+P15+Q15)/6 -> 80 | S15: 80 | T15: 70 | U15: 80 | V15: 70 | W15: 80 | X15: 80 | Y15: =(S15+T15+U15+V15+X15+W15)/6 -> 76.666667 | Z15: ='KEMAMPUAN PRAKTIKUM'!H15 -> 90 | AA15: ='KEMAMPUAN PRAKTIKUM'!M15 -> 69 | AB15: ='KEMAMPUAN PRAKTIKUM'!R15 -> 90 | AC15: ='KEMAMPUAN PRAKTIKUM'!W15 -> 87 | AD15: ='KEMAMPUAN PRAKTIKUM'!AB15 -> 90 | AE15: ='KEMAMPUAN PRAKTIKUM'!AG15 -> 75 | AF15: =AVERAGE(Z15:AE15) -> 83.5
A16: ='INPUT DAFTAR PESERTA'!A13 -> 11 | B16: ='INPUT DAFTAR PESERTA'!B13 -> 2409076011 | C16: ='INPUT DAFTAR PESERTA'!C13 -> Surya Ardhian Mokodongan | D16: 100 | E16: 100 | F16: 100 | G16: 100 | H16: 100 | I16: 100 | J16: =(D16+E16+F16+G16+H16+I16)/6 -> 100 | K16: ='PENULISAN LAPORAN'!L15 -> 85.208333 | L16: 92 | M16: 92 | N16: 92 | O16: 92 | P16: 92 | Q16: 92 | R16: =(L16+M16+N16+O16+P16+Q16)/6 -> 92 | S16: 80 | T16: 80 | U16: 80 | V16: 70 | W16: 80 | X16: 80 | Y16: =(S16+T16+U16+V16+X16+W16)/6 -> 78.333333 | Z16: ='KEMAMPUAN PRAKTIKUM'!H16 -> 90 | AA16: ='KEMAMPUAN PRAKTIKUM'!M16 -> 90 | AB16: ='KEMAMPUAN PRAKTIKUM'!R16 -> 90 | AC16: ='KEMAMPUAN PRAKTIKUM'!W16 -> 57 | AD16: ='KEMAMPUAN PRAKTIKUM'!AB16 -> 90 | AE16: ='KEMAMPUAN PRAKTIKUM'!AG16 -> 75 | AF16: =AVERAGE(Z16:AE16) -> 82
A17: ='INPUT DAFTAR PESERTA'!A14 -> 12 | B17: ='INPUT DAFTAR PESERTA'!B14 -> 2409076012 | C17: ='INPUT DAFTAR PESERTA'!C14 -> Ahmad Irfani Ananda Putra Hariawan | D17: 100 | E17: 100 | F17: 100 | G17: 100 | H17: 100 | I17: 100 | J17: =(D17+E17+F17+G17+H17+I17)/6 -> 100 | K17: ='PENULISAN LAPORAN'!L16 -> 80.166667 | L17: 76 | M17: 76 | N17: 76 | O17: 76 | P17: 76 | Q17: 76 | R17: =(L17+M17+N17+O17+P17+Q17)/6 -> 76 | S17: 80 | T17: 80 | U17: 80 | V17: 70 | W17: 70 | X17: 80 | Y17: =(S17+T17+U17+V17+X17+W17)/6 -> 76.666667 | Z17: ='KEMAMPUAN PRAKTIKUM'!H17 -> 90 | AA17: ='KEMAMPUAN PRAKTIKUM'!M17 -> 90 | AB17: ='KEMAMPUAN PRAKTIKUM'!R17 -> 75 | AC17: ='KEMAMPUAN PRAKTIKUM'!W17 -> 57 | AD17: ='KEMAMPUAN PRAKTIKUM'!AB17 -> 90 | AE17: ='KEMAMPUAN PRAKTIKUM'!AG17 -> 60 | AF17: =AVERAGE(Z17:AE17) -> 77
... A39: ='INPUT DAFTAR PESERTA'!A36 -> 34 | B39: ='INPUT DAFTAR PESERTA'!B36 -> 2409076035 | C39: ='INPUT DAFTAR PESERTA'!C36 -> Muhammad Rizki Nauval Alim | D39: 100 | E39: 100 | F39: 100 | G39: 100 | H39: 100 | I39: 100 | J39: =(D39+E39+F39+G39+H39+I39)/6 -> 100 | K39: ='PENULISAN LAPORAN'!L38 -> 86.166667 | L39: 82 | M39: 82 | N39: 82 | O39: 82 | P39: 82 | Q39: 82 | R39: =(L39+M39+N39+O39+P39+Q39)/6 -> 82 | S39: 80 | T39: 80 | U39: 80 | V39: 70 | W39: 80 | X39: 70 | Y39: =(S39+T39+U39+V39+X39+W39)/6 -> 76.666667 | Z39: ='KEMAMPUAN PRAKTIKUM'!H39 -> 90 | AA39: ='KEMAMPUAN PRAKTIKUM'!M39 -> 72 | AB39: ='KEMAMPUAN PRAKTIKUM'!R39 -> 90 | AC39: ='KEMAMPUAN PRAKTIKUM'!W39 -> 90 | AD39: ='KEMAMPUAN PRAKTIKUM'!AB39 -> 90 | AE39: ='KEMAMPUAN PRAKTIKUM'!AG39 -> 72 | AF39: =AVERAGE(Z39:AE39) -> 84
A40: ='INPUT DAFTAR PESERTA'!A37 -> 35 | B40: ='INPUT DAFTAR PESERTA'!B37 -> 2409076036 | C40: ='INPUT DAFTAR PESERTA'!C37 -> Muhammad Rico Setiawan | D40: 100 | E40: 100 | F40: 100 | G40: 100 | H40: 100 | I40: 0 | J40: =(D40+E40+F40+G40+H40+I40)/6 -> 83.333333 | K40: ='PENULISAN LAPORAN'!L39 -> 0 | L40: 84 | M40: 84 | N40: 84 | O40: 84 | P40: 84 | Q40: 84 | R40: =(L40+M40+N40+O40+P40+Q40)/6 -> 84 | Y40: =(S40+T40+U40+V40+X40+W40)/6 -> 0 | Z40: ='KEMAMPUAN PRAKTIKUM'!H40 -> 90 | AA40: ='KEMAMPUAN PRAKTIKUM'!M40 -> 0 | AB40: ='KEMAMPUAN PRAKTIKUM'!R40 -> 0 | AC40: ='KEMAMPUAN PRAKTIKUM'!W40 -> 0 | AD40: ='KEMAMPUAN PRAKTIKUM'!AB40 -> 0 | AE40: ='KEMAMPUAN PRAKTIKUM'!AG40 -> 0 | AF40: =AVERAGE(Z40:AE40) -> 15
