Workbook

Sheet INPUT DAFTAR PESERTA
A3: NO | B3: NIM | C3: Nama | E3: WORKSHEET TEMPLATE
A4: 1 | B4: 2109046048 | C4: Rafif Fitriansyah Nasution | E4: SISTEM PENILAIAN PRAKTIKUM
A5: 2 | B5: 2109046053 | C5: Muhamaad Rizky Ramdani | E5: LABORATORIUM LAYANAN DASAR
A6: 3 | B6: 2409046015 | C6: Nur Fadillah Septadi
A7: 4 | B7: 2409046026 | C7: Aisha Aqmarina Fathiyya Hawwa
A8: 5 | B8: 2409046027 | C8: Faykar Alfarisi Armadani
A9: 6 | B9: 2409046034 | C9: Annisa Nurdin
A10: 7 | B10: 2409046042 | C10: Aflahal Aula
A11: 8 | B11: 2409046045 | C11: Jofan Ananda Sulle
A12: 9 | B12: 2409046046 | C12: Muhammad Ananda Harisyah Putra | E12: VER 2 (April 2025)
A13: 10 | B13: 2409046048 | C13: Zaid Iman At-Tamam
A14: 11 | B14: 2409046050 | C14: Fachri Zia Pasha
A15: 12 | B15: 2409046051 | C15: Aziffa Reisazalea | E15: Petunjuk Penggunaan Template
A16: 13 | B16: 2409046054 | C16: Suci Andra Pramitha
A17: 14 | B17: 2409046056 | C17: Reira Praditha | E17: 1. Isikan daftar peserta praktikum pada sheet "INPUT DAFTAR PESERTA"
A18: 15 | B18: 2409046060 | C18: Ainaya Salsabila | E18: (Disarankan untuk menyesuaikan dengan template disamping)
A19: 16 | B19: 2504096069 | C19: Hafidz Ihsan Izzuddin | E19: 2. Isian Nama dan NIM pada sheet selanjutnya akan terinput secara otomatis sesuai dengan isian sheet "INPUT DAFTAR PESERTA"
A20: 17 | B20: 2509046001 | C20: Nurman Dwi Prasetyo | E20: 3. Nilai praktikum diisikan pada sheet "PENULISAN LAPORAN", "LAPORAN RESMI", "KEMAMPUAN PRAKTIKUM dan "NILAI HARIAN"
A21: 18 | B21: 2509046002 | C21: Farid Akmal | E21: 4. Rekapitulasi nilai praktikum permodul akan terakumulasi secara otomatis pada sheet "NILAI AKHIR" dan PIE-CHART"
A22: 19 | B22: 2509046003 | C22: Azzahra Tusitha | E22: 5. Perubahan formula pada sistem menyesuaikan dengan aturan dan SOP terbaru penilaian praktikum Lab Elektro Dasar
A23: 20 | B23: 2509046004 | C23: Ahmadia Syarifah Lauradinta | E23: 6. Link akses Surat Keterangan Lulus Praktikum sebagai berikut:
A24: 21 | B24: 2509046005 | C24: Seysa Puji Annura
A25: 22 | B25: 2509046006 | C25: Gita Ramadhani Supriyadi | E25: 7. Link akses Sheet perkomponen sebagai berikut:
A26: 23 | B26: 2509046007 | C26: Fabio Cannavaro Sinaga | E26: Penulisan Laporan
A27: 24 | B27: 2509046008 | C27: Hayatun Nisa | E27: Laporan Resmi
A28: 25 | B28: 2509046009 | C28: Khalilah Denissa Ardia Cahyani | E28: Kemampuan Praktikum
A29: 26 | B29: 2509046010 | C29: Athila Nadya Zalikha | E29: Nilai Harian
A30: 27 | B30: 2509046011 | C30: Aditya Pratama | E30: Nilai Akhir
A31: 28 | B31: 2509046012 | C31: Atiiqah Permata Hati | E31: Pie Chart
A32: 29 | B32: 2509046013 | C32: Yolanda Denis Aprilia
A33: 30 | B33: 2509046014 | C33: Farah Najma
A34: 31 | B34: 2509046015 | C34: Muhammad Abdul Mu'in
A35: 32 | B35: 2509046016 | C35: Muhammad Rofiq Al-Hakim
A36: 33 | B36: 2509046017 | C36: Nadia Eka Pratiwi
A37: 34 | B37: 2509046018 | C37: Rayhana Erda Affiyah
A38: 35 | B38: 2509046019 | C38: Astrina Nadhiroh Illiyin
A39: 36 | B39: 2509046020 | C39: Muhammad Davindia Akmaluza
A40: 37 | B40: 2509046021 | C40: Muhammad Naufal Sabilillah
A41: 38 | B41: 2509046022 | C41: Miranda Nur Salsabila
A42: 39 | B42: 2509046023 | C42: Dinar Rahmatheta
...

Sheet LAPORAN RESMI
A2: NO | B2: NIM | C2: NAMA | D2: Laporan Resmi | L2: Rata-rata
D3: Modul 1 | E3: Modul 2 | F3: Modul 3 | G3: Modul 4 | H3: Modul 5 | I3: Modul 6 | J3: Modul 7 | K3: Modul 8
A4: ='INPUT DAFTAR PESERTA'!A4 -> 1 | B4: ='INPUT DAFTAR PESERTA'!B4 -> 2109046048 | C4: ='INPUT DAFTAR PESERTA'!C4 -> Rafif Fitriansyah Nasution | D4: 86 | E4: 71 | F4: 96 | G4: 94 | H4: 95 | I4: 60 | J4: 87 | K4: 70 | L4: =(D4+E4+F4+G4+H4+I4+J4+K4)/8 -> 82.375
A5: ='INPUT DAFTAR PESERTA'!A5 -> 2 | B5: ='INPUT DAFTAR PESERTA'!B5 -> 2109046053 | C5: ='INPUT DAFTAR PESERTA'!C5 -> Muhamaad Rizky Ramdani | D5: 90 | E5: 50 | F5: 85 | G5: 90 | H5: 60 | I5: 60 | J5: 70 | K5: 70 | L5: =(D5+E5+F5+G5+H5+I5+J5+K5)/8 -> 71.875
A6: ='INPUT DAFTAR PESERTA'!A6 -> 3 | B6: ='INPUT DAFTAR PESERTA'!B6 -> 2409046015 | C6: ='INPUT DAFTAR PESERTA'!C6 -> Nur Fadillah Septadi | D6: 67 | E6: 75 | F6: 82 | G6: 80 | H6: 60 | I6: 30 | J6: 70 | K6: 95 | L6: =(D6+E6+F6+G6+H6+I6+J6+K6)/8 -> 69.875
A7: ='INPUT DAFTAR PESERTA'!A7 -> 4 | B7: ='INPUT DAFTAR PESERTA'!B7 -> 2409046026 | C7: ='INPUT DAFTAR PESERTA'!C7 -> Aisha Aqmarina Fathiyya Hawwa | D7: 98 | E7: 75 | F7: 95 | G7: 80 | H7: 80 | I7: 60 | J7: 70 | K7: 70 | L7: =(D7+E7+F7+G7+H7+I7+J7+K7)/8 -> 78.5
A8: ='INPUT DAFTAR PESERTA'!A8 -> 5 | B8: ='INPUT DAFTAR PESERTA'!B8 -> 2409046027 | C8: ='INPUT DAFTAR PESERTA'!C8 -> Faykar Alfarisi Armadani | D8: 29 | E8: 77 | F8: 100 | G8: 99 | H8: 99 | I8: 60 | J8: 90 | K8: 90 | L8: =(D8+E8+F8+G8+H8+I8+J8+K8)/8 -> 80.5
A9: ='INPUT DAFTAR PESERTA'!A9 -> 6 | B9: ='INPUT DAFTAR PESERTA'!B9 -> 2409046034 | C9: ='INPUT DAFTAR PESERTA'!C9 -> Annisa Nurdin | D9: 41.5 | E9: 87 | F9: 95 | G9: 92 | H9: 80 | I9: 60 | J9: 85 | K9: 70 | L9: =(D9+E9+F9+G9+H9+I9+J9+K9)/8 -> 76.3125
A10: ='INPUT DAFTAR PESERTA'!A10 -> 7 | B10: ='INPUT DAFTAR PESERTA'!B10 -> 2409046042 | C10: ='INPUT DAFTAR PESERTA'!C10 -> Aflahal Aula | D10: 45.5 | E10: 55 | F10: 100 | G10: 94 | H10: 100 | I10: 60 | J10: 90 | K10: 90 | L10: =(D10+E10+F10+G10+H10+I10+J10+K10)/8 -> 79.3125
A11: ='INPUT DAFTAR PESERTA'!A11 -> 8 | B11: ='INPUT DAFTAR PESERTA'!B11 -> 2409046045 | C11: ='INPUT DAFTAR PESERTA'!C11 -> Jofan Ananda Sulle | D11: 46 | E11: 80 | F11: 100 | G11: 99 | H11: 99 | I11: 60 | J11: 84 | K11: 85 | L11: =(D11+E11+F11+G11+H11+I11+J11+K11)/8 -> 81.625
A12: ='INPUT DAFTAR PESERTA'!A12 -> 9 | B12: ='INPUT DAFTAR PESERTA'!B12 -> 2409046046 | C12: ='INPUT DAFTAR PESERTA'!C12 -> Muhammad Ananda Harisyah Putra | D12: 90 | E12: 90 | F12: 90 | G12: 97 | H12: 100 | I12: 60 | J12: 96 | K12: 70 | L12: =(D12+E12+F12+G12+H12+I12+J12+K12)/8 -> 86.625
A13: ='INPUT DAFTAR PESERTA'!A13 -> 10 | B13: ='INPUT DAFTAR PESERTA'!B13 -> 2409046048 | C13: ='INPUT DAFTAR PESERTA'!C13 -> Zaid Iman At-Tamam | D13: 88 | E13: 82 | F13: 40 | G13: 88 | H13: 100 | I13: 40 | J13: 89 | K13: 70 | L13: =(D13+E13+F13+G13+H13+I13+J13+K13)/8 -> 74.625
A14: ='INPUT DAFTAR PESERTA'!A14 -> 11 | B14: ='INPUT DAFTAR PESERTA'!B14 -> 2409046050 | C14: ='INPUT DAFTAR PESERTA'!C14 -> Fachri Zia Pasha | D14: 85 | E14: 86 | F14: 100 | G14: 89 | H14: 100 | I14: 40 | J14: 75 | K14: 70 | L14: =(D14+E14+F14+G14+H14+I14+J14+K14)/8 -> 80.625
A15: ='INPUT DAFTAR PESERTA'!A15 -> 12 | B15: ='INPUT DAFTAR PESERTA'!B15 -> 2409046051 | C15: ='INPUT DAFTAR PESERTA'!C15 -> Aziffa Reisazalea | D15: 90 | E15: 93 | F15: 100 | G15: 89 | H15: 100 | I15: 80 | J15: 94 | K15: 70 | L15: =(D15+E15+F15+G15+H15+I15+J15+K15)/8 -> 89.5
... A18: ='INPUT DAFTAR PESERTA'!A18 -> 15 | B18: ='INPUT DAFTAR PESERTA'!B18 -> 2409046060 | C18: ='INPUT DAFTAR PESERTA'!C18 -> Ainaya Salsabila | D18: 90 | E18: 85 | F18: 98 | G18: 99 | H18: 80 | I18: 80 | J18: 98 | K18: 70 | L18: =(D18+E18+F18+G18+H18+I18+J18+K18)/8 -> 87.5
A19: ='INPUT DAFTAR PESERTA'!A19 -> 16 | B19: ='INPUT DAFTAR PESERTA'!B19 -> 2504096069 | C19: ='INPUT DAFTAR PESERTA'!C19 -> Hafidz Ihsan Izzuddin | L19: =(D19+E19+F19+G19+H19+I19+J19+K19)/8 -> 0
A20: ='INPUT DAFTAR PESERTA'!A20 -> 17 | B20: ='INPUT DAFTAR PESERTA'!B20 -> 2509046001 | C20: ='INPUT DAFTAR PESERTA'!C20 -> Nurman Dwi Prasetyo | D20: 80 | E20: 65 | F20: 90 | G20: 98 | H20: 80 | I20: 70 | J20: 60 | K20: 90 | L20: =(D20+E20+F20+G20+H20+I20+J20+K20)/8 -> 79.125
A21: ='INPUT DAFTAR PESERTA'!A21 -> 18 | B21: ='INPUT DAFTAR PESERTA'!B21 -> 2509046002 | C21: ='INPUT DAFTAR PESERTA'!C21 -> Farid Akmal | D21: 80 | E21: 85 | F21: 100 | G21: 94 | H21: 80 | I21: 100 | J21: 97 | K21: 98 | L21: =(D21+E21+F21+G21+H21+I21+J21+K21)/8 -> 91.75
A22: ='INPUT DAFTAR PESERTA'!A22 -> 19 | B22: ='INPUT DAFTAR PESERTA'!B22 -> 2509046003 | C22: ='INPUT DAFTAR PESERTA'!C22 -> Azzahra Tusitha | D22: 88 | E22: 95 | F22: 100 | G22: 98 | H22: 80 | I22: 100 | J22: 97 | K22: 98 | L22: =(D22+E22+F22+G22+H22+I22+J22+K22)/8 -> 94.5
A23: ='INPUT DAFTAR PESERTA'!A23 -> 20 | B23: ='INPUT DAFTAR PESERTA'!B23 -> 2509046004 | C23: ='INPUT DAFTAR PESERTA'!C23 -> Ahmadia Syarifah Lauradinta | D23: 75 | E23: 80 | F23: 95 | G23: 96 | H23: 80 | I23: 70 | J23: 70 | K23: 85 | L23: =(D23+E23+F23+G23+H23+I23+J23+K23)/8 -> 81.375
A24: ='INPUT DAFTAR PESERTA'!A24 -> 21 | B24: ='INPUT DAFTAR PESERTA'!B24 -> 2509046005 | C24: ='INPUT DAFTAR PESERTA'!C24 -> Seysa Puji Annura | D24: 80 | E24: 57 | F24: 60 | G24: 96 | H24: 80 | I24: 60 | J24: 70 | K24: 50 | L24: =(D24+E24+F24+G24+H24+I24+J24+K24)/8 -> 69.125
A25: ='INPUT DAFTAR PESERTA'!A25 -> 22 | B25: ='INPUT DAFTAR PESERTA'!B25 -> 2509046006 | C25: ='INPUT DAFTAR PESERTA'!C25 -> Gita Ramadhani Supriyadi | L25: =(D25+E25+F25+G25+H25+I25+J25+K25)/8 -> 0
A26: ='INPUT DAFTAR PESERTA'!A26 -> 23 | B26: ='INPUT DAFTAR PESERTA'!B26 -> 2509046007 | C26: ='INPUT DAFTAR PESERTA'!C26 -> Fabio Cannavaro Sinaga | D26: 90 | E26: 78 | F26: 100 | G26: 91 | H26: 80 | I26: 70 | J26: 95 | K26: 90 | L26: =(D26+E26+F26+G26+H26+I26+J26+K26)/8 -> 86.75
A27: ='INPUT DAFTAR PESERTA'!A27 -> 24 | B27: ='INPUT DAFTAR PESERTA'!B27 -> 2509046008 | C27: ='INPUT DAFTAR PESERTA'!C27 -> Hayatun Nisa | D27: 86 | E27: 64 | F27: 98 | G27: 96 | H27: 80 | I27: 35 | J27: 85 | K27: 70 | L27: =(D27+E27+F27+G27+H27+I27+J27+K27)/8 -> 76.75
A28: ='INPUT DAFTAR PESERTA'!A28 -> 25 | B28: ='INPUT DAFTAR PESERTA'!B28 -> 2509046009 | C28: ='INPUT DAFTAR PESERTA'!C28 -> Khalilah Denissa Ardia Cahyani | D28: 40 | E28: 40 | F28: 85 | G28: 30 | H28: 80 | I28: 15 | J28: 20 | K28: 70 | L28: =(D28+E28+F28+G28+H28+I28+J28+K28)/8 -> 47.5
A29: ='INPUT DAFTAR PESERTA'!A29 -> 26 | B29: ='INPUT DAFTAR PESERTA'!B29 -> 2509046010 | C29: ='INPUT DAFTAR PESERTA'!C29 -> Athila Nadya Zalikha | L29: =(D29+E29+F29+G29+H29+I29+J29+K29)/8 -> 0
A30: ='INPUT DAFTAR PESERTA'!A30 -> 27 | B30: ='INPUT DAFTAR PESERTA'!B30 -> 2509046011 | C30: ='INPUT DAFTAR PESERTA'!C30 -> Aditya Pratama | L30: =(D30+E30+F30+G30+H30+I30+J30+K30)/8 -> 0
A31: ='INPUT DAFTAR PESERTA'!A31 -> 28 | B31: ='INPUT DAFTAR PESERTA'!B31 -> 2509046012 | C31: ='INPUT DAFTAR PESERTA'!C31 -> Atiiqah Permata Hati | D31: 85 | E31: 0 | F31: 50 | G31: 83 | H31: 60 | I31: 40 | J31: 85 | K31: 70 | L31: =(D31+E31+F31+G31+H31+I31+J31+K31)/8 -> 59.125
A32: ='INPUT DAFTAR PESERTA'!A32 -> 29 | B32: ='INPUT DAFTAR PESERTA'!B32 -> 2509046013 | C32: ='INPUT DAFTAR PESERTA'!C32 -> Yolanda Denis Aprilia | D32: 92 | E32: 65 | F32: 95 | G32: 91 | H32: 85 | I32: 60 | J32: 80 | K32: 70 | L32: =(D32+E32+F32+G32+H32+I32+J32+K32)/8 -> 79.75
A33: ='INPUT DAFTAR PESERTA'!A33 -> 30 | B33: ='INPUT DAFTAR PESERTA'!B33 -> 2509046014 | C33: ='INPUT DAFTAR PESERTA'!C33 -> Farah Najma | D33: 86 | E33: 77 | F33: 50 | G33: 61 | H33: 80 | I33: 50 | J33: 80 | K33: 90 | L33: =(D33+E33+F33+G33+H33+I33+J33+K33)/8 -> 71.75
A34: ='INPUT DAFTAR PESERTA'!A34 -> 31 | B34: ='INPUT DAFTAR PESERTA'!B34 -> 2509046015 | C34: ='INPUT DAFTAR PESERTA'!C34 -> Muhammad Abdul Mu'in | D34: 92 | E34: 44 | F34: 100 | G34: 92 | H34: 80 | I34: 45 | J34: 88 | K34: 90 | L34: =(D34+E34+F34+G34+H34+I34+J34+K34)/8 -> 78.875
A35: ='INPUT DAFTAR PESERTA'!A35 -> 32 | B35: ='INPUT DAFTAR PESERTA'!B35 -> 2509046016 | C35: ='INPUT DAFTAR PESERTA'!C35 -> Muhammad Rofiq Al-Hakim | L35: =(D35+E35+F35+G35+H35+I35+J35+K35)/8 -> 0
A36: ='INPUT DAFTAR PESERTA'!A36 -> 33 | B36: ='INPUT DAFTAR PESERTA'!B36 -> 2509046017 | C36: ='INPUT DAFTAR PESERTA'!C36 -> Nadia Eka Pratiwi | D36: 90 | E36: 76 | F36: 100 | G36: 93 | H36: 80 | I36: 100 | J36: 98 | K36: 100 | L36: =(D36+E36+F36+G36+H36+I36+J36+K36)/8 -> 92.125
A37: ='INPUT DAFTAR PESERTA'!A37 -> 34 | B37: ='INPUT DAFTAR PESERTA'!B37 -> 2509046018 | C37: ='INPUT DAFTAR PESERTA'!C37 -> Rayhana Erda Affiyah | D37: 95 | E37: 71 | F37: 85 | G37: 95 | H37: 80 | I37: 100 | J37: 96 | K37: 95 | L37: =(D37+E37+F37+G37+H37+I37+J37+K37)/8 -> 89.625
A38: ='INPUT DAFTAR PESERTA'!A38 -> 35 | B38: ='INPUT DAFTAR PESERTA'!B38 -> 2509046019 | C38: ='INPUT DAFTAR PESERTA'!C38 -> Astrina Nadhiroh Illiyin | D38: 87 | E38: 62 | F38: 98 | G38: 97 | H38: 80 | I38: 70 | J38: 97 | K38: 75 | L38: =(D38+E38+F38+G38+H38+I38+J38+K38)/8 -> 83.25
A39: ='INPUT DAFTAR PESERTA'!A39 -> 36 | B39: ='INPUT DAFTAR PESERTA'!B39 -> 2509046020 | C39: ='INPUT DAFTAR PESERTA'!C39 -> Muhammad Davindia Akmaluza | L39: =(D39+E39+F39+G39+H39+I39+J39+K39)/8 -> 0
A40: ='INPUT DAFTAR PESERTA'!A40 -> 37 | B40: ='INPUT DAFTAR PESERTA'!B40 -> 2509046021 | C40: ='INPUT DAFTAR PESERTA'!C40 -> Muhammad Naufal Sabilillah | D40: 85 | E40: 70 | F40: 98 | G40: 99 | H40: 80 | I40: 100 | J40: 97 | K40: 98 | L40: =(D40+E40+F40+G40+H40+I40+J40+K40)/8 -> 90.875
A41: ='INPUT DAFTAR PESERTA'!A41 -> 38 | B41: ='INPUT DAFTAR PESERTA'!B41 -> 2509046022 | C41: ='INPUT DAFTAR PESERTA'!C41 -> Miranda Nur Salsabila | D41: 85 | E41: 71 | F41: 100 | G41: 96 | H41: 90 | I41: 75 | J41: 96 | K41: 95 | L41: =(D41+E41+F41+G41+H41+I41+J41+K41)/8 -> 88.5
A42: ='INPUT DAFTAR PESERTA'!A42 -> 39 | B42: ='INPUT DAFTAR PESERTA'!B42 -> 2509046023 | C42: ='INPUT DAFTAR PESERTA'!C42 -> Dinar Rahmatheta | D42: 100 | E42: 70 | F42: 98 | G42: 96 | H42: 80 | I42: 55 | J42: 90 | K42: 90 | L42: =(D42+E42+F42+G42+H42+I42+J42+K42)/8 -> 84.875
A43: ='INPUT DAFTAR PESERTA'!A43 -> 40 | B43: ='INPUT DAFTAR PESERTA'!B43 -> 2509046024 | C43: ='INPUT DAFTAR PESERTA'!C43 -> Muh. Yasir Naufal | L43: =(D43+E43+F43+G43+H43+I43+J43+K43)/8 -> 0
...

Sheet PENULISAN LAPORAN
A1: HOME
A3: NO | B3: Nim | C3: Nama | D3: Laporan Mingguan | L3: Rata-rata | M3: Resmi | N3: Nilai Akhir
D4: Modul 1 | E4: Modul 2 | F4: Modul 3 | G4: Modul 4 | H4: Modul 5 | I4: Modul 6 | J4: Modul 7 | K4: Modul 8 | L4: 0.5 | M4: 0.5
A5: ='INPUT DAFTAR PESERTA'!A4 -> 1 | B5: ='INPUT DAFTAR PESERTA'!B4 -> 2109046048 | C5: ='INPUT DAFTAR PESERTA'!C4 -> Rafif Fitriansyah Nasution | D5: 80 | E5: 71 | F5: 79 | G5: 94 | H5: 95 | I5: 36 | J5: 87 | K5: 0 | L5: =(D5+E5+F5+G5+H5+I5+J5+K5)/8 -> 67.75 | M5: ='LAPORAN RESMI'!L4 -> 82.375 | N5: =(L5*$L$4)+(M5*$M$4) -> 75.0625
A6: ='INPUT DAFTAR PESERTA'!A5 -> 2 | B6: ='INPUT DAFTAR PESERTA'!B5 -> 2109046053 | C6: ='INPUT DAFTAR PESERTA'!C5 -> Muhamaad Rizky Ramdani | D6: 83 | E6: 46 | F6: 49 | G6: 94 | H6: 90 | I6: 24 | J6: 55 | K6: 0 | L6: =(D6+E6+F6+G6+H6+I6+J6+K6)/8 -> 55.125 | M6: ='LAPORAN RESMI'!L5 -> 71.875 | N6: =(L6*$L$4)+(M6*$M$4) -> 63.5
A7: ='INPUT DAFTAR PESERTA'!A6 -> 3 | B7: ='INPUT DAFTAR PESERTA'!B6 -> 2409046015 | C7: ='INPUT DAFTAR PESERTA'!C6 -> Nur Fadillah Septadi | D7: 67 | E7: 72 | F7: 80 | G7: 93 | H7: 92 | I7: 45 | J7: 57 | K7: 0 | L7: =(D7+E7+F7+G7+H7+I7+J7+K7)/8 -> 63.25 | M7: ='LAPORAN RESMI'!L6 -> 69.875 | N7: =(L7*$L$4)+(M7*$M$4) -> 66.5625
A8: ='INPUT DAFTAR PESERTA'!A7 -> 4 | B8: ='INPUT DAFTAR PESERTA'!B7 -> 2409046026 | C8: ='INPUT DAFTAR PESERTA'!C7 -> Aisha Aqmarina Fathiyya Hawwa | D8: 98 | E8: 82 | F8: 46 | G8: 65 | H8: 40 | I8: 50 | J8: 0 | K8: 90 | L8: =(D8+E8+F8+G8+H8+I8+J8+K8)/8 -> 58.875 | M8: ='LAPORAN RESMI'!L7 -> 78.5 | N8: =(L8*$L$4)+(M8*$M$4) -> 68.6875
A9: ='INPUT DAFTAR PESERTA'!A8 -> 5 | B9: ='INPUT DAFTAR PESERTA'!B8 -> 2409046027 | C9: ='INPUT DAFTAR PESERTA'!C8 -> Faykar Alfarisi Armadani | D9: 29 | E9: 69 | F9: 63 | G9: 65 | H9: 80 | I9: 36 | J9: 80 | K9: 47 | L9: =(D9+E9+F9+G9+H9+I9+J9+K9)/8 -> 58.625 | M9: ='LAPORAN RESMI'!L8 -> 80.5 | N9: =(L9*$L$4)+(M9*$M$4) -> 69.5625
A10: ='INPUT DAFTAR PESERTA'!A9 -> 6 | B10: ='INPUT DAFTAR PESERTA'!B9 -> 2409046034 | C10: ='INPUT DAFTAR PESERTA'!C9 -> Annisa Nurdin | D10: 41.5 | E10: 85 | F10: 96 | G10: 96 | H10: 97 | I10: 30 | J10: 0 | K10: 0 | L10: =(D10+E10+F10+G10+H10+I10+J10+K10)/8 -> 55.6875 | M10: ='LAPORAN RESMI'!L9 -> 76.3125 | N10: =(L10*$L$4)+(M10*$M$4) -> 66
A11: ='INPUT DAFTAR PESERTA'!A10 -> 7 | B11: ='INPUT DAFTAR PESERTA'!B10 -> 2409046042 | C11: ='INPUT DAFTAR PESERTA'!C10 -> Aflahal Aula | D11: 45.5 | E11: 53 | F11: 89 | G11: 91 | H11: 98 | I11: 39 | J11: 85 | K11: 70 | L11: =(D11+E11+F11+G11+H11+I11+J11+K11)/8 -> 71.3125 | M11: ='LAPORAN RESMI'!L10 -> 79.3125 | N11: =(L11*$L$4)+(M11*$M$4) -> 75.3125
A12: ='INPUT DAFTAR PESERTA'!A11 -> 8 | B12: ='INPUT DAFTAR PESERTA'!B11 -> 2409046045 | C12: ='INPUT DAFTAR PESERTA'!C11 -> Jofan Ananda Sulle | D12: 46 | E12: 78 | F12: 92 | G12: 90 | H12: 97 | I12: 31 | J12: 84 | K12: 0 | L12: =(D12+E12+F12+G12+H12+I12+J12+K12)/8 -> 64.75 | M12: ='LAPORAN RESMI'!L11 -> 81.625 | N12: =(L12*$L$4)+(M12*$M$4) -> 73.1875
A13: ='INPUT DAFTAR PESERTA'!A12 -> 9 | B13: ='INPUT DAFTAR PESERTA'!B12 -> 2409046046 | C13: ='INPUT DAFTAR PESERTA'!C12 -> Muhammad Ananda Harisyah Putra | D13: 75 | E13: 83 | F13: 77 | G13: 93 | H13: 93 | I13: 44 | J13: 83 | K13: 58 | L13: =(D13+E13+F13+G13+H13+I13+J13+K13)/8 -> 75.75 | M13: ='LAPORAN RESMI'!L12 -> 86.625 | N13: =(L13*$L$4)+(M13*$M$4) -> 81.1875
A14: ='INPUT DAFTAR PESERTA'!A13 -> 10 | B14: ='INPUT DAFTAR PESERTA'!B13 -> 2409046048 | C14: ='INPUT DAFTAR PESERTA'!C13 -> Zaid Iman At-Tamam | D14: 57 | E14: 60 | F14: 43 | G14: 68 | H14: 86 | I14: 29 | J14: 68 | K14: 0 | L14: =(D14+E14+F14+G14+H14+I14+J14+K14)/8 -> 51.375 | M14: ='LAPORAN RESMI'!L13 -> 74.625 | N14: =(L14*$L$4)+(M14*$M$4) -> 63
A15: ='INPUT DAFTAR PESERTA'!A14 -> 11 | B15: ='INPUT DAFTAR PESERTA'!B14 -> 2409046050 | C15: ='INPUT DAFTAR PESERTA'!C14 -> Fachri Zia Pasha | D15: 67 | E15: 78 | F15: 88 | G15: 95 | H15: 88 | I15: 27 | J15: 75 | K15: 45 | L15: =(D15+E15+F15+G15+H15+I15+J15+K15)/8 -> 70.375 | M15: ='LAPORAN RESMI'!L14 -> 80.625 | N15: =(L15*$L$4)+(M15*$M$4) -> 75.5
A16: ='INPUT DAFTAR PESERTA'!A15 -> 12 | B16: ='INPUT DAFTAR PESERTA'!B15 -> 2409046051 | C16: ='INPUT DAFTAR PESERTA'!C15 -> Aziffa Reisazalea | D16: 80 | E16: 82 | F16: 89 | G16: 91 | H16: 93 | I16: 57 | J16: 81 | K16: 48 | L16: =(D16+E16+F16+G16+H16+I16+J16+K16)/8 -> 77.625 | M16: ='LAPORAN RESMI'!L15 -> 89.5 | N16: =(L16*$L$4)+(M16*$M$4) -> 83.5625
... A46: ='INPUT DAFTAR PESERTA'!A45 -> 42 | B46: ='INPUT DAFTAR PESERTA'!B45 -> 2509046026 | C46: ='INPUT DAFTAR PESERTA'!C45 -> Nabil Rafif Makarim | D46: 45 | E46: 0 | F46: 39 | G46: 0 | H46: 0 | I46: 16 | J46: 63 | K46: 44 | L46: =(D46+E46+F46+G46+H46+I46+J46+K46)/8 -> 25.875 | M46: ='LAPORAN RESMI'!L45 -> 73.875 | N46: =(L46*$L$4)+(M46*$M$4) -> 49.875
A47: 0 | B47: ='INPUT DAFTAR PESERTA'!B46 -> 2509046027 | C47: ='INPUT DAFTAR PESERTA'!C46 -> Natasya Camelia Az-Zahra | D47: 93 | E47: 68 | F47: 60 | G47: 0 | H47: 0 | I47: 30 | J47: 87 | K47: 89 | L47: =(D47+E47+F47+G47+H47+I47+J47+K47)/8 -> 53.375 | M47: ='LAPORAN RESMI'!L46 -> 89 | N47: =(L47*$L$4)+(M47*$M$4) -> 71.1875
A48: ='INPUT DAFTAR PESERTA'!A47 -> 44 | B48: ='INPUT DAFTAR PESERTA'!B47 -> 2509046028 | C48: ='INPUT DAFTAR PESERTA'!C47 -> Afirah Al Abidah | D48: 22 | E48: 0 | F48: 16 | G48: 42 | H48: 0 | I48: 20 | J48: 10 | K48: 26 | L48: =(D48+E48+F48+G48+H48+I48+J48+K48)/8 -> 17 | M48: ='LAPORAN RESMI'!L47 -> 39.375 | N48: =(L48*$L$4)+(M48*$M$4) -> 28.1875
A49: ='INPUT DAFTAR PESERTA'!A48 -> 45 | B49: ='INPUT DAFTAR PESERTA'!B48 -> 2509046029 | C49: ='INPUT DAFTAR PESERTA'!C48 -> Anisa Syalwa | D49: 85 | E49: 43 | F49: 38 | G49: 0 | H49: 0 | I49: 48 | J49: 46 | K49: 47 | L49: =(D49+E49+F49+G49+H49+I49+J49+K49)/8 -> 38.375 | M49: ='LAPORAN RESMI'!L48 -> 65.375 | N49: =(L49*$L$4)+(M49*$M$4) -> 51.875
A50: ='INPUT DAFTAR PESERTA'!A49 -> 46 | B50: ='INPUT DAFTAR PESERTA'!B49 -> 2509046030 | C50: ='INPUT DAFTAR PESERTA'!C49 -> Fikri Firoos Kinarya | D50: 87 | E50: 0 | F50: 45 | G50: 0 | H50: 0 | I50: 45 | J50: 0 | K50: 41 | L50: =(D50+E50+F50+G50+H50+I50+J50+K50)/8 -> 27.25 | M50: ='LAPORAN RESMI'!L49 -> 70.625 | N50: =(L50*$L$4)+(M50*$M$4) -> 48.9375
A51: ='INPUT DAFTAR PESERTA'!A50 -> 47 | B51: ='INPUT DAFTAR PESERTA'!B50 -> 2509046031 | C51: ='INPUT DAFTAR PESERTA'!C50 -> Armitha Luthfiana Andini | D51: 67 | E51: 0 | F51: 35 | G51: 0 | H51: 0 | I51: 19 | J51: 0 | K51: 27 | L51: =(D51+E51+F51+G51+H51+I51+J51+K51)/8 -> 18.5 | M51: ='LAPORAN RESMI'!L50 -> 70.75 | N51: =(L51*$L$4)+(M51*$M$4) -> 44.625
A52: ='INPUT DAFTAR PESERTA'!A51 -> 48 | B52: ='INPUT DAFTAR PESERTA'!B51 -> 2509046032 | C52: ='INPUT DAFTAR PESERTA'!C51 -> Fabio Aditya Purnomo | D52: 48 | E52: 43 | F52: 48 | G52: 80 | H52: 95 | I52: 73 | J52: 62 | K52: 40 | L52: =(D52+E52+F52+G52+H52+I52+J52+K52)/8 -> 61.125 | M52: ='LAPORAN RESMI'!L51 -> 81.625 | N52: =(L52*$L$4)+(M52*$M$4) -> 71.375
A53: ='INPUT DAFTAR PESERTA'!A52 -> 49 | B53: ='INPUT DAFTAR PESERTA'!B52 -> 2509046033 | C53: ='INPUT DAFTAR PESERTA'!C52 -> Rifa Davina Zalfa | D53: 50 | E53: 65 | F53: 63 | G53: 90 | H53: 0 | I53: 0 | J53: 65 | K53: 0 | L53: =(D53+E53+F53+G53+H53+I53+J53+K53)/8 -> 41.625 | M53: ='LAPORAN RESMI'!L52 -> 85.375 | N53: =(L53*$L$4)+(M53*$M$4) -> 63.5
A54: ='INPUT DAFTAR PESERTA'!A53 -> 50 | B54: ='INPUT DAFTAR PESERTA'!B53 -> 2509046034 | C54: ='INPUT DAFTAR PESERTA'!C53 -> Nilna Fergita Nouriansa | D54: 75 | E54: 42 | F54: 53 | G54: 57 | H54: 0 | I54: 0 | J54: 47 | K54: 24 | L54: =(D54+E54+F54+G54+H54+I54+J54+K54)/8 -> 37.25 | M54: ='LAPORAN RESMI'!L53 -> 85 | N54: =(L54*$L$4)+(M54*$M$4) -> 61.125
A55: ='INPUT DAFTAR PESERTA'!A54 -> 51 | B55: ='INPUT DAFTAR PESERTA'!B54 -> 2509046035 | C55: ='INPUT DAFTAR PESERTA'!C54 -> Sandi Prakoso | D55: 0 | E55: 0 | F55: 0 | G55: 0 | H55: 0 | I55: 0 | J55: 17 | K55: 35 | L55: =(D55+E55+F55+G55+H55+I55+J55+K55)/8 -> 6.5 | M55: ='LAPORAN RESMI'!L54 -> 0 | N55: =(L55*$L$4)+(M55*$M$4) -> 3.25
A56: ='INPUT DAFTAR PESERTA'!A55 -> 52 | B56: ='INPUT DAFTAR PESERTA'!B55 -> 2509046036 | C56: ='INPUT DAFTAR PESERTA'!C55 -> Yarasy Ebed Petra Richard Nanuru | D56: 0 | E56: 0 | F56: 0 | G56: 0 | H56: 0 | I56: 0 | J56: 0 | K56: 0 | L56: =(D56+E56+F56+G56+H56+I56+J56+K56)/8 -> 0 | M56: ='LAPORAN RESMI'!L55 -> 0 | N56: =(L56*$L$4)+(M56*$M$4) -> 0
A57: ='INPUT DAFTAR PESERTA'!A56 -> 53 | B57: ='INPUT DAFTAR PESERTA'!B56 -> 2509046037 | C57: ='INPUT DAFTAR PESERTA'!C56 -> Rasya Hanindya Putri | D57: 0 | E57: 0 | F57: 0 | G57: 0 | H57: 0 | I57: 17 | J57: 0 | K57: 0 | L57: =(D57+E57+F57+G57+H57+I57+J57+K57)/8 -> 2.125 | M57: ='LAPORAN RESMI'!L56 -> 0 | N57: =(L57*$L$4)+(M57*$M$4) -> 1.0625
A58: ='INPUT DAFTAR PESERTA'!A57 -> 54 | B58: ='INPUT DAFTAR PESERTA'!B57 -> 2509046038 | C58: ='INPUT DAFTAR PESERTA'!C57 -> Stefania Diah Pramestirehi | D58: 52 | E58: 75 | F58: 22 | G58: 93 | H58: 40 | I58: 45 | J58: 0 | K58: 0 | L58: =(D58+E58+F58+G58+H58+I58+J58+K58)/8 -> 40.875 | M58: ='LAPORAN RESMI'!L57 -> 88.375 | N58: =(L58*$L$4)+(M58*$M$4) -> 64.625
A59: ='INPUT DAFTAR PESERTA'!A58 -> 55 | B59: ='INPUT DAFTAR PESERTA'!B58 -> 2509046039 | C59: ='INPUT DAFTAR PESERTA'!C58 -> Azarina Azzahra | D59: 95 | E59: 93 | F59: 95 | G59: 96 | H59: 95 | I59: 20 | J59: 61 | K59: 78 | L59: =(D59+E59+F59+G59+H59+I59+J59+K59)/8 -> 79.125 | M59: ='LAPORAN RESMI'!L58 -> 96.25 | N59: =(L59*$L$4)+(M59*$M$4) -> 87.6875
... A98: ='INPUT DAFTAR PESERTA'!A97 -> 94 | B98: ='INPUT DAFTAR PESERTA'!B97 -> 2509046079 | C98: ='INPUT DAFTAR PESERTA'!C97 -> Muhamad Jailani | D98: 0 | E98: 0 | F98: 0 | G98: 0 | H98: 37 | I98: 0 | J98: 0 | K98: 0 | L98: =(D98+E98+F98+G98+H98+I98+J98+K98)/8 -> 4.625 | M98: ='LAPORAN RESMI'!L97 -> 0 | N98: =(L98*$L$4)+(M98*$M$4) -> 2.3125
B99: ='INPUT DAFTAR PESERTA'!B98
B100: ='INPUT DAFTAR PESERTA'!B99
B101: ='INPUT DAFTAR PESERTA'!B100

Sheet KEMAMPUAN PRAKTIKUM
A1: HOME
A3: NO | B3: NIM | C3: Nama | D3: Modul 1 | I3: Modul 2 | N3: Modul 3 | S3: Modul 4 | X3: Modul 5 | AC3: Modul 6 | AH3: Modul 7 | AM3: Modul 8
D4: K1 | E4: K2 | F4: K3 | G4: K4 | H4: Rerata | I4: K1 | J4: K2 | K4: K3 | L4: K4 | M4: Rerata | N4: K1 | O4: K2 | P4: K3 | Q4: K4 | R4: Rerata | S4: K1 | T4: K2 | U4: K3 | V4: K4 | W4: Rerata | X4: K1 | Y4: K2 | Z4: K3 | AA4: K4 | AB4: Rerata | AC4: K1 | AD4: K2 | AE4: K3 | AF4: K4 | AG4: Rerata | AH4: K1 | AI4: K2 | AJ4: K3 | AK4: K4 | AL4: Rerata | AM4: K1 | AN4: K2 | AO4: K3 | AP4: K4 | AQ4: Rerata
D5: 0.1 | E5: 0.2 | F5: 0.2 | G5: 0.5 | H5: 1 | I5: 0.1 | J5: 0.2 | K5: 0.2 | L5: 0.5 | M5: 1 | N5: 0.1 | O5: 0.2 | P5: 0.2 | Q5: 0.5 | R5: 1 | S5: 0.1 | T5: 0.2 | U5: 0.2 | V5: 0.5 | W5: 1 | X5: 0.1 | Y5: 0.2 | Z5: 0.2 | AA5: 0.5 | AB5: 1 | AC5: 0.1 | AD5: 0.2 | AE5: 0.2 | AF5: 0.5 | AG5: 1 | AH5: 0.1 | AI5: 0.2 | AJ5: 0.2 | AK5: 0.5 | AL5: 1 | AM5: 0.1 | AN5: 0.2 | AO5: 0.2 | AP5: 0.5 | AQ5: 1
A6: ='INPUT DAFTAR PESERTA'!A4 -> 1 | B6: ='INPUT DAFTAR PESERTA'!B4 -> 2109046048 | C6: ='INPUT DAFTAR PESERTA'!C4 -> Rafif Fitriansyah Nasution | D6: 2 | E6: 3 | F6: 3 | G6: 1 | H6: =((D6*$D$5/3)+(E6*$E$5/3)+(F6*$F$5/3)+(G6*$G$5/3))*90 -> 57 | I6: 3 | J6: 3 | K6: 3 | L6: 2 | M6: =((I6*$D$5/3)+(J6*$E$5/3)+(K6*$F$5/3)+(L6*$G$5/3))*90 -> 75 | N6: 3 | O6: 3 | P6: 3 | Q6: 3 | R6: =((N6*$D$5/3)+(O6*$E$5/3)+(P6*$F$5/3)+(Q6*$G$5/3))*90 -> 90 | S6: 3 | T6: 3 | U6: 3 | V6: 3 | W6: =((S6*$D$5/3)+(T6*$E$5/3)+(U6*$F$5/3)+(V6*$G$5/3))*90 -> 90 | X6: 3 | Y6: 2 | Z6: 2 | AA6: 3 | AB6: =((X6*$D$5/3)+(Y6*$E$5/3)+(Z6*$F$5/3)+(AA6*$G$5/3))*90 -> 78 | AC6: 3 | AD6: 2 | AE6: 2 | AF6: 2 | AG6: =((AC6*$D$5/3)+(AD6*$E$5/3)+(AE6*$F$5/3)+(AF6*$G$5/3))*90 -> 63 | AH6: 2 | AI6: 3 | AJ6: 3 | AK6: 3 | AL6: =((AH6*$D$5/3)+(AI6*$E$5/3)+(AJ6*$F$5/3)+(AK6*$G$5/3))*90 -> 87 | AM6: 2 | AN6: 3 | AO6: 3 | AP6: 1 | AQ6: =((AM6*$D$5/3)+(AN6*$E$5/3)+(AO6*$F$5/3)+(AP6*$G$5/3))*90 -> 57
A7: ='INPUT DAFTAR PESERTA'!A5 -> 2 | B7: ='INPUT DAFTAR PESERTA'!B5 -> 2109046053 | C7: ='INPUT DAFTAR PESERTA'!C5 -> Muhamaad Rizky Ramdani | D7: 2 | E7: 2 | F7: 3 | G7: 3 | H7: =((D7*$D$5/3)+(E7*$E$5/3)+(F7*$F$5/3)+(G7*$G$5/3))*90 -> 81 | I7: 3 | J7: 3 | K7: 3 | L7: 1 | M7: =((I7*$D$5/3)+(J7*$E$5/3)+(K7*$F$5/3)+(L7*$G$5/3))*90 -> 60 | N7: 3 | O7: 3 | P7: 3 | Q7: 2 | R7: =((N7*$D$5/3)+(O7*$E$5/3)+(P7*$F$5/3)+(Q7*$G$5/3))*90 -> 75 | S7: 3 | T7: 3 | U7: 3 | V7: 3 | W7: =((S7*$D$5/3)+(T7*$E$5/3)+(U7*$F$5/3)+(V7*$G$5/3))*90 -> 90 | X7: 3 | Y7: 2 | Z7: 2 | AA7: 3 | AB7: =((X7*$D$5/3)+(Y7*$E$5/3)+(Z7*$F$5/3)+(AA7*$G$5/3))*90 -> 78 | AC7: 3 | AD7: 2 | AE7: 2 | AF7: 2 | AG7: =((AC7*$D$5/3)+(AD7*$E$5/3)+(AE7*$F$5/3)+(AF7*$G$5/3))*90 -> 63 | AH7: 2 | AI7: 3 | AJ7: 3 | AK7: 2 | AL7: =((AH7*$D$5/3)+(AI7*$E$5/3)+(AJ7*$F$5/3)+(AK7*$G$5/3))*90 -> 72 | AM7: 2 | AN7: 3 | AO7: 3 | AP7: 1 | AQ7: =((AM7*$D$5/3)+(AN7*$E$5/3)+(AO7*$F$5/3)+(AP7*$G$5/3))*90 -> 57
A8: ='INPUT DAFTAR PESERTA'!A6 -> 3 | B8: ='INPUT DAFTAR PESERTA'!B6 -> 2409046015 | C8: ='INPUT DAFTAR PESERTA'!C6 -> Nur Fadillah Septadi | D8: 3 | E8: 2 | F8: 2 | G8: 2 | H8: =((D8*$D$5/3)+(E8*$E$5/3)+(F8*$F$5/3)+(G8*$G$5/3))*90 -> 63 | I8: 3 | J8: 3 | K8: 3 | L8: 2 | M8: =((I8*$D$5/3)+(J8*$E$5/3)+(K8*$F$5/3)+(L8*$G$5/3))*90 -> 75 | N8: 3 | O8: 3 | P8: 3 | Q8: 3 | R8: =((N8*$D$5/3)+(O8*$E$5/3)+(P8*$F$5/3)+(Q8*$G$5/3))*90 -> 90 | S8: 3 | T8: 3 | U8: 3 | V8: 3 | W8: =((S8*$D$5/3)+(T8*$E$5/3)+(U8*$F$5/3)+(V8*$G$5/3))*90 -> 90 | X8: 2 | Y8: 3 | Z8: 3 | AA8: 3 | AB8: =((X8*$D$5/3)+(Y8*$E$5/3)+(Z8*$F$5/3)+(AA8*$G$5/3))*90 -> 87 | AC8: 2 | AD8: 2 | AE8: 2 | AF8: 2 | AG8: =((AC8*$D$5/3)+(AD8*$E$5/3)+(AE8*$F$5/3)+(AF8*$G$5/3))*90 -> 60 | AH8: 2 | AI8: 3 | AJ8: 3 | AK8: 2 | AL8: =((AH8*$D$5/3)+(AI8*$E$5/3)+(AJ8*$F$5/3)+(AK8*$G$5/3))*90 -> 72 | AM8: 2 | AN8: 3 | AO8: 3 | AP8: 1 | AQ8: =((AM8*$D$5/3)+(AN8*$E$5/3)+(AO8*$F$5/3)+(AP8*$G$5/3))*90 -> 57
A9: ='INPUT DAFTAR PESERTA'!A7 -> 4 | B9: ='INPUT DAFTAR PESERTA'!B7 -> 2409046026 | C9: ='INPUT DAFTAR PESERTA'!C7 -> Aisha Aqmarina Fathiyya Hawwa | D9: 3 | E9: 2 | F9: 2 | G9: 3 | H9: =((D9*$D$5/3)+(E9*$E$5/3)+(F9*$F$5/3)+(G9*$G$5/3))*90 -> 78 | I9: 3 | J9: 3 | K9: 3 | L9: 3 | M9: =((I9*$D$5/3)+(J9*$E$5/3)+(K9*$F$5/3)+(L9*$G$5/3))*90 -> 90 | N9: 3 | O9: 3 | P9: 3 | Q9: 2 | R9: =((N9*$D$5/3)+(O9*$E$5/3)+(P9*$F$5/3)+(Q9*$G$5/3))*90 -> 75 | S9: 3 | T9: 3 | U9: 3 | V9: 2 | W9: =((S9*$D$5/3)+(T9*$E$5/3)+(U9*$F$5/3)+(V9*$G$5/3))*90 -> 75 | X9: 1 | Y9: 1 | Z9: 1 | AA9: 1 | AB9: =((X9*$D$5/3)+(Y9*$E$5/3)+(Z9*$F$5/3)+(AA9*$G$5/3))*90 -> 30 | AC9: 3 | AD9: 2 | AE9: 2 | AF9: 2 | AG9: =((AC9*$D$5/3)+(AD9*$E$5/3)+(AE9*$F$5/3)+(AF9*$G$5/3))*90 -> 63 | AH9: 2 | AI9: 3 | AJ9: 3 | AK9: 1 | AL9: =((AH9*$D$5/3)+(AI9*$E$5/3)+(AJ9*$F$5/3)+(AK9*$G$5/3))*90 -> 57 | AM9: 3 | AN9: 3 | AO9: 3 | AP9: 3 | AQ9: =((AM9*$D$5/3)+(AN9*$E$5/3)+(AO9*$F$5/3)+(AP9*$G$5/3))*90 -> 90
A10: ='INPUT DAFTAR PESERTA'!A8 -> 5 | B10: ='INPUT DAFTAR PESERTA'!B8 -> 2409046027 | C10: ='INPUT DAFTAR PESERTA'!C8 -> Faykar Alfarisi Armadani | D10: 3 | E10: 3 | F10: 3 | G10: 1 | H10: =((D10*$D$5/3)+(E10*$E$5/3)+(F10*$F$5/3)+(G10*$G$5/3))*90 -> 60 | I10: 3 | J10: 3 | K10: 3 | L10: 2 | M10: =((I10*$D$5/3)+(J10*$E$5/3)+(K10*$F$5/3)+(L10*$G$5/3))*90 -> 75 | N10: 3 | O10: 3 | P10: 3 | Q10: 2 | R10: =((N10*$D$5/3)+(O10*$E$5/3)+(P10*$F$5/3)+(Q10*$G$5/3))*90 -> 75 | S10: 3 | T10: 3 | U10: 3 | V10: 2 | W10: =((S10*$D$5/3)+(T10*$E$5/3)+(U10*$F$5/3)+(V10*$G$5/3))*90 -> 75 | X10: 3 | Y10: 3 | Z10: 3 | AA10: 3 | AB10: =((X10*$D$5/3)+(Y10*$E$5/3)+(Z10*$F$5/3)+(AA10*$G$5/3))*90 -> 90 | AC10: 3 | AD10: 2 | AE10: 2 | AF10: 2 | AG10: =((AC10*$D$5/3)+(AD10*$E$5/3)+(AE10*$F$5/3)+(AF10*$G$5/3))*90 -> 63 | AH10: 2 | AI10: 3 | AJ10: 3 | AK10: 3 | AL10: =((AH10*$D$5/3)+(AI10*$E$5/3)+(AJ10*$F$5/3)+(AK10*$G$5/3))*90 -> 87 | AM10: 3 | AN10: 3 | AO10: 3 | AP10: 1 | AQ10: =((AM10*$D$5/3)+(AN10*$E$5/3)+(AO10*$F$5/3)+(AP10*$G$5/3))*90 -> 60
A11: ='INPUT DAFTAR PESERTA'!A9 -> 6 | B11: ='INPUT DAFTAR PESERTA'!B9 -> 2409046034 | C11: ='INPUT DAFTAR PESERTA'!C9 -> Annisa Nurdin | D11: 3 | E11: 3 | F11: 3 | G11: 1 | H11: =((D11*$D$5/3)+(E11*$E$5/3)+(F11*$F$5/3)+(G11*$G$5/3))*90 -> 60 | I11: 3 | J11: 3 | K11: 3 | L11: 3 | M11: =((I11*$D$5/3)+(J11*$E$5/3)+(K11*$F$5/3)+(L11*$G$5/3))*90 -> 90 | N11: 3 | O11: 3 | P11: 3 | Q11: 3 | R11: =((N11*$D$5/3)+(O11*$E$5/3)+(P11*$F$5/3)+(Q11*$G$5/3))*90 -> 90 | S11: 3 | T11: 3 | U11: 3 | V11: 3 | W11: =((S11*$D$5/3)+(T11*$E$5/3)+(U11*$F$5/3)+(V11*$G$5/3))*90 -> 90 | X11: 3 | Y11: 3 | Z11: 3 | AA11: 3 | AB11: =((X11*$D$5/3)+(Y11*$E$5/3)+(Z11*$F$5/3)+(AA11*$G$5/3))*90 -> 90 | AC11: 3 | AD11: 2 | AE11: 2 | AF11: 2 | AG11: =((AC11*$D$5/3)+(AD11*$E$5/3)+(AE11*$F$5/3)+(AF11*$G$5/3))*90 -> 63 | AH11: 2 | AI11: 3 | AJ11: 3 | AK11: 3 | AL11: =((AH11*$D$5/3)+(AI11*$E$5/3)+(AJ11*$F$5/3)+(AK11*$G$5/3))*90 -> 87 | AM11: 2 | AN11: 3 | AO11: 3 | AP11: 1 | AQ11: =((AM11*$D$5/3)+(AN11*$E$5/3)+(AO11*$F$5/3)+(AP11*$G$5/3))*90 -> 57
A12: ='INPUT DAFTAR PESERTA'!A10 -> 7 | B12: ='INPUT DAFTAR PESERTA'!B10 -> 2409046042 | C12: ='INPUT DAFTAR PESERTA'!C10 -> Aflahal Aula | D12: 3 | E12: 3 | F12: 3 | G12: 1 | H12: =((D12*$D$5/3)+(E12*$E$5/3)+(F12*$F$5/3)+(G12*$G$5/3))*90 -> 60 | I12: 3 | J12: 3 | K12: 3 | L12: 1 | M12: =((I12*$D$5/3)+(J12*$E$5/3)+(K12*$F$5/3)+(L12*$G$5/3))*90 -> 60 | N12: 3 | O12: 3 | P12: 3 | Q12: 3 | R12: =((N12*$D$5/3)+(O12*$E$5/3)+(P12*$F$5/3)+(Q12*$G$5/3))*90 -> 90 | S12: 3 | T12: 3 | U12: 3 | V12: 3 | W12: =((S12*$D$5/3)+(T12*$E$5/3)+(U12*$F$5/3)+(V12*$G$5/3))*90 -> 90 | X12: 3 | Y12: 3 | Z12: 3 | AA12: 3 | AB12: =((X12*$D$5/3)+(Y12*$E$5/3)+(Z12*$F$5/3)+(AA12*$G$5/3))*90 -> 90 | AC12: 3 | AD12: 2 | AE12: 2 | AF12: 2 | AG12: =((AC12*$D$5/3)+(AD12*$E$5/3)+(AE12*$F$5/3)+(AF12*$G$5/3))*90 -> 63 | AH12: 2 | AI12: 3 | AJ12: 3 | AK12: 3 | AL12: =((AH12*$D$5/3)+(AI12*$E$5/3)+(AJ12*$F$5/3)+(AK12*$G$5/3))*90 -> 87 | AM12: 3 | AN12: 3 | AO12: 3 | AP12: 1 | AQ12: =((AM12*$D$5/3)+(AN12*$E$5/3)+(AO12*$F$5/3)+(AP12*$G$5/3))*90 -> 60
A13: ='INPUT DAFTAR PESERTA'!A11 -> 8 | B13: ='INPUT DAFTAR PESERTA'!B11 -> 2409046045 | C13: ='INPUT DAFTAR PESERTA'!C11 -> Jofan Ananda Sulle | D13: 3 | E13: 3 | F13: 3 | G13: 1 | H13: =((D13*$D$5/3)+(E13*$E$5/3)+(F13*$F$5/3)+(G13*$G$5/3))*90 -> 60 | I13: 3 | J13: 3 | K13: 3 | L13: 2 | M13: =((I13*$D$5/3)+(J13*$E$5/3)+(K13*$F$5/3)+(L13*$G$5/3))*90 -> 75 | N13: 3 | O13: 3 | P13: 3 | Q13: 3 | R13: =((N13*$D$5/3)+(O13*$E$5/3)+(P13*$F$5/3)+(Q13*$G$5/3))*90 -> 90 | S13: 3 | T13: 3 | U13: 3 | V13: 3 | W13: =((S13*$D$5/3)+(T13*$E$5/3)+(U13*$F$5/3)+(V13*$G$5/3))*90 -> 90 | X13: 3 | Y13: 3 | Z13: 3 | AA13: 3 | AB13: =((X13*$D$5/3)+(Y13*$E$5/3)+(Z13*$F$5/3)+(AA13*$G$5/3))*90 -> 90 | AC13: 3 | AD13: 2 | AE13: 2 | AF13: 2 | AG13: =((AC13*$D$5/3)+(AD13*$E$5/3)+(AE13*$F$5/3)+(AF13*$G$5/3))*90 -> 63 | AH13: 2 | AI13: 3 | AJ13: 3 | AK13: 1 | AL13: =((AH13*$D$5/3)+(AI13*$E$5/3)+(AJ13*$F$5/3)+(AK13*$G$5/3))*90 -> 57 | AM13: 3 | AN13: 3 | AO13: 3 | AP13: 1 | AQ13: =((AM13*$D$5/3)+(AN13*$E$5/3)+(AO13*$F$5/3)+(AP13*$G$5/3))*90 -> 60
A14: ='INPUT DAFTAR PESERTA'!A12 -> 9 | B14: ='INPUT DAFTAR PESERTA'!B12 -> 2409046046 | C14: ='INPUT DAFTAR PESERTA'!C12 -> Muhammad Ananda Harisyah Putra | D14: 3 | E14: 3 | F14: 3 | G14: 3 | H14: =((D14*$D$5/3)+(E14*$E$5/3)+(F14*$F$5/3)+(G14*$G$5/3))*90 -> 90 | I14: 3 | J14: 3 | K14: 3 | L14: 3 | M14: =((I14*$D$5/3)+(J14*$E$5/3)+(K14*$F$5/3)+(L14*$G$5/3))*90 -> 90 | N14: 3 | O14: 3 | P14: 3 | Q14: 3 | R14: =((N14*$D$5/3)+(O14*$E$5/3)+(P14*$F$5/3)+(Q14*$G$5/3))*90 -> 90 | S14: 3 | T14: 3 | U14: 3 | V14: 3 | W14: =((S14*$D$5/3)+(T14*$E$5/3)+(U14*$F$5/3)+(V14*$G$5/3))*90 -> 90 | X14: 3 | Y14: 3 | Z14: 3 | AA14: 3 | AB14: =((X14*$D$5/3)+(Y14*$E$5/3)+(Z14*$F$5/3)+(AA14*$G$5/3))*90 -> 90 | AC14: 2 | AD14: 2 | AE14: 2 | AF14: 2 | AG14: =((AC14*$D$5/3)+(AD14*$E$5/3)+(AE14*$F$5/3)+(AF14*$G$5/3))*90 -> 60 | AH14: 2 | AI14: 3 | AJ14: 3 | AK14: 3 | AL14: =((AH14*$D$5/3)+(AI14*$E$5/3)+(AJ14*$F$5/3)+(AK14*$G$5/3))*90 -> 87 | AM14: 3 | AN14: 3 | AO14: 3 | AP14: 1 | AQ14: =((AM14*$D$5/3)+(AN14*$E$5/3)+(AO14*$F$5/3)+(AP14*$G$5/3))*90 -> 60
A15: ='INPUT DAFTAR PESERTA'!A13 -> 10 | B15: ='INPUT DAFTAR PESERTA'!B13 -> 2409046048 | C15: ='INPUT DAFTAR PESERTA'!C13 -> Zaid Iman At-Tamam | D15: 3 | E15: 3 | F15: 3 | G15: 2 | H15: =((D15*$D$5/3)+(E15*$E$5/3)+(F15*$F$5/3)+(G15*$G$5/3))*90 -> 75 | I15: 3 | J15: 3 | K15: 3 | L15: 2 | M15: =((I15*$D$5/3)+(J15*$E$5/3)+(K15*$F$5/3)+(L15*$G$5/3))*90 -> 75 | N15: 3 | O15: 3 | P15: 3 | Q15: 2 | R15: =((N15*$D$5/3)+(O15*$E$5/3)+(P15*$F$5/3)+(Q15*$G$5/3))*90 -> 75 | S15: 3 | T15: 3 | U15: 3 | V15: 2 | W15: =((S15*$D$5/3)+(T15*$E$5/3)+(U15*$F$5/3)+(V15*$G$5/3))*90 -> 75 | X15: 3 | Y15: 3 | Z15: 3 | AA15: 3 | AB15: =((X15*$D$5/3)+(Y15*$E$5/3)+(Z15*$F$5/3)+(AA15*$G$5/3))*90 -> 90 | AC15: 2 | AD15: 2 | AE15: 2 | AF15: 2 | AG15: =((AC15*$D$5/3)+(AD15*$E$5/3)+(AE15*$F$5/3)+(AF15*$G$5/3))*90 -> 60 | AH15: 2 | AI15: 3 | AJ15: 3 | AK15: 2 | AL15: =((AH15*$D$5/3)+(AI15*$E$5/3)+(AJ15*$F$5/3)+(AK15*$G$5/3))*90 -> 72 | AM15: 3 | AN15: 3 | AO15: 3 | AP15: 1 | AQ15: =((AM15*$D$5/3)+(AN15*$E$5/3)+(AO15*$F$5/3)+(AP15*$G$5/3))*90 -> 60
A16: ='INPUT DAFTAR PESERTA'!A14 -> 11 | B16: ='INPUT DAFTAR PESERTA'!B14 -> 2409046050 | C16: ='INPUT DAFTAR PESERTA'!C14 -> Fachri Zia Pasha | D16: 3 | E16: 3 | F16: 3 | G16: 3 | H16: =((D16*$D$5/3)+(E16*$E$5/3)+(F16*$F$5/3)+(G16*$G$5/3))*90 -> 90 | I16: 3 | J16: 3 | K16: 3 | L16: 3 | M16: =((I16*$D$5/3)+(J16*$E$5/3)+(K16*$F$5/3)+(L16*$G$5/3))*90 -> 90 | N16: 3 | O16: 3 | P16: 3 | Q16: 3 | R16: =((N16*$D$5/3)+(O16*$E$5/3)+(P16*$F$5/3)+(Q16*$G$5/3))*90 -> 90 | S16: 3 | T16: 3 | U16: 3 | V16: 3 | W16: =((S16*$D$5/3)+(T16*$E$5/3)+(U16*$F$5/3)+(V16*$G$5/3))*90 -> 90 | X16: 3 | Y16: 3 | Z16: 3 | AA16: 3 | AB16: =((X16*$D$5/3)+(Y16*$E$5/3)+(Z16*$F$5/3)+(AA16*$G$5/3))*90 -> 90 | AC16: 2 | AD16: 2 | AE16: 2 | AF16: 2 | AG16: =((AC16*$D$5/3)+(AD16*$E$5/3)+(AE16*$F$5/3)+(AF16*$G$5/3))*90 -> 60 | AH16: 2 | AI16: 3 | AJ16: 3 | AK16: 3 | AL16: =((AH16*$D$5/3)+(AI16*$E$5/3)+(AJ16*$F$5/3)+(AK16*$G$5/3))*90 -> 87 | AM16: 3 | AN16: 3 | AO16: 3 | AP16: 2 | AQ16: =((AM16*$D$5/3)+(AN16*$E$5/3)+(AO16*$F$5/3)+(AP16*$G$5/3))*90 -> 75
A17: ='INPUT DAFTAR PESERTA'!A15 -> 12 | B17: ='INPUT DAFTAR PESERTA'!B15 -> 2409046051 | C17: ='INPUT DAFTAR PESERTA'!C15 -> Aziffa Reisazalea | D17: 3 | E17: 3 | F17: 3 | G17: 3 | H17: =((D17*$D$5/3)+(E17*$E$5/3)+(F17*$F$5/3)+(G17*$G$5/3))*90 -> 90 | I17: 3 | J17: 3 | K17: 3 | L17: 3 | M17: =((I17*$D$5/3)+(J17*$E$5/3)+(K17*$F$5/3)+(L17*$G$5/3))*90 -> 90 | N17: 3 | O17: 3 | P17: 3 | Q17: 3 | R17: =((N17*$D$5/3)+(O17*$E$5/3)+(P17*$F$5/3)+(Q17*$G$5/3))*90 -> 90 | S17: 3 | T17: 3 | U17: 3 | V17: 3 | W17: =((S17*$D$5/3)+(T17*$E$5/3)+(U17*$F$5/3)+(V17*$G$5/3))*90 -> 90 | X17: 3 | Y17: 3 | Z17: 3 | AA17: 3 | AB17: =((X17*$D$5/3)+(Y17*$E$5/3)+(Z17*$F$5/3)+(AA17*$G$5/3))*90 -> 90 | AC17: 2 | AD17: 2 | AE17: 2 | AF17: 2 | AG17: =((AC17*$D$5/3)+(AD17*$E$5/3)+(AE17*$F$5/3)+(AF17*$G$5/3))*90 -> 60 | AH17: 2 | AI17: 3 | AJ17: 3 | AK17: 3 | AL17: =((AH17*$D$5/3)+(AI17*$E$5/3)+(AJ17*$F$5/3)+(AK17*$G$5/3))*90 -> 87 | AM17: 3 | AN17: 3 | AO17: 3 | AP17: 2 | AQ17: =((AM17*$D$5/3)+(AN17*$E$5/3)+(AO17*$F$5/3)+(AP17*$G$5/3))*90 -> 75
... A26: ='INPUT DAFTAR PESERTA'!A24 -> 21 | B26: ='INPUT DAFTAR PESERTA'!B24 -> 2509046005 | C26: ='INPUT DAFTAR PESERTA'!C24 -> Seysa Puji Annura | D26: 3 | E26: 2 | F26: 3 | G26: 1 | H26: =((D26*$D$5/3)+(E26*$E$5/3)+(F26*$F$5/3)+(G26*$G$5/3))*90 -> 54 | I26: 2 | J26: 3 | K26: 2 | L26: 1 | M26: =((I26*$D$5/3)+(J26*$E$5/3)+(K26*$F$5/3)+(L26*$G$5/3))*90 -> 51 | N26: 3 | O26: 3 | P26: 3 | Q26: 1 | R26: =((N26*$D$5/3)+(O26*$E$5/3)+(P26*$F$5/3)+(Q26*$G$5/3))*90 -> 60 | S26: 3 | T26: 3 | U26: 3 | V26: 1 | W26: =((S26*$D$5/3)+(T26*$E$5/3)+(U26*$F$5/3)+(V26*$G$5/3))*90 -> 60 | X26: 2 | Y26: 2 | Z26: 2 | AA26: 1 | AB26: =((X26*$D$5/3)+(Y26*$E$5/3)+(Z26*$F$5/3)+(AA26*$G$5/3))*90 -> 45 | AC26: 3 | AD26: 3 | AE26: 3 | AF26: 3 | AG26: =((AC26*$D$5/3)+(AD26*$E$5/3)+(AE26*$F$5/3)+(AF26*$G$5/3))*90 -> 90 | AH26: 2 | AI26: 3 | AJ26: 3 | AK26: 1 | AL26: =((AH26*$D$5/3)+(AI26*$E$5/3)+(AJ26*$F$5/3)+(AK26*$G$5/3))*90 -> 57 | AM26: 3 | AN26: 3 | AO26: 3 | AP26: 0 | AQ26: =((AM26*$D$5/3)+(AN26*$E$5/3)+(AO26*$F$5/3)+(AP26*$G$5/3))*90 -> 45
A27: ='INPUT DAFTAR PESERTA'!A25 -> 22 | B27: ='INPUT DAFTAR PESERTA'!B25 -> 2509046006 | C27: ='INPUT DAFTAR PESERTA'!C25 -> Gita Ramadhani Supriyadi | H27: =((D27*$D$5/3)+(E27*$E$5/3)+(F27*$F$5/3)+(G27*$G$5/3))*90 -> 0 | I27: 1 | J27: 1 | K27: 1 | L27: 1 | M27: =((I27*$D$5/3)+(J27*$E$5/3)+(K27*$F$5/3)+(L27*$G$5/3))*90 -> 30 | N27: 0 | O27: 0 | P27: 0 | Q27: 0 | R27: =((N27*$D$5/3)+(O27*$E$5/3)+(P27*$F$5/3)+(Q27*$G$5/3))*90 -> 0 | S27: 0 | T27: 0 | U27: 0 | V27: 0 | W27: =((S27*$D$5/3)+(T27*$E$5/3)+(U27*$F$5/3)+(V27*$G$5/3))*90 -> 0 | X27: 1 | Y27: 1 | Z27: 1 | AA27: 1 | AB27: =((X27*$D$5/3)+(Y27*$E$5/3)+(Z27*$F$5/3)+(AA27*$G$5/3))*90 -> 30 | AC27: 0 | AD27: 0 | AE27: 0 | AF27: 0 | AG27: =((AC27*$D$5/3)+(AD27*$E$5/3)+(AE27*$F$5/3)+(AF27*$G$5/3))*90 -> 0 | AH27: 0 | AI27: 0 | AJ27: 0 | AK27: 0 | AL27: =((AH27*$D$5/3)+(AI27*$E$5/3)+(AJ27*$F$5/3)+(AK27*$G$5/3))*90 -> 0 | AM27: 0 | AN27: 0 | AO27: 0 | AP27: 0 | AQ27: =((AM27*$D$5/3)+(AN27*$E$5/3)+(AO27*$F$5/3)+(AP27*$G$5/3))*90 -> 0
A28: ='INPUT DAFTAR PESERTA'!A26 -> 23 | B28: ='INPUT DAFTAR PESERTA'!B26 -> 2509046007 | C28: ='INPUT DAFTAR PESERTA'!C26 -> Fabio Cannavaro Sinaga | D28: 3 | E28: 3 | F28: 3 | G28: 3 | H28: =((D28*$D$5/3)+(E28*$E$5/3)+(F28*$F$5/3)+(G28*$G$5/3))*90 -> 90 | I28: 3 | J28: 3 | K28: 2 | L28: 2 | M28: =((I28*$D$5/3)+(J28*$E$5/3)+(K28*$F$5/3)+(L28*$G$5/3))*90 -> 69 | N28: 3 | O28: 3 | P28: 3 | Q28: 3 | R28: =((N28*$D$5/3)+(O28*$E$5/3)+(P28*$F$5/3)+(Q28*$G$5/3))*90 -> 90 | S28: 3 | T28: 3 | U28: 3 | V28: 3 | W28: =((S28*$D$5/3)+(T28*$E$5/3)+(U28*$F$5/3)+(V28*$G$5/3))*90 -> 90 | X28: 2 | Y28: 2 | Z28: 2 | AA28: 3 | AB28: =((X28*$D$5/3)+(Y28*$E$5/3)+(Z28*$F$5/3)+(AA28*$G$5/3))*90 -> 75 | AC28: 3 | AD28: 3 | AE28: 3 | AF28: 2 | AG28: =((AC28*$D$5/3)+(AD28*$E$5/3)+(AE28*$F$5/3)+(AF28*$G$5/3))*90 -> 75 | AH28: 2 | AI28: 3 | AJ28: 3 | AK28: 2 | AL28: =((AH28*$D$5/3)+(AI28*$E$5/3)+(AJ28*$F$5/3)+(AK28*$G$5/3))*90 -> 72 | AM28: 3 | AN28: 3 | AO28: 3 | AP28: 1 | AQ28: =((AM28*$D$5/3)+(AN28*$E$5/3)+(AO28*$F$5/3)+(AP28*$G$5/3))*90 -> 60
A29: ='INPUT DAFTAR PESERTA'!A27 -> 24 | B29: ='INPUT DAFTAR PESERTA'!B27 -> 2509046008 | C29: ='INPUT DAFTAR PESERTA'!C27 -> Hayatun Nisa | D29: 3 | E29: 3 | F29: 3 | G29: 2 | H29: =((D29*$D$5/3)+(E29*$E$5/3)+(F29*$F$5/3)+(G29*$G$5/3))*90 -> 75 | I29: 3 | J29: 3 | K29: 3 | L29: 1 | M29: =((I29*$D$5/3)+(J29*$E$5/3)+(K29*$F$5/3)+(L29*$G$5/3))*90 -> 60 | N29: 3 | O29: 3 | P29: 3 | Q29: 2 | R29: =((N29*$D$5/3)+(O29*$E$5/3)+(P29*$F$5/3)+(Q29*$G$5/3))*90 -> 75 | S29: 3 | T29: 3 | U29: 3 | V29: 1 | W29: =((S29*$D$5/3)+(T29*$E$5/3)+(U29*$F$5/3)+(V29*$G$5/3))*90 -> 60 | X29: 2 | Y29: 2 | Z29: 2 | AA29: 3 | AB29: =((X29*$D$5/3)+(Y29*$E$5/3)+(Z29*$F$5/3)+(AA29*$G$5/3))*90 -> 75 | AC29: 3 | AD29: 2 | AE29: 2 | AF29: 2 | AG29: =((AC29*$D$5/3)+(AD29*$E$5/3)+(AE29*$F$5/3)+(AF29*$G$5/3))*90 -> 63 | AH29: 2 | AI29: 3 | AJ29: 3 | AK29: 1 | AL29: =((AH29*$D$5/3)+(AI29*$E$5/3)+(AJ29*$F$5/3)+(AK29*$G$5/3))*90 -> 57 | AM29: 3 | AN29: 3 | AO29: 3 | AP29: 1 | AQ29: =((AM29*$D$5/3)+(AN29*$E$5/3)+(AO29*$F$5/3)+(AP29*$G$5/3))*90 -> 60
A30: ='INPUT DAFTAR PESERTA'!A28 -> 25 | B30: ='INPUT DAFTAR PESERTA'!B28 -> 2509046009 | C30: ='INPUT DAFTAR PESERTA'!C28 -> Khalilah Denissa Ardia Cahyani | D30: 3 | E30: 3 | F30: 3 | G30: 2 | H30: =((D30*$D$5/3)+(E30*$E$5/3)+(F30*$F$5/3)+(G30*$G$5/3))*90 -> 75 | I30: 3 | J30: 3 | K30: 3 | L30: 1 | M30: =((I30*$D$5/3)+(J30*$E$5/3)+(K30*$F$5/3)+(L30*$G$5/3))*90 -> 60 | N30: 3 | O30: 3 | P30: 3 | Q30: 2 | R30: =((N30*$D$5/3)+(O30*$E$5/3)+(P30*$F$5/3)+(Q30*$G$5/3))*90 -> 75 | S30: 2 | T30: 3 | U30: 3 | V30: 2 | W30: =((S30*$D$5/3)+(T30*$E$5/3)+(U30*$F$5/3)+(V30*$G$5/3))*90 -> 72 | X30: 2 | Y30: 3 | Z30: 3 | AA30: 2 | AB30: =((X30*$D$5/3)+(Y30*$E$5/3)+(Z30*$F$5/3)+(AA30*$G$5/3))*90 -> 72 | AC30: 3 | AD30: 2 | AE30: 2 | AF30: 2 | AG30: =((AC30*$D$5/3)+(AD30*$E$5/3)+(AE30*$F$5/3)+(AF30*$G$5/3))*90 -> 63 | AH30: 2 | AI30: 3 | AJ30: 3 | AK30: 1 | AL30: =((AH30*$D$5/3)+(AI30*$E$5/3)+(AJ30*$F$5/3)+(AK30*$G$5/3))*90 -> 57 | AM30: 0 | AN30: 0 | AO30: 0 | AP30: 0 | AQ30: =((AM30*$D$5/3)+(AN30*$E$5/3)+(AO30*$F$5/3)+(AP30*$G$5/3))*90 -> 0
A31: ='INPUT DAFTAR PESERTA'!A29 -> 26 | B31: ='INPUT DAFTAR PESERTA'!B29 -> 2509046010 | C31: ='INPUT DAFTAR PESERTA'!C29 -> Athila Nadya Zalikha | D31: 3 | E31: 3 | F31: 3 | G31: 2 | H31: =((D31*$D$5/3)+(E31*$E$5/3)+(F31*$F$5/3)+(G31*$G$5/3))*90 -> 75 | I31: 1 | J31: 1 | K31: 1 | L31: 1 | M31: =((I31*$D$5/3)+(J31*$E$5/3)+(K31*$F$5/3)+(L31*$G$5/3))*90 -> 30 | N31: 0 | O31: 0 | P31: 0 | Q31: 0 | R31: =((N31*$D$5/3)+(O31*$E$5/3)+(P31*$F$5/3)+(Q31*$G$5/3))*90 -> 0 | S31: 0 | T31: 0 | U31: 0 | V31: 0 | W31: =((S31*$D$5/3)+(T31*$E$5/3)+(U31*$F$5/3)+(V31*$G$5/3))*90 -> 0 | X31: 2 | Y31: 2 | Z31: 2 | AA31: 3 | AB31: =((X31*$D$5/3)+(Y31*$E$5/3)+(Z31*$F$5/3)+(AA31*$G$5/3))*90 -> 75 | AC31: 3 | AD31: 2 | AE31: 2 | AF31: 2 | AG31: =((AC31*$D$5/3)+(AD31*$E$5/3)+(AE31*$F$5/3)+(AF31*$G$5/3))*90 -> 63 | AH31: 2 | AI31: 3 | AJ31: 3 | AK31: 1 | AL31: =((AH31*$D$5/3)+(AI31*$E$5/3)+(AJ31*$F$5/3)+(AK31*$G$5/3))*90 -> 57 | AM31: 0 | AN31: 0 | AO31: 0 | AP31: 0 | AQ31: =((AM31*$D$5/3)+(AN31*$E$5/3)+(AO31*$F$5/3)+(AP31*$G$5/3))*90 -> 0
A32: ='INPUT DAFTAR PESERTA'!A30 -> 27 | B32: ='INPUT DAFTAR PESERTA'!B30 -> 2509046011 | C32: ='INPUT DAFTAR PESERTA'!C30 -> Aditya Pratama | D32: 3 | E32: 3 | F32: 3 | G32: 2 | H32: =((D32*$D$5/3)+(E32*$E$5/3)+(F32*$F$5/3)+(G32*$G$5/3))*90 -> 75 | I32: 3 | J32: 3 | K32: 3 | L32: 1 | M32: =((I32*$D$5/3)+(J32*$E$5/3)+(K32*$F$5/3)+(L32*$G$5/3))*90 -> 60 | N32: 0 | O32: 0 | P32: 0 | Q32: 0 | R32: =((N32*$D$5/3)+(O32*$E$5/3)+(P32*$F$5/3)+(Q32*$G$5/3))*90 -> 0 | S32: 0 | T32: 0 | U32: 0 | V32: 0 | W32: =((S32*$D$5/3)+(T32*$E$5/3)+(U32*$F$5/3)+(V32*$G$5/3))*90 -> 0 | X32: 1 | Y32: 1 | Z32: 1 | AA32: 1 | AB32: =((X32*$D$5/3)+(Y32*$E$5/3)+(Z32*$F$5/3)+(AA32*$G$5/3))*90 -> 30 | AC32: 0 | AD32: 0 | AE32: 0 | AF32: 0 | AG32: =((AC32*$D$5/3)+(AD32*$E$5/3)+(AE32*$F$5/3)+(AF32*$G$5/3))*90 -> 0 | AH32: 2 | AI32: 3 | AJ32: 3 | AK32: 1 | AL32: =((AH32*$D$5/3)+(AI32*$E$5/3)+(AJ32*$F$5/3)+(AK32*$G$5/3))*90 -> 57 | AM32: 0 | AN32: 0 | AO32: 0 | AP32: 0 | AQ32: =((AM32*$D$5/3)+(AN32*$E$5/3)+(AO32*$F$5/3)+(AP32*$G$5/3))*90 -> 0
A33: ='INPUT DAFTAR PESERTA'!A31 -> 28 | B33: ='INPUT DAFTAR PESERTA'!B31 -> 2509046012 | C33: ='INPUT DAFTAR PESERTA'!C31 -> Atiiqah Permata Hati | D33: 3 | E33: 3 | F33: 3 | G33: 1 | H33: =((D33*$D$5/3)+(E33*$E$5/3)+(F33*$F$5/3)+(G33*$G$5/3))*90 -> 60 | I33: 2 | J33: 2 | K33: 2 | L33: 1 | M33: =((I33*$D$5/3)+(J33*$E$5/3)+(K33*$F$5/3)+(L33*$G$5/3))*90 -> 45 | N33: 2 | O33: 3 | P33: 3 | Q33: 1 | R33: =((N33*$D$5/3)+(O33*$E$5/3)+(P33*$F$5/3)+(Q33*$G$5/3))*90 -> 57 | S33: 3 | T33: 3 | U33: 3 | V33: 1 | W33: =((S33*$D$5/3)+(T33*$E$5/3)+(U33*$F$5/3)+(V33*$G$5/3))*90 -> 60 | X33: 3 | Y33: 2 | Z33: 3 | AA33: 1 | AB33: =((X33*$D$5/3)+(Y33*$E$5/3)+(Z33*$F$5/3)+(AA33*$G$5/3))*90 -> 54 | AC33: 3 | AD33: 2 | AE33: 2 | AF33: 2 | AG33: =((AC33*$D$5/3)+(AD33*$E$5/3)+(AE33*$F$5/3)+(AF33*$G$5/3))*90 -> 63 | AH33: 2 | AI33: 3 | AJ33: 3 | AK33: 1 | AL33: =((AH33*$D$5/3)+(AI33*$E$5/3)+(AJ33*$F$5/3)+(AK33*$G$5/3))*90 -> 57 | AM33: 3 | AN33: 3 | AO33: 3 | AP33: 1 | AQ33: =((AM33*$D$5/3)+(AN33*$E$5/3)+(AO33*$F$5/3)+(AP33*$G$5/3))*90 -> 60
A34: ='INPUT DAFTAR PESERTA'!A32 -> 29 | B34: ='INPUT DAFTAR PESERTA'!B32 -> 2509046013 | C34: ='INPUT DAFTAR PESERTA'!C32 -> Yolanda Denis Aprilia | D34: 3 | E34: 3 | F34: 3 | G34: 2 | H34: =((D34*$D$5/3)+(E34*$E$5/3)+(F34*$F$5/3)+(G34*$G$5/3))*90 -> 75 | I34: 2 | J34: 2 | K34: 2 | L34: 1 | M34: =((I34*$D$5/3)+(J34*$E$5/3)+(K34*$F$5/3)+(L34*$G$5/3))*90 -> 45 | N34: 3 | O34: 3 | P34: 3 | Q34: 2 | R34: =((N34*$D$5/3)+(O34*$E$5/3)+(P34*$F$5/3)+(Q34*$G$5/3))*90 -> 75 | S34: 3 | T34: 3 | U34: 3 | V34: 1 | W34: =((S34*$D$5/3)+(T34*$E$5/3)+(U34*$F$5/3)+(V34*$G$5/3))*90 -> 60 | X34: 3 | Y34: 2 | Z34: 3 | AA34: 1 | AB34: =((X34*$D$5/3)+(Y34*$E$5/3)+(Z34*$F$5/3)+(AA34*$G$5/3))*90 -> 54 | AC34: 3 | AD34: 2 | AE34: 2 | AF34: 2 | AG34: =((AC34*$D$5/3)+(AD34*$E$5/3)+(AE34*$F$5/3)+(AF34*$G$5/3))*90 -> 63 | AH34: 2 | AI34: 3 | AJ34: 3 | AK34: 1 | AL34: =((AH34*$D$5/3)+(AI34*$E$5/3)+(AJ34*$F$5/3)+(AK34*$G$5/3))*90 -> 57 | AM34: 3 | AN34: 3 | AO34: 3 | AP34: 1 | AQ34: =((AM34*$D$5/3)+(AN34*$E$5/3)+(AO34*$F$5/3)+(AP34*$G$5/3))*90 -> 60
A35: ='INPUT DAFTAR PESERTA'!A33 -> 30 | B35: ='INPUT DAFTAR PESERTA'!B33 -> 2509046014 | C35: ='INPUT DAFTAR PESERTA'!C33 -> Farah Najma | D35: 2 | E35: 2 | F35: 2 | G35: 3 | H35: =((D35*$D$5/3)+(E35*$E$5/3)+(F35*$F$5/3)+(G35*$G$5/3))*90 -> 75 | I35: 2 | J35: 2 | K35: 2 | L35: 1 | M35: =((I35*$D$5/3)+(J35*$E$5/3)+(K35*$F$5/3)+(L35*$G$5/3))*90 -> 45 | N35: 2 | O35: 3 | P35: 3 | Q35: 1 | R35: =((N35*$D$5/3)+(O35*$E$5/3)+(P35*$F$5/3)+(Q35*$G$5/3))*90 -> 57 | S35: 3 | T35: 3 | U35: 3 | V35: 1 | W35: =((S35*$D$5/3)+(T35*$E$5/3)+(U35*$F$5/3)+(V35*$G$5/3))*90 -> 60 | X35: 3 | Y35: 3 | Z35: 3 | AA35: 1 | AB35: =((X35*$D$5/3)+(Y35*$E$5/3)+(Z35*$F$5/3)+(AA35*$G$5/3))*90 -> 60 | AC35: 3 | AD35: 2 | AE35: 2 | AF35: 2 | AG35: =((AC35*$D$5/3)+(AD35*$E$5/3)+(AE35*$F$5/3)+(AF35*$G$5/3))*90 -> 63 | AH35: 2 | AI35: 3 | AJ35: 3 | AK35: 1 | AL35: =((AH35*$D$5/3)+(AI35*$E$5/3)+(AJ35*$F$5/3)+(AK35*$G$5/3))*90 -> 57 | AM35: 3 | AN35: 3 | AO35: 3 | AP35: 1 | AQ35: =((AM35*$D$5/3)+(AN35*$E$5/3)+(AO35*$F$5/3)+(AP35*$G$5/3))*90 -> 60
A36: ='INPUT DAFTAR PESERTA'!A34 -> 31 | B36: ='INPUT DAFTAR PESERTA'!B34 -> 2509046015 | C36: ='INPUT DAFTAR PESERTA'!C34 -> Muhammad Abdul Mu'in | D36: 2 | E36: 3 | F36: 2 | G36: 2 | H36: =((D36*$D$5/3)+(E36*$E$5/3)+(F36*$F$5/3)+(G36*$G$5/3))*90 -> 66 | I36: 2 | J36: 2 | K36: 2 | L36: 1 | M36: =((I36*$D$5/3)+(J36*$E$5/3)+(K36*$F$5/3)+(L36*$G$5/3))*90 -> 45 | N36: 3 | O36: 3 | P36: 3 | Q36: 1 | R36: =((N36*$D$5/3)+(O36*$E$5/3)+(P36*$F$5/3)+(Q36*$G$5/3))*90 -> 60 | S36: 3 | T36: 3 | U36: 3 | V36: 1 | W36: =((S36*$D$5/3)+(T36*$E$5/3)+(U36*$F$5/3)+(V36*$G$5/3))*90 -> 60 | X36: 3 | Y36: 3 | Z36: 3 | AA36: 1 | AB36: =((X36*$D$5/3)+(Y36*$E$5/3)+(Z36*$F$5/3)+(AA36*$G$5/3))*90 -> 60 | AC36: 3 | AD36: 2 | AE36: 2 | AF36: 2 | AG36: =((AC36*$D$5/3)+(AD36*$E$5/3)+(AE36*$F$5/3)+(AF36*$G$5/3))*90 -> 63 | AH36: 3 | AI36: 3 | AJ36: 3 | AK36: 1 | AL36: =((AH36*$D$5/3)+(AI36*$E$5/3)+(AJ36*$F$5/3)+(AK36*$G$5/3))*90 -> 60 | AM36: 3 | AN36: 3 | AO36: 3 | AP36: 1 | AQ36: =((AM36*$D$5/3)+(AN36*$E$5/3)+(AO36*$F$5/3)+(AP36*$G$5/3))*90 -> 60
A37: ='INPUT DAFTAR PESERTA'!A35 -> 32 | B37: ='INPUT DAFTAR PESERTA'!B35 -> 2509046016 | C37: ='INPUT DAFTAR PESERTA'!C35 -> Muhammad Rofiq Al-Hakim | D37: 1 | E37: 2 | F37: 3 | G37: 3 | H37: =((D37*$D$5/3)+(E37*$E$5/3)+(F37*$F$5/3)+(G37*$G$5/3))*90 -> 78 | I37: 1 | J37: 1 | K37: 1 | L37: 1 | M37: =((I37*$D$5/3)+(J37*$E$5/3)+(K37*$F$5/3)+(L37*$G$5/3))*90 -> 30 | N37: 0 | O37: 0 | P37: 0 | Q37: 0 | R37: =((N37*$D$5/3)+(O37*$E$5/3)+(P37*$F$5/3)+(Q37*$G$5/3))*90 -> 0 | S37: 3 | T37: 3 | U37: 3 | V37: 1 | W37: =((S37*$D$5/3)+(T37*$E$5/3)+(U37*$F$5/3)+(V37*$G$5/3))*90 -> 60 | X37: 3 | Y37: 2 | Z37: 2 | AA37: 3 | AB37: =((X37*$D$5/3)+(Y37*$E$5/3)+(Z37*$F$5/3)+(AA37*$G$5/3))*90 -> 78 | AC37: 3 | AD37: 2 | AE37: 2 | AF37: 2 | AG37: =((AC37*$D$5/3)+(AD37*$E$5/3)+(AE37*$F$5/3)+(AF37*$G$5/3))*90 -> 63 | AH37: 2 | AI37: 3 | AJ37: 3 | AK37: 3 | AL37: =((AH37*$D$5/3)+(AI37*$E$5/3)+(AJ37*$F$5/3)+(AK37*$G$5/3))*90 -> 87 | AM37: 2 | AN37: 3 | AO37: 3 | AP37: 1 | AQ37: =((AM37*$D$5/3)+(AN37*$E$5/3)+(AO37*$F$5/3)+(AP37*$G$5/3))*90 -> 57
A38: ='INPUT DAFTAR PESERTA'!A36 -> 33 | B38: ='INPUT DAFTAR PESERTA'!B36 -> 2509046017 | C38: ='INPUT DAFTAR PESERTA'!C36 -> Nadia Eka Pratiwi | D38: 3 | E38: 3 | F38: 3 | G38: 3 | H38: =((D38*$D$5/3)+(E38*$E$5/3)+(F38*$F$5/3)+(G38*$G$5/3))*90 -> 90 | I38: 1 | J38: 1 | K38: 1 | L38: 1 | M38: =((I38*$D$5/3)+(J38*$E$5/3)+(K38*$F$5/3)+(L38*$G$5/3))*90 -> 30 | N38: 3 | O38: 3 | P38: 3 | Q38: 2 | R38: =((N38*$D$5/3)+(O38*$E$5/3)+(P38*$F$5/3)+(Q38*$G$5/3))*90 -> 75 | S38: 3 | T38: 3 | U38: 3 | V38: 2 | W38: =((S38*$D$5/3)+(T38*$E$5/3)+(U38*$F$5/3)+(V38*$G$5/3))*90 -> 75 | X38: 3 | Y38: 3 | Z38: 2 | AA38: 3 | AB38: =((X38*$D$5/3)+(Y38*$E$5/3)+(Z38*$F$5/3)+(AA38*$G$5/3))*90 -> 84 | AC38: 3 | AD38: 2 | AE38: 2 | AF38: 2 | AG38: =((AC38*$D$5/3)+(AD38*$E$5/3)+(AE38*$F$5/3)+(AF38*$G$5/3))*90 -> 63 | AH38: 2 | AI38: 3 | AJ38: 3 | AK38: 3 | AL38: =((AH38*$D$5/3)+(AI38*$E$5/3)+(AJ38*$F$5/3)+(AK38*$G$5/3))*90 -> 87 | AM38: 2 | AN38: 3 | AO38: 3 | AP38: 3 | AQ38: =((AM38*$D$5/3)+(AN38*$E$5/3)+(AO38*$F$5/3)+(AP38*$G$5/3))*90 -> 87
A39: ='INPUT DAFTAR PESERTA'!A37 -> 34 | B39: ='INPUT DAFTAR PESERTA'!B37 -> 2509046018 | C39: ='INPUT DAFTAR PESERTA'!C37 -> Rayhana Erda Affiyah | D39: 1 | E39: 2 | F39: 2 | G39: 3 | H39: =((D39*$D$5/3)+(E39*$E$5/3)+(F39*$F$5/3)+(G39*$G$5/3))*90 -> 72 | I39: 1 | J39: 1 | K39: 1 | L39: 1 | M39: =((I39*$D$5/3)+(J39*$E$5/3)+(K39*$F$5/3)+(L39*$G$5/3))*90 -> 30 | N39: 3 | O39: 3 | P39: 3 | Q39: 3 | R39: =((N39*$D$5/3)+(O39*$E$5/3)+(P39*$F$5/3)+(Q39*$G$5/3))*90 -> 90 | S39: 3 | T39: 3 | U39: 3 | V39: 3 | W39: =((S39*$D$5/3)+(T39*$E$5/3)+(U39*$F$5/3)+(V39*$G$5/3))*90 -> 90 | X39: 3 | Y39: 3 | Z39: 2 | AA39: 3 | AB39: =((X39*$D$5/3)+(Y39*$E$5/3)+(Z39*$F$5/3)+(AA39*$G$5/3))*90 -> 84 | AC39: 3 | AD39: 2 | AE39: 2 | AF39: 2 | AG39: =((AC39*$D$5/3)+(AD39*$E$5/3)+(AE39*$F$5/3)+(AF39*$G$5/3))*90 -> 63 | AH39: 2 | AI39: 3 | AJ39: 3 | AK39: 3 | AL39: =((AH39*$D$5/3)+(AI39*$E$5/3)+(AJ39*$F$5/3)+(AK39*$G$5/3))*90 -> 87 | AM39: 2 | AN39: 3 | AO39: 3 | AP39: 2 | AQ39: =((AM39*$D$5/3)+(AN39*$E$5/3)+(AO39*$F$5/3)+(AP39*$G$5/3))*90 -> 72
A40: ='INPUT DAFTAR PESERTA'!A38 -> 35 | B40: ='INPUT DAFTAR PESERTA'!B38 -> 2509046019 | C40: ='INPUT DAFTAR PESERTA'!C38 -> Astrina Nadhiroh Illiyin | D40: 3 | E40: 3 | F40: 3 | G40: 2 | H40: =((D40*$D$5/3)+(E40*$E$5/3)+(F40*$F$5/3)+(G40*$G$5/3))*90 -> 75 | I40: 1 | J40: 1 | K40: 1 | L40: 1 | M40: =((I40*$D$5/3)+(J40*$E$5/3)+(K40*$F$5/3)+(L40*$G$5/3))*90 -> 30 | N40: 3 | O40: 3 | P40: 3 | Q40: 3 | R40: =((N40*$D$5/3)+(O40*$E$5/3)+(P40*$F$5/3)+(Q40*$G$5/3))*90 -> 90 | S40: 3 | T40: 3 | U40: 3 | V40: 3 | W40: =((S40*$D$5/3)+(T40*$E$5/3)+(U40*$F$5/3)+(V40*$G$5/3))*90 -> 90 | X40: 3 | Y40: 2 | Z40: 3 | AA40: 3 | AB40: =((X40*$D$5/3)+(Y40*$E$5/3)+(Z40*$F$5/3)+(AA40*$G$5/3))*90 -> 84 | AC40: 3 | AD40: 2 | AE40: 2 | AF40: 2 | AG40: =((AC40*$D$5/3)+(AD40*$E$5/3)+(AE40*$F$5/3)+(AF40*$G$5/3))*90 -> 63 | AH40: 2 | AI40: 3 | AJ40: 3 | AK40: 3 | AL40: =((AH40*$D$5/3)+(AI40*$E$5/3)+(AJ40*$F$5/3)+(AK40*$G$5/3))*90 -> 87 | AM40: 2 | AN40: 3 | AO40: 3 | AP40: 1.5 | AQ40: =((AM40*$D$5/3)+(AN40*$E$5/3)+(AO40*$F$5/3)+(AP40*$G$5/3))*90 -> 64.5
A41: ='INPUT DAFTAR PESERTA'!A39 -> 36 | B41: ='INPUT DAFTAR PESERTA'!B39 -> 2509046020 | C41: ='INPUT DAFTAR PESERTA'!C39 -> Muhammad Davindia Akmaluza | D41: 3 | E41: 3 | F41: 3 | G41: 1 | H41: =((D41*$D$5/3)+(E41*$E$5/3)+(F41*$F$5/3)+(G41*$G$5/3))*90 -> 60 | I41: 1 | J41: 1 | K41: 1 | L41: 1 | M41: =((I41*$D$5/3)+(J41*$E$5/3)+(K41*$F$5/3)+(L41*$G$5/3))*90 -> 30 | N41: 0 | O41: 0 | P41: 0 | Q41: 0 | R41: =((N41*$D$5/3)+(O41*$E$5/3)+(P41*$F$5/3)+(Q41*$G$5/3))*90 -> 0 | S41: 0 | T41: 0 | U41: 0 | V41: 0 | W41: =((S41*$D$5/3)+(T41*$E$5/3)+(U41*$F$5/3)+(V41*$G$5/3))*90 -> 0 | X41: 1 | Y41: 1 | Z41: 1 | AA41: 1 | AB41: =((X41*$D$5/3)+(Y41*$E$5/3)+(Z41*$F$5/3)+(AA41*$G$5/3))*90 -> 30 | AC41: 3 | AD41: 2 | AE41: 2 | AF41: 2 | AG41: =((AC41*$D$5/3)+(AD41*$E$5/3)+(AE41*$F$5/3)+(AF41*$G$5/3))*90 -> 63 | AH41: 2 | AI41: 3 | AJ41: 3 | AK41: 1 | AL41: =((AH41*$D$5/3)+(AI41*$E$5/3)+(AJ41*$F$5/3)+(AK41*$G$5/3))*90 -> 57 | AQ41: =((AM41*$D$5/3)+(AN41*$E$5/3)+(AO41*$F$5/3)+(AP41*$G$5/3))*90 -> 0
A42: ='INPUT DAFTAR PESERTA'!A40 -> 37 | B42: ='INPUT DAFTAR PESERTA'!B40 -> 2509046021 | C42: ='INPUT DAFTAR PESERTA'!C40 -> Muhammad Naufal Sabilillah | D42: 3 | E42: 3 | F42: 3 | G42: 2 | H42: =((D42*$D$5/3)+(E42*$E$5/3)+(F42*$F$5/3)+(G42*$G$5/3))*90 -> 75 | I42: 2 | J42: 2 | K42: 2 | L42: 1 | M42: =((I42*$D$5/3)+(J42*$E$5/3)+(K42*$F$5/3)+(L42*$G$5/3))*90 -> 45 | N42: 3 | O42: 3 | P42: 3 | Q42: 3 | R42: =((N42*$D$5/3)+(O42*$E$5/3)+(P42*$F$5/3)+(Q42*$G$5/3))*90 -> 90 | S42: 3 | T42: 3 | U42: 3 | V42: 3 | W42: =((S42*$D$5/3)+(T42*$E$5/3)+(U42*$F$5/3)+(V42*$G$5/3))*90 -> 90 | X42: 3 | Y42: 3 | Z42: 3 | AA42: 3 | AB42: =((X42*$D$5/3)+(Y42*$E$5/3)+(Z42*$F$5/3)+(AA42*$G$5/3))*90 -> 90 | AC42: 3 | AD42: 2 | AE42: 2 | AF42: 2 | AG42: =((AC42*$D$5/3)+(AD42*$E$5/3)+(AE42*$F$5/3)+(AF42*$G$5/3))*90 -> 63 | AH42: 2 | AI42: 3 | AJ42: 3 | AK42: 3 | AL42: =((AH42*$D$5/3)+(AI42*$E$5/3)+(AJ42*$F$5/3)+(AK42*$G$5/3))*90 -> 87 | AM42: 2 | AN42: 3 | AO42: 3 | AP42: 2 | AQ42: =((AM42*$D$5/3)+(AN42*$E$5/3)+(AO42*$F$5/3)+(AP42*$G$5/3))*90 -> 72
A43: ='INPUT DAFTAR PESERTA'!A41 -> 38 | B43: ='INPUT DAFTAR PESERTA'!B41 -> 2509046022 | C43: ='INPUT DAFTAR PESERTA'!C41 -> Miranda Nur Salsabila | D43: 2 | E43: 3 | F43: 3 | G43: 2 | H43: =((D43*$D$5/3)+(E43*$E$5/3)+(F43*$F$5/3)+(G43*$G$5/3))*90 -> 72 | I43: 2 | J43: 2 | K43: 2 | L43: 1 | M43: =((I43*$D$5/3)+(J43*$E$5/3)+(K43*$F$5/3)+(L43*$G$5/3))*90 -> 45 | N43: 3 | O43: 3 | P43: 3 | Q43: 1 | R43: =((N43*$D$5/3)+(O43*$E$5/3)+(P43*$F$5/3)+(Q43*$G$5/3))*90 -> 60 | S43: 3 | T43: 3 | U43: 3 | V43: 1 | W43: =((S43*$D$5/3)+(T43*$E$5/3)+(U43*$F$5/3)+(V43*$G$5/3))*90 -> 60 | X43: 2 | Y43: 2 | Z43: 2 | AA43: 3 | AB43: =((X43*$D$5/3)+(Y43*$E$5/3)+(Z43*$F$5/3)+(AA43*$G$5/3))*90 -> 75 | AC43: 3 | AD43: 2 | AE43: 2 | AF43: 2 | AG43: =((AC43*$D$5/3)+(AD43*$E$5/3)+(AE43*$F$5/3)+(AF43*$G$5/3))*90 -> 63 | AH43: 2 | AI43: 3 | AJ43: 3 | AK43: 3 | AL43: =((AH43*$D$5/3)+(AI43*$E$5/3)+(AJ43*$F$5/3)+(AK43*$G$5/3))*90 -> 87 | AM43: 2 | AN43: 3 | AO43: 3 | AP43: 1 | AQ43: =((AM43*$D$5/3)+(AN43*$E$5/3)+(AO43*$F$5/3)+(AP43*$G$5/3))*90 -> 57
A44: ='INPUT DAFTAR PESERTA'!A42 -> 39 | B44: ='INPUT DAFTAR PESERTA'!B42 -> 2509046023 | C44: ='INPUT DAFTAR PESERTA'!C42 -> Dinar Rahmatheta | D44: 2 | E44: 3 | F44: 3 | G44: 3 | H44: =((D44*$D$5/3)+(E44*$E$5/3)+(F44*$F$5/3)+(G44*$G$5/3))*90 -> 87 | I44: 2 | J44: 2 | K44: 2 | L44: 1 | M44: =((I44*$D$5/3)+(J44*$E$5/3)+(K44*$F$5/3)+(L44*$G$5/3))*90 -> 45 | N44: 3 | O44: 3 | P44: 3 | Q44: 1 | R44: =((N44*$D$5/3)+(O44*$E$5/3)+(P44*$F$5/3)+(Q44*$G$5/3))*90 -> 60 | S44: 3 | T44: 3 | U44: 3 | V44: 1 | W44: =((S44*$D$5/3)+(T44*$E$5/3)+(U44*$F$5/3)+(V44*$G$5/3))*90 -> 60 | X44: 3 | Y44: 2 | Z44: 2 | AA44: 3 | AB44: =((X44*$D$5/3)+(Y44*$E$5/3)+(Z44*$F$5/3)+(AA44*$G$5/3))*90 -> 78 | AC44: 3 | AD44: 2 | AE44: 2 | AF44: 2 | AG44: =((AC44*$D$5/3)+(AD44*$E$5/3)+(AE44*$F$5/3)+(AF44*$G$5/3))*90 -> 63 | AH44: 2 | AI44: 3 | AJ44: 3 | AK44: 3 | AL44: =((AH44*$D$5/3)+(AI44*$E$5/3)+(AJ44*$F$5/3)+(AK44*$G$5/3))*90 -> 87 | AM44: 2 | AN44: 3 | AO44: 3 | AP44: 2 | AQ44: =((AM44*$D$5/3)+(AN44*$E$5/3)+(AO44*$F$5/3)+(AP44*$G$5/3))*90 -> 72
A45: ='INPUT DAFTAR PESERTA'!A43 -> 40 | B45: ='INPUT DAFTAR PESERTA'!B43 -> 2509046024 | C45: ='INPUT DAFTAR PESERTA'!C43 -> Muh. Yasir Naufal | D45: 3 | E45: 3 | F45: 3 | G45: 1 | H45: =((D45*$D$5/3)+(E45*$E$5/3)+(F45*$F$5/3)+(G45*$G$5/3))*90 -> 60 | I45: 1 | J45: 1 | K45: 1 | L45: 1 | M45: =((I45*$D$5/3)+(J45*$E$5/3)+(K45*$F$5/3)+(L45*$G$5/3))*90 -> 30 | N45: 0 | O45: 0 | P45: 0 | Q45: 0 | R45: =((N45*$D$5/3)+(O45*$E$5/3)+(P45*$F$5/3)+(Q45*$G$5/3))*90 -> 0 | S45: 0 | T45: 0 | U45: 0 | V45: 0 | W45: =((S45*$D$5/3)+(T45*$E$5/3)+(U45*$F$5/3)+(V45*$G$5/3))*90 -> 0 | X45: 1 | Y45: 1 | Z45: 1 | AA45: 1 | AB45: =((X45*$D$5/3)+(Y45*$E$5/3)+(Z45*$F$5/3)+(AA45*$G$5/3))*90 -> 30 | AC45: 3 | AD45: 3 | AE45: 3 | AF45: 3 | AG45: =((AC45*$D$5/3)+(AD45*$E$5/3)+(AE45*$F$5/3)+(AF45*$G$5/3))*90 -> 90 | AH45: 2 | AI45: 3 | AJ45: 3 | AK45: 1 | AL45: =((AH45*$D$5/3)+(AI45*$E$5/3)+(AJ45*$F$5/3)+(AK45*$G$5/3))*90 -> 57 | AQ45: =((AM45*$D$5/3)+(AN45*$E$5/3)+(AO45*$F$5/3)+(AP45*$G$5/3))*90 -> 0
A46: ='INPUT DAFTAR PESERTA'!A44 -> 41 | B46: ='INPUT DAFTAR PESERTA'!B44 -> 2509046025 | C46: ='INPUT DAFTAR PESERTA'!C44 -> Andi Nada Bunga Zahra | D46: 3 | E46: 3 | F46: 3 | G46: 2 | H46: =((D46*$D$5/3)+(E46*$E$5/3)+(F46*$F$5/3)+(G46*$G$5/3))*90 -> 75 | I46: 3 | J46: 3 | K46: 3 | L46: 3 | M46: =((I46*$D$5/3)+(J46*$E$5/3)+(K46*$F$5/3)+(L46*$G$5/3))*90 -> 90 | N46: 3 | O46: 3 | P46: 3 | Q46: 2 | R46: =((N46*$D$5/3)+(O46*$E$5/3)+(P46*$F$5/3)+(Q46*$G$5/3))*90 -> 75 | S46: 3 | T46: 3 | U46: 3 | V46: 1 | W46: =((S46*$D$5/3)+(T46*$E$5/3)+(U46*$F$5/3)+(V46*$G$5/3))*90 -> 60 | X46: 2 | Y46: 3 | Z46: 3 | AA46: 1 | AB46: =((X46*$D$5/3)+(Y46*$E$5/3)+(Z46*$F$5/3)+(AA46*$G$5/3))*90 -> 57 | AC46: 3 | AD46: 3 | AE46: 3 | AF46: 2 | AG46: =((AC46*$D$5/3)+(AD46*$E$5/3)+(AE46*$F$5/3)+(AF46*$G$5/3))*90 -> 75 | AH46: 3 | AI46: 3 | AJ46: 3 | AK46: 3 | AL46: =((AH46*$D$5/3)+(AI46*$E$5/3)+(AJ46*$F$5/3)+(AK46*$G$5/3))*90 -> 90 | AM46: 3 | AN46: 3 | AO46: 3 | AP46: 3 | AQ46: =((AM46*$D$5/3)+(AN46*$E$5/3)+(AO46*$F$5/3)+(AP46*$G$5/3))*90 -> 90
A47: ='INPUT DAFTAR PESERTA'!A45 -> 42 | B47: ='INPUT DAFTAR PESERTA'!B45 -> 2509046026 | C47: ='INPUT DAFTAR PESERTA'!C45 -> Nabil Rafif Makarim | D47: 3 | E47: 3 | F47: 3 | G47: 2 | H47: =((D47*$D$5/3)+(E47*$E$5/3)+(F47*$F$5/3)+(G47*$G$5/3))*90 -> 75 | I47: 1 | J47: 1 | K47: 1 | L47: 1 | M47: =((I47*$D$5/3)+(J47*$E$5/3)+(K47*$F$5/3)+(L47*$G$5/3))*90 -> 30 | N47: 3 | O47: 3 | P47: 3 | Q47: 1 | R47: =((N47*$D$5/3)+(O47*$E$5/3)+(P47*$F$5/3)+(Q47*$G$5/3))*90 -> 60 | S47: 3 | T47: 3 | U47: 3 | V47: 1 | W47: =((S47*$D$5/3)+(T47*$E$5/3)+(U47*$F$5/3)+(V47*$G$5/3))*90 -> 60 | X47: 2 | Y47: 3 | Z47: 3 | AA47: 1 | AB47: =((X47*$D$5/3)+(Y47*$E$5/3)+(Z47*$F$5/3)+(AA47*$G$5/3))*90 -> 57 | AC47: 3 | AD47: 2 | AE47: 2 | AF47: 2 | AG47: =((AC47*$D$5/3)+(AD47*$E$5/3)+(AE47*$F$5/3)+(AF47*$G$5/3))*90 -> 63 | AH47: 3 | AI47: 3 | AJ47: 3 | AK47: 2 | AL47: =((AH47*$D$5/3)+(AI47*$E$5/3)+(AJ47*$F$5/3)+(AK47*$G$5/3))*90 -> 75 | AM47: 3 | AN47: 3 | AO47: 3 | AP47: 1 | AQ47: =((AM47*$D$5/3)+(AN47*$E$5/3)+(AO47*$F$5/3)+(AP47*$G$5/3))*90 -> 60
A48: ='INPUT DAFTAR PESERTA'!A46 -> 43 | B48: ='INPUT DAFTAR PESERTA'!B46 -> 2509046027 | C48: ='INPUT DAFTAR PESERTA'!C46 -> Natasya Camelia Az-Zahra | D48: 3 | E48: 3 | F48: 3 | G48: 3 | H48: =((D48*$D$5/3)+(E48*$E$5/3)+(F48*$F$5/3)+(G48*$G$5/3))*90 -> 90 | I48: 3 | J48: 3 | K48: 3 | L48: 2 | M48: =((I48*$D$5/3)+(J48*$E$5/3)+(K48*$F$5/3)+(L48*$G$5/3))*90 -> 75 | N48: 3 | O48: 3 | P48: 3 | Q48: 2 | R48: =((N48*$D$5/3)+(O48*$E$5/3)+(P48*$F$5/3)+(Q48*$G$5/3))*90 -> 75 | S48: 3 | T48: 3 | U48: 3 | V48: 1 | W48: =((S48*$D$5/3)+(T48*$E$5/3)+(U48*$F$5/3)+(V48*$G$5/3))*90 -> 60 | X48: 2 | Y48: 3 | Z48: 3 | AA48: 1 | AB48: =((X48*$D$5/3)+(Y48*$E$5/3)+(Z48*$F$5/3)+(AA48*$G$5/3))*90 -> 57 | AC48: 3 | AD48: 3 | AE48: 3 | AF48: 2 | AG48: =((AC48*$D$5/3)+(AD48*$E$5/3)+(AE48*$F$5/3)+(AF48*$G$5/3))*90 -> 75 | AH48: 3 | AI48: 3 | AJ48: 3 | AK48: 3 | AL48: =((AH48*$D$5/3)+(AI48*$E$5/3)+(AJ48*$F$5/3)+(AK48*$G$5/3))*90 -> 90 | AM48: 3 | AN48: 3 | AO48: 3 | AP48: 3 | AQ48: =((AM48*$D$5/3)+(AN48*$E$5/3)+(AO48*$F$5/3)+(AP48*$G$5/3))*90 -> 90
