Workbook

Sheet INPUT DAFTAR PESERTA
A1: PRODI: TEKNIK PERTAMBANGAN
A3: NO | B3: NIM | C3: Nama | E3: WORKSHEET TEMPLATE
A4: 1 | B4: 2309056046 | C4: Erwin | E4: SISTEM PENILAIAN PRAKTIKUM
A5: 2 | B5: 2409056015 | C5: Denny Setiawan | E5: LABORATORIUM LAYANAN DASAR
A6: 3 | B6: 2409056031 | C6: Rahmad Oka Aufa Ramadan
A7: 4 | B7: 2409056032 | C7: Stewa Syaifa Bakhid
A8: 5 | B8: 2409056033 | C8: Adnan Fadil Annur
A9: 6 | B9: 2409056039 | C9: Muhammad Hasbi Ash Shiddieqy
A10: 7 | B10: 2409056044 | C10: Siti Aisyah Hasanah
A11: 8 | B11: 2409056047 | C11: D’arch Hweng Junior
A12: 9 | B12: 2409056052 | C12: Andi Syaifullah Al Maslulil Agri | E12: VER 2 (April 2025)
A13: 10 | B13: 2409056058 | C13: Andre Pratama
A14: 11 | B14: 2409056067 | C14: Andi Afif Najib Abdillah
A15: 12 | B15: 2409056068 | C15: Christianus Gonzaga | E15: Petunjuk Penggunaan Template
A16: 13 | B16: 2509056001 | C16: Mutiara Suci Rahmadani
A17: 14 | B17: 2509056002 | C17: Adhwa Ghinna Febrianty | E17: 1. Isikan daftar peserta praktikum pada sheet "INPUT DAFTAR PESERTA"
A18: 15 | B18: 2509056003 | C18: Muhammad Daffa Alifiansyah | E18: (Disarankan untuk menyesuaikan dengan template disamping)
A19: 16 | B19: 2509056004 | C19: Adya Nur Adzhuriva | E19: 2. Isian Nama dan NIM pada sheet selanjutnya akan terinput secara otomatis sesuai dengan isian sheet "INPUT DAFTAR PESERTA"
A20: 17 | B20: 2509056005 | C20: Cheva Fasha Prathama | E20: 3. Nilai praktikum diisikan pada sheet "PENULISAN LAPORAN", "LAPORAN RESMI", "KEMAMPUAN PRAKTIKUM dan "NILAI HARIAN"
A21: 18 | B21: 2509056006 | C21: Muhammad Zaki Fadillah | E21: 4. Rekapitulasi nilai praktikum permodul akan terakumulasi secara otomatis pada sheet "NILAI AKHIR" dan PIE-CHART"
A22: 19 | B22: 2509056007 | C22: Widdyanti Fetrina Sefriany | E22: 5. Perubahan formula pada sistem menyesuaikan dengan aturan dan SOP terbaru penilaian praktikum Lab Elektro Dasar
A23: 20 | B23: 2509056008 | C23: Gita Mufidatuzahrah | E23: 6. Link akses Surat Keterangan Lulus Praktikum sebagai berikut:
A24: 21 | B24: 2509056009 | C24: Muhammad Hersal Ramadhan
A25: 22 | B25: 2509056010 | C25: Chikal Fattiya Putri | E25: 7. Link akses Sheet perkomponen sebagai berikut:
A26: 23 | B26: 2509056011 | C26: Muhammad Daffa Lailitama Sinaga | E26: Penulisan Laporan
A27: 24 | B27: 2509056012 | C27: Sera Ayu Ningsih | E27: Laporan Resmi
A28: 25 | B28: 2509056013 | C28: Naufal Firdaus Syauqi | E28: Kemampuan Praktikum
A29: 26 | B29: 2509056014 | C29: Alexander Radja Roben Saragih | E29: Nilai Harian
A30: 27 | B30: 2509056015 | C30: Tiara Aqila Azzahra | E30: Nilai Akhir
A31: 28 | B31: 2509056016 | C31: Muhammad Haikal Islamy Saputra | E31: Pie Chart
A32: 29 | B32: 2509056017 | C32: Faatihur Rizki
A33: 30 | B33: 2509056018 | C33: Rashya Annara Salsabilla Tomasoa
A34: 31 | B34: 2509056019 | C34: Desta Novie Sulfianie
A35: 32 | B35: 2509056020 | C35: Chandra Ahmad Dwinata
A36: 33 | B36: 2509056021 | C36: Sopando Imanuel Sipayung
A37: 34 | B37: 2509056022 | C37: Rayhan Winata Prabowo
A38: 35 | B38: 2509056023 | C38: Ahmad Din Nejad
A39: 36 | B39: 2509056024 | C39: Nabil Candra Hartanto
A40: 37 | B40: 2509056025 | C40: Muhammad Rifqi Ibnu Malik
A41: 38 | B41: 2509056026 | C41: Aditya Alfiansyah
...

Sheet LAPORAN RESMI
A2: NO | B2: NIM | C2: NAMA | D2: Laporan Resmi | L2: Rata-rata
D3: Modul 1 | E3: Modul 2 | F3: Modul 3 | G3: Modul 4 | H3: Modul 5 | I3: Modul 6 | J3: Modul 7 | K3: Modul 8
A4: ='INPUT DAFTAR PESERTA'!A4 -> 1 | B4: ='INPUT DAFTAR PESERTA'!B4 -> 2309056046 | C4: ='INPUT DAFTAR PESERTA'!C4 -> Erwin | D4: 50 | E4: 45 | F4: 30 | G4: 40 | H4: 60 | I4: 10 | J4: 30 | K4: 50 | L4: =(D4+E4+F4+G4+H4+I4+J4+K4)/8 -> 39.375
A5: ='INPUT DAFTAR PESERTA'!A5 -> 2 | B5: ='INPUT DAFTAR PESERTA'!B5 -> 2409056015 | C5: ='INPUT DAFTAR PESERTA'!C5 -> Denny Setiawan | L5: =(D5+E5+F5+G5+H5+I5+J5+K5)/8 -> 0
A6: ='INPUT DAFTAR PESERTA'!A6 -> 3 | B6: ='INPUT DAFTAR PESERTA'!B6 -> 2409056031 | C6: ='INPUT DAFTAR PESERTA'!C6 -> Rahmad Oka Aufa Ramadan | L6: =(D6+E6+F6+G6+H6+I6+J6+K6)/8 -> 0
A7: ='INPUT DAFTAR PESERTA'!A7 -> 4 | B7: ='INPUT DAFTAR PESERTA'!B7 -> 2409056032 | C7: ='INPUT DAFTAR PESERTA'!C7 -> Stewa Syaifa Bakhid | L7: =(D7+E7+F7+G7+H7+I7+J7+K7)/8 -> 0
A8: ='INPUT DAFTAR PESERTA'!A8 -> 5 | B8: ='INPUT DAFTAR PESERTA'!B8 -> 2409056033 | C8: ='INPUT DAFTAR PESERTA'!C8 -> Adnan Fadil Annur | L8: =(D8+E8+F8+G8+H8+I8+J8+K8)/8 -> 0
A9: ='INPUT DAFTAR PESERTA'!A9 -> 6 | B9: ='INPUT DAFTAR PESERTA'!B9 -> 2409056039 | C9: ='INPUT DAFTAR PESERTA'!C9 -> Muhammad Hasbi Ash Shiddieqy | L9: =(D9+E9+F9+G9+H9+I9+J9+K9)/8 -> 0
A10: ='INPUT DAFTAR PESERTA'!A10 -> 7 | B10: ='INPUT DAFTAR PESERTA'!B10 -> 2409056044 | C10: ='INPUT DAFTAR PESERTA'!C10 -> Siti Aisyah Hasanah | L10: =(D10+E10+F10+G10+H10+I10+J10+K10)/8 -> 0
A11: ='INPUT DAFTAR PESERTA'!A11 -> 8 | B11: ='INPUT DAFTAR PESERTA'!B11 -> 2409056047 | C11: ='INPUT DAFTAR PESERTA'!C11 -> D’arch Hweng Junior | L11: =(D11+E11+F11+G11+H11+I11+J11+K11)/8 -> 0
A12: ='INPUT DAFTAR PESERTA'!A12 -> 9 | B12: ='INPUT DAFTAR PESERTA'!B12 -> 2409056052 | C12: ='INPUT DAFTAR PESERTA'!C12 -> Andi Syaifullah Al Maslulil Agri | L12: =(D12+E12+F12+G12+H12+I12+J12+K12)/8 -> 0
A13: ='INPUT DAFTAR PESERTA'!A13 -> 10 | B13: ='INPUT DAFTAR PESERTA'!B13 -> 2409056058 | C13: ='INPUT DAFTAR PESERTA'!C13 -> Andre Pratama | L13: =(D13+E13+F13+G13+H13+I13+J13+K13)/8 -> 0
A14: ='INPUT DAFTAR PESERTA'!A14 -> 11 | B14: ='INPUT DAFTAR PESERTA'!B14 -> 2409056067 | C14: ='INPUT DAFTAR PESERTA'!C14 -> Andi Afif Najib Abdillah | L14: =(D14+E14+F14+G14+H14+I14+J14+K14)/8 -> 0
A15: ='INPUT DAFTAR PESERTA'!A15 -> 12 | B15: ='INPUT DAFTAR PESERTA'!B15 -> 2409056068 | C15: ='INPUT DAFTAR PESERTA'!C15 -> Christianus Gonzaga | L15: =(D15+E15+F15+G15+H15+I15+J15+K15)/8 -> 0
A16: ='INPUT DAFTAR PESERTA'!A16 -> 13 | B16: ='INPUT DAFTAR PESERTA'!B16 -> 2509056001 | C16: ='INPUT DAFTAR PESERTA'!C16 -> Mutiara Suci Rahmadani | D16: 95 | E16: 87 | F16: 98 | G16: 89 | H16: 95 | I16: 100 | J16: 96 | K16: 90 | L16: =(D16+E16+F16+G16+H16+I16+J16+K16)/8 -> 93.75
A17: ='INPUT DAFTAR PESERTA'!A17 -> 14 | B17: ='INPUT DAFTAR PESERTA'!B17 -> 2509056002 | C17: ='INPUT DAFTAR PESERTA'!C17 -> Adhwa Ghinna Febrianty | D17: 95 | E17: 86 | F17: 100 | G17: 92 | H17: 90 | I17: 100 | J17: 95 | K17: 90 | L17: =(D17+E17+F17+G17+H17+I17+J17+K17)/8 -> 93.5
A18: ='INPUT DAFTAR PESERTA'!A18 -> 15 | B18: ='INPUT DAFTAR PESERTA'!B18 -> 2509056003 | C18: ='INPUT DAFTAR PESERTA'!C18 -> Muhammad Daffa Alifiansyah | D18: 90 | E18: 90 | F18: 100 | G18: 86 | H18: 90 | I18: 30 | J18: 94 | K18: 90 | L18: =(D18+E18+F18+G18+H18+I18+J18+K18)/8 -> 83.75
A19: ='INPUT DAFTAR PESERTA'!A19 -> 16 | B19: ='INPUT DAFTAR PESERTA'!B19 -> 2509056004 | C19: ='INPUT DAFTAR PESERTA'!C19 -> Adya Nur Adzhuriva | L19: =(D19+E19+F19+G19+H19+I19+J19+K19)/8 -> 0
A20: ='INPUT DAFTAR PESERTA'!A20 -> 17 | B20: ='INPUT DAFTAR PESERTA'!B20 -> 2509056005 | C20: ='INPUT DAFTAR PESERTA'!C20 -> Cheva Fasha Prathama | L20: =(D20+E20+F20+G20+H20+I20+J20+K20)/8 -> 0
A21: ='INPUT DAFTAR PESERTA'!A21 -> 18 | B21: ='INPUT DAFTAR PESERTA'!B21 -> 2509056006 | C21: ='INPUT DAFTAR PESERTA'!C21 -> Muhammad Zaki Fadillah | L21: =(D21+E21+F21+G21+H21+I21+J21+K21)/8 -> 0
A22: ='INPUT DAFTAR PESERTA'!A22 -> 19 | B22: ='INPUT DAFTAR PESERTA'!B22 -> 2509056007 | C22: ='INPUT DAFTAR PESERTA'!C22 -> Widdyanti Fetrina Sefriany | L22: =(D22+E22+F22+G22+H22+I22+J22+K22)/8 -> 0
A23: ='INPUT DAFTAR PESERTA'!A23 -> 20 | B23: ='INPUT DAFTAR PESERTA'!B23 -> 2509056008 | C23: ='INPUT DAFTAR PESERTA'!C23 -> Gita Mufidatuzahrah | L23: =(D23+E23+F23+G23+H23+I23+J23+K23)/8 -> 0
A24: ='INPUT DAFTAR PESERTA'!A24 -> 21 | B24: ='INPUT DAFTAR PESERTA'!B24 -> 2509056009 | C24: ='INPUT DAFTAR PESERTA'!C24 -> Muhammad Hersal Ramadhan | D24: 90 | E24: 73 | F24: 96 | G24: 99 | H24: 80 | I24: 80 | J24: 96 | K24: 98 | L24: =(D24+E24+F24+G24+H24+I24+J24+K24)/8 -> 89
A25: ='INPUT DAFTAR PESERTA'!A25 -> 22 | B25: ='INPUT DAFTAR PESERTA'!B25 -> 2509056010 | C25: ='INPUT DAFTAR PESERTA'!C25 -> Chikal Fattiya Putri | L25: =(D25+E25+F25+G25+H25+I25+J25+K25)/8 -> 0
A26: ='INPUT DAFTAR PESERTA'!A26 -> 23 | B26: ='INPUT DAFTAR PESERTA'!B26 -> 2509056011 | C26: ='INPUT DAFTAR PESERTA'!C26 -> Muhammad Daffa Lailitama Sinaga | D26: 95 | E26: 92 | F26: 98 | G26: 95 | H26: 100 | I26: 100 | J26: 96 | K26: 98 | L26: =(D26+E26+F26+G26+H26+I26+J26+K26)/8 -> 96.75
A27: ='INPUT DAFTAR PESERTA'!A27 -> 24 | B27: ='INPUT DAFTAR PESERTA'!B27 -> 2509056012 | C27: ='INPUT DAFTAR PESERTA'!C27 -> Sera Ayu Ningsih | D27: 90 | E27: 42 | F27: 30 | G27: 60 | H27: 60 | I27: 35 | J27: 62 | K27: 90 | L27: =(D27+E27+F27+G27+H27+I27+J27+K27)/8 -> 58.625
A28: ='INPUT DAFTAR PESERTA'!A28 -> 25 | B28: ='INPUT DAFTAR PESERTA'!B28 -> 2509056013 | C28: ='INPUT DAFTAR PESERTA'!C28 -> Naufal Firdaus Syauqi | D28: 90 | E28: 83 | F28: 98 | G28: 83 | H28: 80 | I28: 100 | J28: 95 | K28: 90 | L28: =(D28+E28+F28+G28+H28+I28+J28+K28)/8 -> 89.875
A29: ='INPUT DAFTAR PESERTA'!A29 -> 26 | B29: ='INPUT DAFTAR PESERTA'!B29 -> 2509056014 | C29: ='INPUT DAFTAR PESERTA'!C29 -> Alexander Radja Roben Saragih | D29: 98 | E29: 88 | F29: 99 | G29: 99 | H29: 90 | I29: 100 | J29: 95 | K29: 98 | L29: =(D29+E29+F29+G29+H29+I29+J29+K29)/8 -> 95.875
A30: ='INPUT DAFTAR PESERTA'!A30 -> 27 | B30: ='INPUT DAFTAR PESERTA'!B30 -> 2509056015 | C30: ='INPUT DAFTAR PESERTA'!C30 -> Tiara Aqila Azzahra | D30: 90 | E30: 87 | F30: 100 | G30: 98 | H30: 80 | I30: 100 | J30: 96 | K30: 98 | L30: =(D30+E30+F30+G30+H30+I30+J30+K30)/8 -> 93.625
A31: ='INPUT DAFTAR PESERTA'!A31 -> 28 | B31: ='INPUT DAFTAR PESERTA'!B31 -> 2509056016 | C31: ='INPUT DAFTAR PESERTA'!C31 -> Muhammad Haikal Islamy Saputra | D31: 96 | E31: 81 | F31: 99 | G31: 89 | H31: 80 | I31: 100 | J31: 74 | K31: 90 | L31: =(D31+E31+F31+G31+H31+I31+J31+K31)/8 -> 88.625
A32: ='INPUT DAFTAR PESERTA'!A32 -> 29 | B32: ='INPUT DAFTAR PESERTA'!B32 -> 2509056017 | C32: ='INPUT DAFTAR PESERTA'!C32 -> Faatihur Rizki | D32: 96 | E32: 88 | F32: 98 | G32: 96 | H32: 90 | I32: 100 | J32: 96 | K32: 90 | L32: =(D32+E32+F32+G32+H32+I32+J32+K32)/8 -> 94.25
A33: ='INPUT DAFTAR PESERTA'!A33 -> 30 | B33: ='INPUT DAFTAR PESERTA'!B33 -> 2509056018 | C33: ='INPUT DAFTAR PESERTA'!C33 -> Rashya Annara Salsabilla Tomasoa | D33: 96 | E33: 97 | F33: 100 | G33: 98 | H33: 80 | I33: 100 | J33: 96 | K33: 98 | L33: =(D33+E33+F33+G33+H33+I33+J33+K33)/8 -> 95.625
A34: ='INPUT DAFTAR PESERTA'!A34 -> 31 | B34: ='INPUT DAFTAR PESERTA'!B34 -> 2509056019 | C34: ='INPUT DAFTAR PESERTA'!C34 -> Desta Novie Sulfianie | L34: =(D34+E34+F34+G34+H34+I34+J34+K34)/8 -> 0
A35: ='INPUT DAFTAR PESERTA'!A35 -> 32 | B35: ='INPUT DAFTAR PESERTA'!B35 -> 2509056020 | C35: ='INPUT DAFTAR PESERTA'!C35 -> Chandra Ahmad Dwinata | D35: 17 | E35: 25 | F35: 15 | G35: 42 | H35: 50 | I35: 27 | J35: 40 | K35: 50 | L35: =(D35+E35+F35+G35+H35+I35+J35+K35)/8 -> 33.25
A36: ='INPUT DAFTAR PESERTA'!A36 -> 33 | B36: ='INPUT DAFTAR PESERTA'!B36 -> 2509056021 | C36: ='INPUT DAFTAR PESERTA'!C36 -> Sopando Imanuel Sipayung | D36: 80 | E36: 98 | F36: 95 | G36: 91 | H36: 80 | I36: 100 | J36: 94 | K36: 98 | L36: =(D36+E36+F36+G36+H36+I36+J36+K36)/8 -> 92
A37: ='INPUT DAFTAR PESERTA'!A37 -> 34 | B37: ='INPUT DAFTAR PESERTA'!B37 -> 2509056022 | C37: ='INPUT DAFTAR PESERTA'!C37 -> Rayhan Winata Prabowo | D37: 80 | E37: 85 | F37: 100 | G37: 96 | H37: 90 | I37: 100 | J37: 96 | K37: 90 | L37: =(D37+E37+F37+G37+H37+I37+J37+K37)/8 -> 92.125
A38: ='INPUT DAFTAR PESERTA'!A38 -> 35 | B38: ='INPUT DAFTAR PESERTA'!B38 -> 2509056023 | C38: ='INPUT DAFTAR PESERTA'!C38 -> Ahmad Din Nejad | L38: =(D38+E38+F38+G38+H38+I38+J38+K38)/8 -> 0
A39: ='INPUT DAFTAR PESERTA'!A39 -> 36 | B39: ='INPUT DAFTAR PESERTA'!B39 -> 2509056024 | C39: ='INPUT DAFTAR PESERTA'!C39 -> Nabil Candra Hartanto | D39: 85 | E39: 78 | F39: 98 | G39: 92 | H39: 70 | I39: 100 | J39: 96 | K39: 90 | L39: =(D39+E39+F39+G39+H39+I39+J39+K39)/8 -> 88.625
A40: ='INPUT DAFTAR PESERTA'!A40 -> 37 | B40: ='INPUT DAFTAR PESERTA'!B40 -> 2509056025 | C40: ='INPUT DAFTAR PESERTA'!C40 -> Muhammad Rifqi Ibnu Malik | L40: =(D40+E40+F40+G40+H40+I40+J40+K40)/8 -> 0
A41: ='INPUT DAFTAR PESERTA'!A41 -> 38 | B41: ='INPUT DAFTAR PESERTA'!B41 -> 2509056026 | C41: ='INPUT DAFTAR PESERTA'!C41 -> Aditya Alfiansyah | L41: =(D41+E41+F41+G41+H41+I41+J41+K41)/8 -> 0
...

Sheet PENULISAN LAPORAN
A1: HOME
A3: NO | B3: Nim | C3: Nama | D3: Laporan Mingguan | L3: Rata-rata | M3: Resmi | N3: Nilai Akhir
D4: Modul 1 | E4: Modul 2 | F4: Modul 3 | G4: Modul 4 | H4: Modul 5 | I4: Modul 6 | J4: Modul 7 | K4: Modul 8 | L4: 0.5 | M4: 0.5
A5: ='INPUT DAFTAR PESERTA'!A4 -> 1 | B5: ='INPUT DAFTAR PESERTA'!B4 -> 2309056046 | C5: ='INPUT DAFTAR PESERTA'!C4 -> Erwin | D5: 50 | E5: 0 | F5: 0 | G5: 0 | H5: 70 | I5: 0 | J5: 0 | K5: 0 | L5: =(D5+E5+F5+G5+H5+I5+J5+K5)/8 -> 15 | M5: ='LAPORAN RESMI'!L4 -> 39.375 | N5: =(L5*$L$4)+(M5*$M$4) -> 27.1875
A6: ='INPUT DAFTAR PESERTA'!A5 -> 2 | B6: ='INPUT DAFTAR PESERTA'!B5 -> 2409056015 | C6: ='INPUT DAFTAR PESERTA'!C5 -> Denny Setiawan | G6: 0 | H6: 0 | I6: 0 | J6: 0 | K6: 0 | L6: =(D6+E6+F6+G6+H6+I6+J6+K6)/8 -> 0 | M6: ='LAPORAN RESMI'!L5 -> 0 | N6: =(L6*$L$4)+(M6*$M$4) -> 0
A7: ='INPUT DAFTAR PESERTA'!A6 -> 3 | B7: ='INPUT DAFTAR PESERTA'!B6 -> 2409056031 | C7: ='INPUT DAFTAR PESERTA'!C6 -> Rahmad Oka Aufa Ramadan | G7: 0 | H7: 0 | I7: 0 | K7: 0 | L7: =(D7+E7+F7+G7+H7+I7+J7+K7)/8 -> 0 | M7: ='LAPORAN RESMI'!L6 -> 0 | N7: =(L7*$L$4)+(M7*$M$4) -> 0
A8: ='INPUT DAFTAR PESERTA'!A7 -> 4 | B8: ='INPUT DAFTAR PESERTA'!B7 -> 2409056032 | C8: ='INPUT DAFTAR PESERTA'!C7 -> Stewa Syaifa Bakhid | G8: 0 | H8: 0 | I8: 0 | K8: 0 | L8: =(D8+E8+F8+G8+H8+I8+J8+K8)/8 -> 0 | M8: ='LAPORAN RESMI'!L7 -> 0 | N8: =(L8*$L$4)+(M8*$M$4) -> 0
A9: ='INPUT DAFTAR PESERTA'!A8 -> 5 | B9: ='INPUT DAFTAR PESERTA'!B8 -> 2409056033 | C9: ='INPUT DAFTAR PESERTA'!C8 -> Adnan Fadil Annur | D9: 85 | G9: 0 | H9: 0 | I9: 0 | K9: 0 | L9: =(D9+E9+F9+G9+H9+I9+J9+K9)/8 -> 10.625 | M9: ='LAPORAN RESMI'!L8 -> 0 | N9: =(L9*$L$4)+(M9*$M$4) -> 5.3125
A10: ='INPUT DAFTAR PESERTA'!A9 -> 6 | B10: ='INPUT DAFTAR PESERTA'!B9 -> 2409056039 | C10: ='INPUT DAFTAR PESERTA'!C9 -> Muhammad Hasbi Ash Shiddieqy | G10: 0 | H10: 0 | I10: 0 | K10: 0 | L10: =(D10+E10+F10+G10+H10+I10+J10+K10)/8 -> 0 | M10: ='LAPORAN RESMI'!L9 -> 0 | N10: =(L10*$L$4)+(M10*$M$4) -> 0
A11: ='INPUT DAFTAR PESERTA'!A10 -> 7 | B11: ='INPUT DAFTAR PESERTA'!B10 -> 2409056044 | C11: ='INPUT DAFTAR PESERTA'!C10 -> Siti Aisyah Hasanah | G11: 0 | H11: 0 | I11: 0 | K11: 0 | L11: =(D11+E11+F11+G11+H11+I11+J11+K11)/8 -> 0 | M11: ='LAPORAN RESMI'!L10 -> 0 | N11: =(L11*$L$4)+(M11*$M$4) -> 0
A12: ='INPUT DAFTAR PESERTA'!A11 -> 8 | B12: ='INPUT DAFTAR PESERTA'!B11 -> 2409056047 | C12: ='INPUT DAFTAR PESERTA'!C11 -> D’arch Hweng Junior | G12: 0 | H12: 0 | I12: 0 | K12: 0 | L12: =(D12+E12+F12+G12+H12+I12+J12+K12)/8 -> 0 | M12: ='LAPORAN RESMI'!L11 -> 0 | N12: =(L12*$L$4)+(M12*$M$4) -> 0
A13: ='INPUT DAFTAR PESERTA'!A12 -> 9 | B13: ='INPUT DAFTAR PESERTA'!B12 -> 2409056052 | C13: ='INPUT DAFTAR PESERTA'!C12 -> Andi Syaifullah Al Maslulil Agri | G13: 0 | H13: 0 | I13: 0 | K13: 0 | L13: =(D13+E13+F13+G13+H13+I13+J13+K13)/8 -> 0 | M13: ='LAPORAN RESMI'!L12 -> 0 | N13: =(L13*$L$4)+(M13*$M$4) -> 0
A14: ='INPUT DAFTAR PESERTA'!A13 -> 10 | B14: ='INPUT DAFTAR PESERTA'!B13 -> 2409056058 | C14: ='INPUT DAFTAR PESERTA'!C13 -> Andre Pratama | G14: 0 | H14: 0 | I14: 0 | K14: 0 | L14: =(D14+E14+F14+G14+H14+I14+J14+K14)/8 -> 0 | M14: ='LAPORAN RESMI'!L13 -> 0 | N14: =(L14*$L$4)+(M14*$M$4) -> 0
A15: ='INPUT DAFTAR PESERTA'!A14 -> 11 | B15: ='INPUT DAFTAR PESERTA'!B14 -> 2409056067 | C15: ='INPUT DAFTAR PESERTA'!C14 -> Andi Afif Najib Abdillah | G15: 0 | H15: 0 | I15: 0 | K15: 0 | L15: =(D15+E15+F15+G15+H15+I15+J15+K15)/8 -> 0 | M15: ='LAPORAN RESMI'!L14 -> 0 | N15: =(L15*$L$4)+(M15*$M$4) -> 0
A16: ='INPUT DAFTAR PESERTA'!A15 -> 12 | B16: ='INPUT DAFTAR PESERTA'!B15 -> 2409056068 | C16: ='INPUT DAFTAR PESERTA'!C15 -> Christianus Gonzaga | G16: 0 | H16: 0 | I16: 0 | K16: 0 | L16: =(D16+E16+F16+G16+H16+I16+J16+K16)/8 -> 0 | M16: ='LAPORAN RESMI'!L15 -> 0 | N16: =(L16*$L$4)+(M16*$M$4) -> 0
A17: ='INPUT DAFTAR PESERTA'!A16 -> 13 | B17: ='INPUT DAFTAR PESERTA'!B16 -> 2509056001 | C17: ='INPUT DAFTAR PESERTA'!C16 -> Mutiara Suci Rahmadani | D17: 50 | E17: 57 | F17: 71 | G17: 84 | H17: 37 | I17: 36 | J17: 91 | K17: 49 | L17: =(D17+E17+F17+G17+H17+I17+J17+K17)/8 -> 59.375 | M17: ='LAPORAN RESMI'!L16 -> 93.75 | N17: =(L17*$L$4)+(M17*$M$4) -> 76.5625
A18: ='INPUT DAFTAR PESERTA'!A17 -> 14 | B18: ='INPUT DAFTAR PESERTA'!B17 -> 2509056002 | C18: ='INPUT DAFTAR PESERTA'!C17 -> Adhwa Ghinna Febrianty | D18: 75 | E18: 41 | F18: 81 | G18: 70 | H18: 0 | I18: 48 | J18: 49 | K18: 0 | L18: =(D18+E18+F18+G18+H18+I18+J18+K18)/8 -> 45.5 | M18: ='LAPORAN RESMI'!L17 -> 93.5 | N18: =(L18*$L$4)+(M18*$M$4) -> 69.5
A19: ='INPUT DAFTAR PESERTA'!A18 -> 15 | B19: ='INPUT DAFTAR PESERTA'!B18 -> 2509056003 | C19: ='INPUT DAFTAR PESERTA'!C18 -> Muhammad Daffa Alifiansyah | D19: 65 | E19: 83 | F19: 79 | G19: 81 | H19: 0 | I19: 26 | J19: 89 | K19: 0 | L19: =(D19+E19+F19+G19+H19+I19+J19+K19)/8 -> 52.875 | M19: ='LAPORAN RESMI'!L18 -> 83.75 | N19: =(L19*$L$4)+(M19*$M$4) -> 68.3125
A20: ='INPUT DAFTAR PESERTA'!A19 -> 16 | B20: ='INPUT DAFTAR PESERTA'!B19 -> 2509056004 | C20: ='INPUT DAFTAR PESERTA'!C19 -> Adya Nur Adzhuriva | G20: 0 | H20: 0 | I20: 5 | K20: 0 | L20: =(D20+E20+F20+G20+H20+I20+J20+K20)/8 -> 0.625 | M20: ='LAPORAN RESMI'!L19 -> 0 | N20: =(L20*$L$4)+(M20*$M$4) -> 0.3125
A21: ='INPUT DAFTAR PESERTA'!A20 -> 17 | B21: ='INPUT DAFTAR PESERTA'!B20 -> 2509056005 | C21: ='INPUT DAFTAR PESERTA'!C20 -> Cheva Fasha Prathama | G21: 0 | H21: 0 | I21: 0 | K21: 0 | L21: =(D21+E21+F21+G21+H21+I21+J21+K21)/8 -> 0 | M21: ='LAPORAN RESMI'!L20 -> 0 | N21: =(L21*$L$4)+(M21*$M$4) -> 0
A22: ='INPUT DAFTAR PESERTA'!A21 -> 18 | B22: ='INPUT DAFTAR PESERTA'!B21 -> 2509056006 | C22: ='INPUT DAFTAR PESERTA'!C21 -> Muhammad Zaki Fadillah | G22: 0 | H22: 0 | I22: 0 | K22: 0 | L22: =(D22+E22+F22+G22+H22+I22+J22+K22)/8 -> 0 | M22: ='LAPORAN RESMI'!L21 -> 0 | N22: =(L22*$L$4)+(M22*$M$4) -> 0
A23: ='INPUT DAFTAR PESERTA'!A22 -> 19 | B23: ='INPUT DAFTAR PESERTA'!B22 -> 2509056007 | C23: ='INPUT DAFTAR PESERTA'!C22 -> Widdyanti Fetrina Sefriany | G23: 0 | H23: 0 | I23: 0 | K23: 0 | L23: =(D23+E23+F23+G23+H23+I23+J23+K23)/8 -> 0 | M23: ='LAPORAN RESMI'!L22 -> 0 | N23: =(L23*$L$4)+(M23*$M$4) -> 0
A24: ='INPUT DAFTAR PESERTA'!A23 -> 20 | B24: ='INPUT DAFTAR PESERTA'!B23 -> 2509056008 | C24: ='INPUT DAFTAR PESERTA'!C23 -> Gita Mufidatuzahrah | D24: 47 | G24: 0 | H24: 0 | I24: 0 | J24: 28 | K24: 0 | L24: =(D24+E24+F24+G24+H24+I24+J24+K24)/8 -> 9.375 | M24: ='LAPORAN RESMI'!L23 -> 0 | N24: =(L24*$L$4)+(M24*$M$4) -> 4.6875
A25: ='INPUT DAFTAR PESERTA'!A24 -> 21 | B25: ='INPUT DAFTAR PESERTA'!B24 -> 2509056009 | C25: ='INPUT DAFTAR PESERTA'!C24 -> Muhammad Hersal Ramadhan | D25: 47 | E25: 50 | F25: 83 | G25: 76 | H25: 77 | I25: 0 | J25: 0 | K25: 0 | L25: =(D25+E25+F25+G25+H25+I25+J25+K25)/8 -> 41.625 | M25: ='LAPORAN RESMI'!L24 -> 89 | N25: =(L25*$L$4)+(M25*$M$4) -> 65.3125
A26: ='INPUT DAFTAR PESERTA'!A25 -> 22 | B26: ='INPUT DAFTAR PESERTA'!B25 -> 2509056010 | C26: ='INPUT DAFTAR PESERTA'!C25 -> Chikal Fattiya Putri | G26: 0 | H26: 28 | I26: 25 | J26: 48 | K26: 0 | L26: =(D26+E26+F26+G26+H26+I26+J26+K26)/8 -> 12.625 | M26: ='LAPORAN RESMI'!L25 -> 0 | N26: =(L26*$L$4)+(M26*$M$4) -> 6.3125
A27: ='INPUT DAFTAR PESERTA'!A26 -> 23 | B27: ='INPUT DAFTAR PESERTA'!B26 -> 2509056011 | C27: ='INPUT DAFTAR PESERTA'!C26 -> Muhammad Daffa Lailitama Sinaga | D27: 75 | E27: 0 | F27: 75 | G27: 95 | H27: 93 | I27: 49 | J27: 87 | K27: 28 | L27: =(D27+E27+F27+G27+H27+I27+J27+K27)/8 -> 62.75 | M27: ='LAPORAN RESMI'!L26 -> 96.75 | N27: =(L27*$L$4)+(M27*$M$4) -> 79.75
A28: ='INPUT DAFTAR PESERTA'!A27 -> 24 | B28: ='INPUT DAFTAR PESERTA'!B27 -> 2509056012 | C28: ='INPUT DAFTAR PESERTA'!C27 -> Sera Ayu Ningsih | D28: 0 | E28: 0 | F28: 0 | G28: 70 | H28: 30 | I28: 31 | J28: 62 | K28: 0 | L28: =(D28+E28+F28+G28+H28+I28+J28+K28)/8 -> 24.125 | M28: ='LAPORAN RESMI'!L27 -> 58.625 | N28: =(L28*$L$4)+(M28*$M$4) -> 41.375
A29: ='INPUT DAFTAR PESERTA'!A28 -> 25 | B29: ='INPUT DAFTAR PESERTA'!B28 -> 2509056013 | C29: ='INPUT DAFTAR PESERTA'!C28 -> Naufal Firdaus Syauqi | D29: 72 | F29: 36 | G29: 66 | H29: 45 | I29: 29 | J29: 62 | K29: 60 | L29: =(D29+E29+F29+G29+H29+I29+J29+K29)/8 -> 46.25 | M29: ='LAPORAN RESMI'!L28 -> 89.875 | N29: =(L29*$L$4)+(M29*$M$4) -> 68.0625
A30: ='INPUT DAFTAR PESERTA'!A29 -> 26 | B30: ='INPUT DAFTAR PESERTA'!B29 -> 2509056014 | C30: ='INPUT DAFTAR PESERTA'!C29 -> Alexander Radja Roben Saragih | D30: 83 | E30: 51 | F30: 98 | G30: 93 | H30: 90 | I30: 93 | J30: 84 | K30: 75 | L30: =(D30+E30+F30+G30+H30+I30+J30+K30)/8 -> 83.375 | M30: ='LAPORAN RESMI'!L29 -> 95.875 | N30: =(L30*$L$4)+(M30*$M$4) -> 89.625
A31: ='INPUT DAFTAR PESERTA'!A30 -> 27 | B31: ='INPUT DAFTAR PESERTA'!B30 -> 2509056015 | C31: ='INPUT DAFTAR PESERTA'!C30 -> Tiara Aqila Azzahra | D31: 48 | E31: 64 | F31: 44 | G31: 82 | H31: 92 | I31: 39 | J31: 74 | K31: 60 | L31: =(D31+E31+F31+G31+H31+I31+J31+K31)/8 -> 62.875 | M31: ='LAPORAN RESMI'!L30 -> 93.625 | N31: =(L31*$L$4)+(M31*$M$4) -> 78.25
A32: ='INPUT DAFTAR PESERTA'!A31 -> 28 | B32: ='INPUT DAFTAR PESERTA'!B31 -> 2509056016 | C32: ='INPUT DAFTAR PESERTA'!C31 -> Muhammad Haikal Islamy Saputra | D32: 0 | E32: 36 | F32: 0 | G32: 71 | H32: 38 | I32: 24 | J32: 74 | K32: 63 | L32: =(D32+E32+F32+G32+H32+I32+J32+K32)/8 -> 38.25 | M32: ='LAPORAN RESMI'!L31 -> 88.625 | N32: =(L32*$L$4)+(M32*$M$4) -> 63.4375
A33: ='INPUT DAFTAR PESERTA'!A32 -> 29 | B33: ='INPUT DAFTAR PESERTA'!B32 -> 2509056017 | C33: ='INPUT DAFTAR PESERTA'!C32 -> Faatihur Rizki | D33: 0 | E33: 0 | F33: 29 | G33: 57 | H33: 50 | I33: 54 | J33: 61 | K33: 57 | L33: =(D33+E33+F33+G33+H33+I33+J33+K33)/8 -> 38.5 | M33: ='LAPORAN RESMI'!L32 -> 94.25 | N33: =(L33*$L$4)+(M33*$M$4) -> 66.375
A34: ='INPUT DAFTAR PESERTA'!A33 -> 30 | B34: ='INPUT DAFTAR PESERTA'!B33 -> 2509056018 | C34: ='INPUT DAFTAR PESERTA'!C33 -> Rashya Annara Salsabilla Tomasoa | D34: 63 | E34: 88 | F34: 85 | G34: 87 | H34: 88 | I34: 44 | J34: 86 | K34: 0 | L34: =(D34+E34+F34+G34+H34+I34+J34+K34)/8 -> 67.625 | M34: ='LAPORAN RESMI'!L33 -> 95.625 | N34: =(L34*$L$4)+(M34*$M$4) -> 81.625
A35: ='INPUT DAFTAR PESERTA'!A34 -> 31 | B35: ='INPUT DAFTAR PESERTA'!B34 -> 2509056019 | C35: ='INPUT DAFTAR PESERTA'!C34 -> Desta Novie Sulfianie | E35: 0 | F35: 43 | G35: 0 | H35: 40 | I35: 30 | K35: 0 | L35: =(D35+E35+F35+G35+H35+I35+J35+K35)/8 -> 14.125 | M35: ='LAPORAN RESMI'!L34 -> 0 | N35: =(L35*$L$4)+(M35*$M$4) -> 7.0625
A36: ='INPUT DAFTAR PESERTA'!A35 -> 32 | B36: ='INPUT DAFTAR PESERTA'!B35 -> 2509056020 | C36: ='INPUT DAFTAR PESERTA'!C35 -> Chandra Ahmad Dwinata | E36: 0 | F36: 30 | G36: 26 | H36: 68 | I36: 5 | J36: 23 | K36: 17 | L36: =(D36+E36+F36+G36+H36+I36+J36+K36)/8 -> 21.125 | M36: ='LAPORAN RESMI'!L35 -> 33.25 | N36: =(L36*$L$4)+(M36*$M$4) -> 27.1875
A37: ='INPUT DAFTAR PESERTA'!A36 -> 33 | B37: ='INPUT DAFTAR PESERTA'!B36 -> 2509056021 | C37: ='INPUT DAFTAR PESERTA'!C36 -> Sopando Imanuel Sipayung | D37: 77 | E37: 94 | F37: 63 | G37: 56 | H37: 75 | I37: 77 | J37: 71 | K37: 0 | L37: =(D37+E37+F37+G37+H37+I37+J37+K37)/8 -> 64.125 | M37: ='LAPORAN RESMI'!L36 -> 92 | N37: =(L37*$L$4)+(M37*$M$4) -> 78.0625
A38: ='INPUT DAFTAR PESERTA'!A37 -> 34 | B38: ='INPUT DAFTAR PESERTA'!B37 -> 2509056022 | C38: ='INPUT DAFTAR PESERTA'!C37 -> Rayhan Winata Prabowo | D38: 0 | E38: 55 | F38: 44 | G38: 81 | H38: 21 | I38: 19 | J38: 45 | K38: 53 | L38: =(D38+E38+F38+G38+H38+I38+J38+K38)/8 -> 39.75 | M38: ='LAPORAN RESMI'!L37 -> 92.125 | N38: =(L38*$L$4)+(M38*$M$4) -> 65.9375
A39: ='INPUT DAFTAR PESERTA'!A38 -> 35 | B39: ='INPUT DAFTAR PESERTA'!B38 -> 2509056023 | C39: ='INPUT DAFTAR PESERTA'!C38 -> Ahmad Din Nejad | E39: 0 | G39: 0 | H39: 0 | I39: 0 | K39: 0 | L39: =(D39+E39+F39+G39+H39+I39+J39+K39)/8 -> 0 | M39: ='LAPORAN RESMI'!L38 -> 0 | N39: =(L39*$L$4)+(M39*$M$4) -> 0
A40: ='INPUT DAFTAR PESERTA'!A39 -> 36 | B40: ='INPUT DAFTAR PESERTA'!B39 -> 2509056024 | C40: ='INPUT DAFTAR PESERTA'!C39 -> Nabil Candra Hartanto | D40: 57 | E40: 0 | F40: 71 | G40: 0 | H40: 0 | I40: 38 | J40: 31 | K40: 0 | L40: =(D40+E40+F40+G40+H40+I40+J40+K40)/8 -> 24.625 | M40: ='LAPORAN RESMI'!L39 -> 88.625 | N40: =(L40*$L$4)+(M40*$M$4) -> 56.625
A41: ='INPUT DAFTAR PESERTA'!A40 -> 37 | B41: ='INPUT DAFTAR PESERTA'!B40 -> 2509056025 | C41: ='INPUT DAFTAR PESERTA'!C40 -> Muhammad Rifqi Ibnu Malik | D41: 37 | G41: 0 | H41: 38 | I41: 0 | J41: 25 | K41: 39 | L41: =(D41+E41+F41+G41+H41+I41+J41+K41)/8 -> 17.375 | M41: ='LAPORAN RESMI'!L40 -> 0 | N41: =(L41*$L$4)+(M41*$M$4) -> 8.6875
...

Sheet KEMAMPUAN PRAKTIKUM
A1: HOME
A3: NO | B3: NIM | C3: Nama | D3: Modul 1 | I3: Modul 2 | N3: Modul 3 | S3: Modul 4 | X3: Modul 5 | AC3: Modul 6 | AH3: Modul 7 | AM3: Modul 8
D4: K1 | E4: K2 | F4: K3 | G4: K4 | H4: Rerata | I4: K1 | J4: K2 | K4: K3 | L4: K4 | M4: Rerata | N4: K1 | O4: K2 | P4: K3 | Q4: K4 | R4: Rerata | S4: K1 | T4: K2 | U4: K3 | V4: K4 | W4: Rerata | X4: K1 | Y4: K2 | Z4: K3 | AA4: K4 | AB4: Rerata | AC4: K1 | AD4: K2 | AE4: K3 | AF4: K4 | AG4: Rerata | AH4: K1 | AI4: K2 | AJ4: K3 | AK4: K4 | AL4: Rerata | AM4: K1 | AN4: K2 | AO4: K3 | AP4: K4 | AQ4: Rerata
D5: 0.1 | E5: 0.2 | F5: 0.2 | G5: 0.5 | H5: 1 | I5: 0.1 | J5: 0.2 | K5: 0.2 | L5: 0.5 | M5: 1 | N5: 0.1 | O5: 0.2 | P5: 0.2 | Q5: 0.5 | R5: 1 | S5: 0.1 | T5: 0.2 | U5: 0.2 | V5: 0.5 | W5: 1 | X5: 0.1 | Y5: 0.2 | Z5: 0.2 | AA5: 0.5 | AB5: 1 | AC5: 0.1 | AD5: 0.2 | AE5: 0.2 | AF5: 0.5 | AG5: 1 | AH5: 0.1 | AI5: 0.2 | AJ5: 0.2 | AK5: 0.5 | AL5: 1 | AM5: 0.1 | AN5: 0.2 | AO5: 0.2 | AP5: 0.5 | AQ5: 1
A6: ='INPUT DAFTAR PESERTA'!A4 -> 1 | B6: ='INPUT DAFTAR PESERTA'!B4 -> 2309056046 | C6: ='INPUT DAFTAR PESERTA'!C4 -> Erwin | D6: 2 | E6: 3 | F6: 3 | G6: 1 | H6: =((D6*$D$5/3)+(E6*$E$5/3)+(F6*$F$5/3)+(G6*$G$5/3))*90 -> 57 | I6: 3 | J6: 3 | K6: 3 | L6: 1 | M6: =((I6*$D$5/3)+(J6*$E$5/3)+(K6*$F$5/3)+(L6*$G$5/3))*90 -> 60 | N6: 2 | O6: 3 | P6: 3 | Q6: 1 | R6: =((N6*$D$5/3)+(O6*$E$5/3)+(P6*$F$5/3)+(Q6*$G$5/3))*90 -> 57 | S6: 2 | T6: 3 | U6: 3 | V6: 1 | W6: =((S6*$D$5/3)+(T6*$E$5/3)+(U6*$F$5/3)+(V6*$G$5/3))*90 -> 57 | X6: 2 | Y6: 3 | Z6: 3 | AA6: 2 | AB6: =((X6*$D$5/3)+(Y6*$E$5/3)+(Z6*$F$5/3)+(AA6*$G$5/3))*90 -> 72 | AC6: 3 | AD6: 2 | AE6: 2 | AF6: 2 | AG6: =((AC6*$D$5/3)+(AD6*$E$5/3)+(AE6*$F$5/3)+(AF6*$G$5/3))*90 -> 63 | AH6: 2 | AI6: 3 | AJ6: 3 | AK6: 1 | AL6: =((AH6*$D$5/3)+(AI6*$E$5/3)+(AJ6*$F$5/3)+(AK6*$G$5/3))*90 -> 57 | AM6: 2 | AN6: 3 | AO6: 3 | AP6: 1 | AQ6: =((AM6*$D$5/3)+(AN6*$E$5/3)+(AO6*$F$5/3)+(AP6*$G$5/3))*90 -> 57
A7: ='INPUT DAFTAR PESERTA'!A5 -> 2 | B7: ='INPUT DAFTAR PESERTA'!B5 -> 2409056015 | C7: ='INPUT DAFTAR PESERTA'!C5 -> Denny Setiawan | H7: =((D7*$D$5/3)+(E7*$E$5/3)+(F7*$F$5/3)+(G7*$G$5/3))*90 -> 0 | I7: 1 | J7: 1 | K7: 1 | L7: 1 | M7: =((I7*$D$5/3)+(J7*$E$5/3)+(K7*$F$5/3)+(L7*$G$5/3))*90 -> 30 | R7: =((N7*$D$5/3)+(O7*$E$5/3)+(P7*$F$5/3)+(Q7*$G$5/3))*90 -> 0 | W7: =((S7*$D$5/3)+(T7*$E$5/3)+(U7*$F$5/3)+(V7*$G$5/3))*90 -> 0 | X7: 1 | Y7: 1 | Z7: 1 | AA7: 1 | AB7: =((X7*$D$5/3)+(Y7*$E$5/3)+(Z7*$F$5/3)+(AA7*$G$5/3))*90 -> 30 | AC7: 3 | AD7: 2 | AE7: 2 | AF7: 2 | AG7: =((AC7*$D$5/3)+(AD7*$E$5/3)+(AE7*$F$5/3)+(AF7*$G$5/3))*90 -> 63 | AL7: =((AH7*$D$5/3)+(AI7*$E$5/3)+(AJ7*$F$5/3)+(AK7*$G$5/3))*90 -> 0 | AQ7: =((AM7*$D$5/3)+(AN7*$E$5/3)+(AO7*$F$5/3)+(AP7*$G$5/3))*90 -> 0
A8: ='INPUT DAFTAR PESERTA'!A6 -> 3 | B8: ='INPUT DAFTAR PESERTA'!B6 -> 2409056031 | C8: ='INPUT DAFTAR PESERTA'!C6 -> Rahmad Oka Aufa Ramadan | H8: =((D8*$D$5/3)+(E8*$E$5/3)+(F8*$F$5/3)+(G8*$G$5/3))*90 -> 0 | I8: 1 | J8: 1 | K8: 1 | L8: 1 | M8: =((I8*$D$5/3)+(J8*$E$5/3)+(K8*$F$5/3)+(L8*$G$5/3))*90 -> 30 | R8: =((N8*$D$5/3)+(O8*$E$5/3)+(P8*$F$5/3)+(Q8*$G$5/3))*90 -> 0 | W8: =((S8*$D$5/3)+(T8*$E$5/3)+(U8*$F$5/3)+(V8*$G$5/3))*90 -> 0 | X8: 1 | Y8: 1 | Z8: 1 | AA8: 1 | AB8: =((X8*$D$5/3)+(Y8*$E$5/3)+(Z8*$F$5/3)+(AA8*$G$5/3))*90 -> 30 | AC8: 3 | AD8: 2 | AE8: 2 | AF8: 2 | AG8: =((AC8*$D$5/3)+(AD8*$E$5/3)+(AE8*$F$5/3)+(AF8*$G$5/3))*90 -> 63 | AL8: =((AH8*$D$5/3)+(AI8*$E$5/3)+(AJ8*$F$5/3)+(AK8*$G$5/3))*90 -> 0 | AQ8: =((AM8*$D$5/3)+(AN8*$E$5/3)+(AO8*$F$5/3)+(AP8*$G$5/3))*90 -> 0
A9: ='INPUT DAFTAR PESERTA'!A7 -> 4 | B9: ='INPUT DAFTAR PESERTA'!B7 -> 2409056032 | C9: ='INPUT DAFTAR PESERTA'!C7 -> Stewa Syaifa Bakhid | H9: =((D9*$D$5/3)+(E9*$E$5/3)+(F9*$F$5/3)+(G9*$G$5/3))*90 -> 0 | I9: 1 | J9: 1 | K9: 1 | L9: 1 | M9: =((I9*$D$5/3)+(J9*$E$5/3)+(K9*$F$5/3)+(L9*$G$5/3))*90 -> 30 | R9: =((N9*$D$5/3)+(O9*$E$5/3)+(P9*$F$5/3)+(Q9*$G$5/3))*90 -> 0 | W9: =((S9*$D$5/3)+(T9*$E$5/3)+(U9*$F$5/3)+(V9*$G$5/3))*90 -> 0 | X9: 1 | Y9: 1 | Z9: 1 | AA9: 1 | AB9: =((X9*$D$5/3)+(Y9*$E$5/3)+(Z9*$F$5/3)+(AA9*$G$5/3))*90 -> 30 | AC9: 3 | AD9: 2 | AE9: 2 | AF9: 2 | AG9: =((AC9*$D$5/3)+(AD9*$E$5/3)+(AE9*$F$5/3)+(AF9*$G$5/3))*90 -> 63 | AL9: =((AH9*$D$5/3)+(AI9*$E$5/3)+(AJ9*$F$5/3)+(AK9*$G$5/3))*90 -> 0 | AQ9: =((AM9*$D$5/3)+(AN9*$E$5/3)+(AO9*$F$5/3)+(AP9*$G$5/3))*90 -> 0
A10: ='INPUT DAFTAR PESERTA'!A8 -> 5 | B10: ='INPUT DAFTAR PESERTA'!B8 -> 2409056033 | C10: ='INPUT DAFTAR PESERTA'!C8 -> Adnan Fadil Annur | D10: 3 | E10: 3 | F10: 3 | G10: 3 | H10: =((D10*$D$5/3)+(E10*$E$5/3)+(F10*$F$5/3)+(G10*$G$5/3))*90 -> 90 | I10: 1 | J10: 1 | K10: 1 | L10: 1 | M10: =((I10*$D$5/3)+(J10*$E$5/3)+(K10*$F$5/3)+(L10*$G$5/3))*90 -> 30 | R10: =((N10*$D$5/3)+(O10*$E$5/3)+(P10*$F$5/3)+(Q10*$G$5/3))*90 -> 0 | W10: =((S10*$D$5/3)+(T10*$E$5/3)+(U10*$F$5/3)+(V10*$G$5/3))*90 -> 0 | X10: 1 | Y10: 1 | Z10: 1 | AA10: 1 | AB10: =((X10*$D$5/3)+(Y10*$E$5/3)+(Z10*$F$5/3)+(AA10*$G$5/3))*90 -> 30 | AC10: 3 | AD10: 2 | AE10: 2 | AF10: 2 | AG10: =((AC10*$D$5/3)+(AD10*$E$5/3)+(AE10*$F$5/3)+(AF10*$G$5/3))*90 -> 63 | AL10: =((AH10*$D$5/3)+(AI10*$E$5/3)+(AJ10*$F$5/3)+(AK10*$G$5/3))*90 -> 0 | AQ10: =((AM10*$D$5/3)+(AN10*$E$5/3)+(AO10*$F$5/3)+(AP10*$G$5/3))*90 -> 0
A11: ='INPUT DAFTAR PESERTA'!A9 -> 6 | B11: ='INPUT DAFTAR PESERTA'!B9 -> 2409056039 | C11: ='INPUT DAFTAR PESERTA'!C9 -> Muhammad Hasbi Ash Shiddieqy | H11: =((D11*$D$5/3)+(E11*$E$5/3)+(F11*$F$5/3)+(G11*$G$5/3))*90 -> 0 | I11: 1 | J11: 1 | K11: 1 | L11: 1 | M11: =((I11*$D$5/3)+(J11*$E$5/3)+(K11*$F$5/3)+(L11*$G$5/3))*90 -> 30 | R11: =((N11*$D$5/3)+(O11*$E$5/3)+(P11*$F$5/3)+(Q11*$G$5/3))*90 -> 0 | W11: =((S11*$D$5/3)+(T11*$E$5/3)+(U11*$F$5/3)+(V11*$G$5/3))*90 -> 0 | X11: 1 | Y11: 1 | Z11: 1 | AA11: 1 | AB11: =((X11*$D$5/3)+(Y11*$E$5/3)+(Z11*$F$5/3)+(AA11*$G$5/3))*90 -> 30 | AC11: 3 | AD11: 2 | AE11: 2 | AF11: 2 | AG11: =((AC11*$D$5/3)+(AD11*$E$5/3)+(AE11*$F$5/3)+(AF11*$G$5/3))*90 -> 63 | AL11: =((AH11*$D$5/3)+(AI11*$E$5/3)+(AJ11*$F$5/3)+(AK11*$G$5/3))*90 -> 0 | AQ11: =((AM11*$D$5/3)+(AN11*$E$5/3)+(AO11*$F$5/3)+(AP11*$G$5/3))*90 -> 0
A12: ='INPUT DAFTAR PESERTA'!A10 -> 7 | B12: ='INPUT DAFTAR PESERTA'!B10 -> 2409056044 | C12: ='INPUT DAFTAR PESERTA'!C10 -> Siti Aisyah Hasanah | H12: =((D12*$D$5/3)+(E12*$E$5/3)+(F12*$F$5/3)+(G12*$G$5/3))*90 -> 0 | I12: 1 | J12: 1 | K12: 1 | L12: 1 | M12: =((I12*$D$5/3)+(J12*$E$5/3)+(K12*$F$5/3)+(L12*$G$5/3))*90 -> 30 | R12: =((N12*$D$5/3)+(O12*$E$5/3)+(P12*$F$5/3)+(Q12*$G$5/3))*90 -> 0 | W12: =((S12*$D$5/3)+(T12*$E$5/3)+(U12*$F$5/3)+(V12*$G$5/3))*90 -> 0 | X12: 1 | Y12: 1 | Z12: 1 | AA12: 1 | AB12: =((X12*$D$5/3)+(Y12*$E$5/3)+(Z12*$F$5/3)+(AA12*$G$5/3))*90 -> 30 | AC12: 3 | AD12: 2 | AE12: 2 | AF12: 2 | AG12: =((AC12*$D$5/3)+(AD12*$E$5/3)+(AE12*$F$5/3)+(AF12*$G$5/3))*90 -> 63 | AL12: =((AH12*$D$5/3)+(AI12*$E$5/3)+(AJ12*$F$5/3)+(AK12*$G$5/3))*90 -> 0 | AQ12: =((AM12*$D$5/3)+(AN12*$E$5/3)+(AO12*$F$5/3)+(AP12*$G$5/3))*90 -> 0
A13: ='INPUT DAFTAR PESERTA'!A11 -> 8 | B13: ='INPUT DAFTAR PESERTA'!B11 -> 2409056047 | C13: ='INPUT DAFTAR PESERTA'!C11 -> D’arch Hweng Junior | H13: =((D13*$D$5/3)+(E13*$E$5/3)+(F13*$F$5/3)+(G13*$G$5/3))*90 -> 0 | I13: 1 | J13: 1 | K13: 1 | L13: 1 | M13: =((I13*$D$5/3)+(J13*$E$5/3)+(K13*$F$5/3)+(L13*$G$5/3))*90 -> 30 | R13: =((N13*$D$5/3)+(O13*$E$5/3)+(P13*$F$5/3)+(Q13*$G$5/3))*90 -> 0 | W13: =((S13*$D$5/3)+(T13*$E$5/3)+(U13*$F$5/3)+(V13*$G$5/3))*90 -> 0 | X13: 1 | Y13: 1 | Z13: 1 | AA13: 1 | AB13: =((X13*$D$5/3)+(Y13*$E$5/3)+(Z13*$F$5/3)+(AA13*$G$5/3))*90 -> 30 | AC13: 3 | AD13: 2 | AE13: 2 | AF13: 2 | AG13: =((AC13*$D$5/3)+(AD13*$E$5/3)+(AE13*$F$5/3)+(AF13*$G$5/3))*90 -> 63 | AL13: =((AH13*$D$5/3)+(AI13*$E$5/3)+(AJ13*$F$5/3)+(AK13*$G$5/3))*90 -> 0 | AQ13: =((AM13*$D$5/3)+(AN13*$E$5/3)+(AO13*$F$5/3)+(AP13*$G$5/3))*90 -> 0
A14: ='INPUT DAFTAR PESERTA'!A12 -> 9 | B14: ='INPUT DAFTAR PESERTA'!B12 -> 2409056052 | C14: ='INPUT DAFTAR PESERTA'!C12 -> Andi Syaifullah Al Maslulil Agri | H14: =((D14*$D$5/3)+(E14*$E$5/3)+(F14*$F$5/3)+(G14*$G$5/3))*90 -> 0 | I14: 1 | J14: 1 | K14: 1 | L14: 1 | M14: =((I14*$D$5/3)+(J14*$E$5/3)+(K14*$F$5/3)+(L14*$G$5/3))*90 -> 30 | R14: =((N14*$D$5/3)+(O14*$E$5/3)+(P14*$F$5/3)+(Q14*$G$5/3))*90 -> 0 | W14: =((S14*$D$5/3)+(T14*$E$5/3)+(U14*$F$5/3)+(V14*$G$5/3))*90 -> 0 | X14: 1 | Y14: 1 | Z14: 1 | AA14: 1 | AB14: =((X14*$D$5/3)+(Y14*$E$5/3)+(Z14*$F$5/3)+(AA14*$G$5/3))*90 -> 30 | AC14: 3 | AD14: 2 | AE14: 2 | AF14: 2 | AG14: =((AC14*$D$5/3)+(AD14*$E$5/3)+(AE14*$F$5/3)+(AF14*$G$5/3))*90 -> 63 | AL14: =((AH14*$D$5/3)+(AI14*$E$5/3)+(AJ14*$F$5/3)+(AK14*$G$5/3))*90 -> 0 | AQ14: =((AM14*$D$5/3)+(AN14*$E$5/3)+(AO14*$F$5/3)+(AP14*$G$5/3))*90 -> 0
A15: ='INPUT DAFTAR PESERTA'!A13 -> 10 | B15: ='INPUT DAFTAR PESERTA'!B13 -> 2409056058 | C15: ='INPUT DAFTAR PESERTA'!C13 -> Andre Pratama | H15: =((D15*$D$5/3)+(E15*$E$5/3)+(F15*$F$5/3)+(G15*$G$5/3))*90 -> 0 | I15: 1 | J15: 1 | K15: 1 | L15: 1 | M15: =((I15*$D$5/3)+(J15*$E$5/3)+(K15*$F$5/3)+(L15*$G$5/3))*90 -> 30 | R15: =((N15*$D$5/3)+(O15*$E$5/3)+(P15*$F$5/3)+(Q15*$G$5/3))*90 -> 0 | W15: =((S15*$D$5/3)+(T15*$E$5/3)+(U15*$F$5/3)+(V15*$G$5/3))*90 -> 0 | X15: 1 | Y15: 1 | Z15: 1 | AA15: 1 | AB15: =((X15*$D$5/3)+(Y15*$E$5/3)+(Z15*$F$5/3)+(AA15*$G$5/3))*90 -> 30 | AC15: 3 | AD15: 2 | AE15: 2 | AF15: 2 | AG15: =((AC15*$D$5/3)+(AD15*$E$5/3)+(AE15*$F$5/3)+(AF15*$G$5/3))*90 -> 63 | AL15: =((AH15*$D$5/3)+(AI15*$E$5/3)+(AJ15*$F$5/3)+(AK15*$G$5/3))*90 -> 0 | AQ15: =((AM15*$D$5/3)+(AN15*$E$5/3)+(AO15*$F$5/3)+(AP15*$G$5/3))*90 -> 0
A16: ='INPUT DAFTAR PESERTA'!A14 -> 11 | B16: ='INPUT DAFTAR PESERTA'!B14 -> 2409056067 | C16: ='INPUT DAFTAR PESERTA'!C14 -> Andi Afif Najib Abdillah | H16: =((D16*$D$5/3)+(E16*$E$5/3)+(F16*$F$5/3)+(G16*$G$5/3))*90 -> 0 | I16: 1 | J16: 1 | K16: 1 | L16: 1 | M16: =((I16*$D$5/3)+(J16*$E$5/3)+(K16*$F$5/3)+(L16*$G$5/3))*90 -> 30 | R16: =((N16*$D$5/3)+(O16*$E$5/3)+(P16*$F$5/3)+(Q16*$G$5/3))*90 -> 0 | W16: =((S16*$D$5/3)+(T16*$E$5/3)+(U16*$F$5/3)+(V16*$G$5/3))*90 -> 0 | X16: 1 | Y16: 1 | Z16: 1 | AA16: 1 | AB16: =((X16*$D$5/3)+(Y16*$E$5/3)+(Z16*$F$5/3)+(AA16*$G$5/3))*90 -> 30 | AC16: 3 | AD16: 2 | AE16: 2 | AF16: 2 | AG16: =((AC16*$D$5/3)+(AD16*$E$5/3)+(AE16*$F$5/3)+(AF16*$G$5/3))*90 -> 63 | AL16: =((AH16*$D$5/3)+(AI16*$E$5/3)+(AJ16*$F$5/3)+(AK16*$G$5/3))*90 -> 0 | AQ16: =((AM16*$D$5/3)+(AN16*$E$5/3)+(AO16*$F$5/3)+(AP16*$G$5/3))*90 -> 0
A17: ='INPUT DAFTAR PESERTA'!A15 -> 12 | B17: ='INPUT DAFTAR PESERTA'!B15 -> 2409056068 | C17: ='INPUT DAFTAR PESERTA'!C15 -> Christianus Gonzaga | H17: =((D17*$D$5/3)+(E17*$E$5/3)+(F17*$F$5/3)+(G17*$G$5/3))*90 -> 0 | I17: 1 | J17: 1 | K17: 1 | L17: 1 | M17: =((I17*$D$5/3)+(J17*$E$5/3)+(K17*$F$5/3)+(L17*$G$5/3))*90 -> 30 | R17: =((N17*$D$5/3)+(O17*$E$5/3)+(P17*$F$5/3)+(Q17*$G$5/3))*90 -> 0 | W17: =((S17*$D$5/3)+(T17*$E$5/3)+(U17*$F$5/3)+(V17*$G$5/3))*90 -> 0 | X17: 1 | Y17: 1 | Z17: 1 | AA17: 1 | AB17: =((X17*$D$5/3)+(Y17*$E$5/3)+(Z17*$F$5/3)+(AA17*$G$5/3))*90 -> 30 | AC17: 3 | AD17: 2 | AE17: 2 | AF17: 2 | AG17: =((AC17*$D$5/3)+(AD17*$E$5/3)+(AE17*$F$5/3)+(AF17*$G$5/3))*90 -> 63 | AL17: =((AH17*$D$5/3)+(AI17*$E$5/3)+(AJ17*$F$5/3)+(AK17*$G$5/3))*90 -> 0 | AQ17: =((AM17*$D$5/3)+(AN17*$E$5/3)+(AO17*$F$5/3)+(AP17*$G$5/3))*90 -> 0
A18: ='INPUT DAFTAR PESERTA'!A16 -> 13 | B18: ='INPUT DAFTAR PESERTA'!B16 -> 2509056001 | C18: ='INPUT DAFTAR PESERTA'!C16 -> Mutiara Suci Rahmadani | D18: 3 | E18: 3 | F18: 3 | G18: 2 | H18: =((D18*$D$5/3)+(E18*$E$5/3)+(F18*$F$5/3)+(G18*$G$5/3))*90 -> 75 | I18: 3 | J18: 3 | K18: 3 | L18: 1 | M18: =((I18*$D$5/3)+(J18*$E$5/3)+(K18*$F$5/3)+(L18*$G$5/3))*90 -> 60 | N18: 3 | O18: 3 | P18: 3 | Q18: 3 | R18: =((N18*$D$5/3)+(O18*$E$5/3)+(P18*$F$5/3)+(Q18*$G$5/3))*90 -> 90 | S18: 3 | T18: 3 | U18: 3 | V18: 3 | W18: =((S18*$D$5/3)+(T18*$E$5/3)+(U18*$F$5/3)+(V18*$G$5/3))*90 -> 90 | X18: 2 | Y18: 3 | Z18: 3 | AA18: 1 | AB18: =((X18*$D$5/3)+(Y18*$E$5/3)+(Z18*$F$5/3)+(AA18*$G$5/3))*90 -> 57 | AC18: 3 | AD18: 3 | AE18: 3 | AF18: 2 | AG18: =((AC18*$D$5/3)+(AD18*$E$5/3)+(AE18*$F$5/3)+(AF18*$G$5/3))*90 -> 75 | AH18: 2 | AI18: 3 | AJ18: 3 | AK18: 3 | AL18: =((AH18*$D$5/3)+(AI18*$E$5/3)+(AJ18*$F$5/3)+(AK18*$G$5/3))*90 -> 87 | AM18: 3 | AN18: 3 | AO18: 3 | AP18: 3 | AQ18: =((AM18*$D$5/3)+(AN18*$E$5/3)+(AO18*$F$5/3)+(AP18*$G$5/3))*90 -> 90
A19: ='INPUT DAFTAR PESERTA'!A17 -> 14 | B19: ='INPUT DAFTAR PESERTA'!B17 -> 2509056002 | C19: ='INPUT DAFTAR PESERTA'!C17 -> Adhwa Ghinna Febrianty | D19: 3 | E19: 3 | F19: 3 | G19: 2 | H19: =((D19*$D$5/3)+(E19*$E$5/3)+(F19*$F$5/3)+(G19*$G$5/3))*90 -> 75 | I19: 3 | J19: 3 | K19: 3 | L19: 1 | M19: =((I19*$D$5/3)+(J19*$E$5/3)+(K19*$F$5/3)+(L19*$G$5/3))*90 -> 60 | N19: 3 | O19: 3 | P19: 3 | Q19: 3 | R19: =((N19*$D$5/3)+(O19*$E$5/3)+(P19*$F$5/3)+(Q19*$G$5/3))*90 -> 90 | S19: 3 | T19: 3 | U19: 3 | V19: 2 | W19: =((S19*$D$5/3)+(T19*$E$5/3)+(U19*$F$5/3)+(V19*$G$5/3))*90 -> 75 | X19: 2 | Y19: 3 | Z19: 3 | AA19: 1 | AB19: =((X19*$D$5/3)+(Y19*$E$5/3)+(Z19*$F$5/3)+(AA19*$G$5/3))*90 -> 57 | AC19: 3 | AD19: 3 | AE19: 3 | AF19: 2 | AG19: =((AC19*$D$5/3)+(AD19*$E$5/3)+(AE19*$F$5/3)+(AF19*$G$5/3))*90 -> 75 | AH19: 2 | AI19: 3 | AJ19: 3 | AK19: 1 | AL19: =((AH19*$D$5/3)+(AI19*$E$5/3)+(AJ19*$F$5/3)+(AK19*$G$5/3))*90 -> 57 | AM19: 3 | AN19: 3 | AO19: 3 | AP19: 1 | AQ19: =((AM19*$D$5/3)+(AN19*$E$5/3)+(AO19*$F$5/3)+(AP19*$G$5/3))*90 -> 60
A20: ='INPUT DAFTAR PESERTA'!A18 -> 15 | B20: ='INPUT DAFTAR PESERTA'!B18 -> 2509056003 | C20: ='INPUT DAFTAR PESERTA'!C18 -> Muhammad Daffa Alifiansyah | D20: 3 | E20: 3 | F20: 3 | G20: 2 | H20: =((D20*$D$5/3)+(E20*$E$5/3)+(F20*$F$5/3)+(G20*$G$5/3))*90 -> 75 | I20: 3 | J20: 3 | K20: 3 | L20: 3 | M20: =((I20*$D$5/3)+(J20*$E$5/3)+(K20*$F$5/3)+(L20*$G$5/3))*90 -> 90 | N20: 3 | O20: 3 | P20: 3 | Q20: 3 | R20: =((N20*$D$5/3)+(O20*$E$5/3)+(P20*$F$5/3)+(Q20*$G$5/3))*90 -> 90 | S20: 3 | T20: 3 | U20: 3 | V20: 3 | W20: =((S20*$D$5/3)+(T20*$E$5/3)+(U20*$F$5/3)+(V20*$G$5/3))*90 -> 90 | X20: 1 | Y20: 1 | Z20: 1 | AA20: 1 | AB20: =((X20*$D$5/3)+(Y20*$E$5/3)+(Z20*$F$5/3)+(AA20*$G$5/3))*90 -> 30 | AC20: 3 | AD20: 3 | AE20: 3 | AF20: 2 | AG20: =((AC20*$D$5/3)+(AD20*$E$5/3)+(AE20*$F$5/3)+(AF20*$G$5/3))*90 -> 75 | AH20: 2 | AI20: 3 | AJ20: 3 | AK20: 3 | AL20: =((AH20*$D$5/3)+(AI20*$E$5/3)+(AJ20*$F$5/3)+(AK20*$G$5/3))*90 -> 87 | AM20: 3 | AN20: 3 | AO20: 3 | AP20: 1 | AQ20: =((AM20*$D$5/3)+(AN20*$E$5/3)+(AO20*$F$5/3)+(AP20*$G$5/3))*90 -> 60
A21: ='INPUT DAFTAR PESERTA'!A19 -> 16 | B21: ='INPUT DAFTAR PESERTA'!B19 -> 2509056004 | C21: ='INPUT DAFTAR PESERTA'!C19 -> Adya Nur Adzhuriva | H21: =((D21*$D$5/3)+(E21*$E$5/3)+(F21*$F$5/3)+(G21*$G$5/3))*90 -> 0 | M21: =((I21*$D$5/3)+(J21*$E$5/3)+(K21*$F$5/3)+(L21*$G$5/3))*90 -> 0 | R21: =((N21*$D$5/3)+(O21*$E$5/3)+(P21*$F$5/3)+(Q21*$G$5/3))*90 -> 0 | W21: =((S21*$D$5/3)+(T21*$E$5/3)+(U21*$F$5/3)+(V21*$G$5/3))*90 -> 0 | X21: 1 | Y21: 1 | Z21: 1 | AA21: 1 | AB21: =((X21*$D$5/3)+(Y21*$E$5/3)+(Z21*$F$5/3)+(AA21*$G$5/3))*90 -> 30 | AC21: 3 | AD21: 3 | AE21: 3 | AF21: 2 | AG21: =((AC21*$D$5/3)+(AD21*$E$5/3)+(AE21*$F$5/3)+(AF21*$G$5/3))*90 -> 75 | AL21: =((AH21*$D$5/3)+(AI21*$E$5/3)+(AJ21*$F$5/3)+(AK21*$G$5/3))*90 -> 0 | AQ21: =((AM21*$D$5/3)+(AN21*$E$5/3)+(AO21*$F$5/3)+(AP21*$G$5/3))*90 -> 0
A22: ='INPUT DAFTAR PESERTA'!A20 -> 17 | B22: ='INPUT DAFTAR PESERTA'!B20 -> 2509056005 | C22: ='INPUT DAFTAR PESERTA'!C20 -> Cheva Fasha Prathama | H22: =((D22*$D$5/3)+(E22*$E$5/3)+(F22*$F$5/3)+(G22*$G$5/3))*90 -> 0 | M22: =((I22*$D$5/3)+(J22*$E$5/3)+(K22*$F$5/3)+(L22*$G$5/3))*90 -> 0 | R22: =((N22*$D$5/3)+(O22*$E$5/3)+(P22*$F$5/3)+(Q22*$G$5/3))*90 -> 0 | W22: =((S22*$D$5/3)+(T22*$E$5/3)+(U22*$F$5/3)+(V22*$G$5/3))*90 -> 0 | X22: 1 | Y22: 1 | Z22: 1 | AA22: 1 | AB22: =((X22*$D$5/3)+(Y22*$E$5/3)+(Z22*$F$5/3)+(AA22*$G$5/3))*90 -> 30 | AG22: =((AC22*$D$5/3)+(AD22*$E$5/3)+(AE22*$F$5/3)+(AF22*$G$5/3))*90 -> 0 | AL22: =((AH22*$D$5/3)+(AI22*$E$5/3)+(AJ22*$F$5/3)+(AK22*$G$5/3))*90 -> 0 | AQ22: =((AM22*$D$5/3)+(AN22*$E$5/3)+(AO22*$F$5/3)+(AP22*$G$5/3))*90 -> 0
A23: ='INPUT DAFTAR PESERTA'!A21 -> 18 | B23: ='INPUT DAFTAR PESERTA'!B21 -> 2509056006 | C23: ='INPUT DAFTAR PESERTA'!C21 -> Muhammad Zaki Fadillah | H23: =((D23*$D$5/3)+(E23*$E$5/3)+(F23*$F$5/3)+(G23*$G$5/3))*90 -> 0 | M23: =((I23*$D$5/3)+(J23*$E$5/3)+(K23*$F$5/3)+(L23*$G$5/3))*90 -> 0 | R23: =((N23*$D$5/3)+(O23*$E$5/3)+(P23*$F$5/3)+(Q23*$G$5/3))*90 -> 0 | W23: =((S23*$D$5/3)+(T23*$E$5/3)+(U23*$F$5/3)+(V23*$G$5/3))*90 -> 0 | X23: 1 | Y23: 1 | Z23: 1 | AA23: 1 | AB23: =((X23*$D$5/3)+(Y23*$E$5/3)+(Z23*$F$5/3)+(AA23*$G$5/3))*90 -> 30 | AG23: =((AC23*$D$5/3)+(AD23*$E$5/3)+(AE23*$F$5/3)+(AF23*$G$5/3))*90 -> 0 | AL23: =((AH23*$D$5/3)+(AI23*$E$5/3)+(AJ23*$F$5/3)+(AK23*$G$5/3))*90 -> 0 | AQ23: =((AM23*$D$5/3)+(AN23*$E$5/3)+(AO23*$F$5/3)+(AP23*$G$5/3))*90 -> 0
A24: ='INPUT DAFTAR PESERTA'!A22 -> 19 | B24: ='INPUT DAFTAR PESERTA'!B22 -> 2509056007 | C24: ='INPUT DAFTAR PESERTA'!C22 -> Widdyanti Fetrina Sefriany | H24: =((D24*$D$5/3)+(E24*$E$5/3)+(F24*$F$5/3)+(G24*$G$5/3))*90 -> 0 | M24: =((I24*$D$5/3)+(J24*$E$5/3)+(K24*$F$5/3)+(L24*$G$5/3))*90 -> 0 | R24: =((N24*$D$5/3)+(O24*$E$5/3)+(P24*$F$5/3)+(Q24*$G$5/3))*90 -> 0 | W24: =((S24*$D$5/3)+(T24*$E$5/3)+(U24*$F$5/3)+(V24*$G$5/3))*90 -> 0 | X24: 1 | Y24: 1 | Z24: 1 | AA24: 1 | AB24: =((X24*$D$5/3)+(Y24*$E$5/3)+(Z24*$F$5/3)+(AA24*$G$5/3))*90 -> 30 | AG24: =((AC24*$D$5/3)+(AD24*$E$5/3)+(AE24*$F$5/3)+(AF24*$G$5/3))*90 -> 0 | AL24: =((AH24*$D$5/3)+(AI24*$E$5/3)+(AJ24*$F$5/3)+(AK24*$G$5/3))*90 -> 0 | AQ24: =((AM24*$D$5/3)+(AN24*$E$5/3)+(AO24*$F$5/3)+(AP24*$G$5/3))*90 -> 0
A25: ='INPUT DAFTAR PESERTA'!A23 -> 20 | B25: ='INPUT DAFTAR PESERTA'!B23 -> 2509056008 | C25: ='INPUT DAFTAR PESERTA'!C23 -> Gita Mufidatuzahrah | D25: 3 | E25: 3 | F25: 3 | G25: 1 | H25: =((D25*$D$5/3)+(E25*$E$5/3)+(F25*$F$5/3)+(G25*$G$5/3))*90 -> 60 | M25: =((I25*$D$5/3)+(J25*$E$5/3)+(K25*$F$5/3)+(L25*$G$5/3))*90 -> 0 | R25: =((N25*$D$5/3)+(O25*$E$5/3)+(P25*$F$5/3)+(Q25*$G$5/3))*90 -> 0 | W25: =((S25*$D$5/3)+(T25*$E$5/3)+(U25*$F$5/3)+(V25*$G$5/3))*90 -> 0 | X25: 1 | Y25: 1 | Z25: 1 | AA25: 1 | AB25: =((X25*$D$5/3)+(Y25*$E$5/3)+(Z25*$F$5/3)+(AA25*$G$5/3))*90 -> 30 | AG25: =((AC25*$D$5/3)+(AD25*$E$5/3)+(AE25*$F$5/3)+(AF25*$G$5/3))*90 -> 0 | AH25: 2 | AI25: 3 | AJ25: 3 | AK25: 1 | AL25: =((AH25*$D$5/3)+(AI25*$E$5/3)+(AJ25*$F$5/3)+(AK25*$G$5/3))*90 -> 57 | AQ25: =((AM25*$D$5/3)+(AN25*$E$5/3)+(AO25*$F$5/3)+(AP25*$G$5/3))*90 -> 0
A26: ='INPUT DAFTAR PESERTA'!A24 -> 21 | B26: ='INPUT DAFTAR PESERTA'!B24 -> 2509056009 | C26: ='INPUT DAFTAR PESERTA'!C24 -> Muhammad Hersal Ramadhan | D26: 2 | E26: 3 | F26: 2 | G26: 2 | H26: =((D26*$D$5/3)+(E26*$E$5/3)+(F26*$F$5/3)+(G26*$G$5/3))*90 -> 66 | I26: 3 | J26: 3 | K26: 3 | L26: 1 | M26: =((I26*$D$5/3)+(J26*$E$5/3)+(K26*$F$5/3)+(L26*$G$5/3))*90 -> 60 | N26: 3 | O26: 3 | P26: 3 | Q26: 3 | R26: =((N26*$D$5/3)+(O26*$E$5/3)+(P26*$F$5/3)+(Q26*$G$5/3))*90 -> 90 | S26: 2 | T26: 3 | U26: 3 | V26: 3 | W26: =((S26*$D$5/3)+(T26*$E$5/3)+(U26*$F$5/3)+(V26*$G$5/3))*90 -> 87 | X26: 2 | Y26: 2 | Z26: 2 | AA26: 3 | AB26: =((X26*$D$5/3)+(Y26*$E$5/3)+(Z26*$F$5/3)+(AA26*$G$5/3))*90 -> 75 | AC26: 3 | AD26: 2 | AE26: 3 | AF26: 2 | AG26: =((AC26*$D$5/3)+(AD26*$E$5/3)+(AE26*$F$5/3)+(AF26*$G$5/3))*90 -> 69 | AH26: 2 | AI26: 3 | AJ26: 3 | AK26: 1 | AL26: =((AH26*$D$5/3)+(AI26*$E$5/3)+(AJ26*$F$5/3)+(AK26*$G$5/3))*90 -> 57 | AM26: 3 | AN26: 3 | AO26: 3 | AP26: 1 | AQ26: =((AM26*$D$5/3)+(AN26*$E$5/3)+(AO26*$F$5/3)+(AP26*$G$5/3))*90 -> 60
A27: ='INPUT DAFTAR PESERTA'!A25 -> 22 | B27: ='INPUT DAFTAR PESERTA'!B25 -> 2509056010 | C27: ='INPUT DAFTAR PESERTA'!C25 -> Chikal Fattiya Putri | H27: =((D27*$D$5/3)+(E27*$E$5/3)+(F27*$F$5/3)+(G27*$G$5/3))*90 -> 0 | M27: =((I27*$D$5/3)+(J27*$E$5/3)+(K27*$F$5/3)+(L27*$G$5/3))*90 -> 0 | R27: =((N27*$D$5/3)+(O27*$E$5/3)+(P27*$F$5/3)+(Q27*$G$5/3))*90 -> 0 | W27: =((S27*$D$5/3)+(T27*$E$5/3)+(U27*$F$5/3)+(V27*$G$5/3))*90 -> 0 | X27: 3 | Y27: 3 | Z27: 3 | AA27: 1 | AB27: =((X27*$D$5/3)+(Y27*$E$5/3)+(Z27*$F$5/3)+(AA27*$G$5/3))*90 -> 60 | AC27: 3 | AD27: 2 | AE27: 3 | AF27: 2 | AG27: =((AC27*$D$5/3)+(AD27*$E$5/3)+(AE27*$F$5/3)+(AF27*$G$5/3))*90 -> 69 | AH27: 2 | AI27: 3 | AJ27: 3 | AK27: 1 | AL27: =((AH27*$D$5/3)+(AI27*$E$5/3)+(AJ27*$F$5/3)+(AK27*$G$5/3))*90 -> 57 | AQ27: =((AM27*$D$5/3)+(AN27*$E$5/3)+(AO27*$F$5/3)+(AP27*$G$5/3))*90 -> 0
A28: ='INPUT DAFTAR PESERTA'!A26 -> 23 | B28: ='INPUT DAFTAR PESERTA'!B26 -> 2509056011 | C28: ='INPUT DAFTAR PESERTA'!C26 -> Muhammad Daffa Lailitama Sinaga | D28: 3 | E28: 3 | F28: 3 | G28: 2 | H28: =((D28*$D$5/3)+(E28*$E$5/3)+(F28*$F$5/3)+(G28*$G$5/3))*90 -> 75 | I28: 3 | J28: 3 | K28: 3 | L28: 1 | M28: =((I28*$D$5/3)+(J28*$E$5/3)+(K28*$F$5/3)+(L28*$G$5/3))*90 -> 60 | N28: 2 | O28: 3 | P28: 3 | Q28: 3 | R28: =((N28*$D$5/3)+(O28*$E$5/3)+(P28*$F$5/3)+(Q28*$G$5/3))*90 -> 87 | S28: 2 | T28: 3 | U28: 3 | V28: 3 | W28: =((S28*$D$5/3)+(T28*$E$5/3)+(U28*$F$5/3)+(V28*$G$5/3))*90 -> 87 | X28: 3 | Y28: 3 | Z28: 3 | AA28: 3 | AB28: =((X28*$D$5/3)+(Y28*$E$5/3)+(Z28*$F$5/3)+(AA28*$G$5/3))*90 -> 90 | AC28: 3 | AD28: 2 | AE28: 3 | AF28: 2 | AG28: =((AC28*$D$5/3)+(AD28*$E$5/3)+(AE28*$F$5/3)+(AF28*$G$5/3))*90 -> 69 | AH28: 2 | AI28: 3 | AJ28: 3 | AK28: 3 | AL28: =((AH28*$D$5/3)+(AI28*$E$5/3)+(AJ28*$F$5/3)+(AK28*$G$5/3))*90 -> 87 | AM28: 3 | AN28: 3 | AO28: 3 | AP28: 1 | AQ28: =((AM28*$D$5/3)+(AN28*$E$5/3)+(AO28*$F$5/3)+(AP28*$G$5/3))*90 -> 60
A29: ='INPUT DAFTAR PESERTA'!A27 -> 24 | B29: ='INPUT DAFTAR PESERTA'!B27 -> 2509056012 | C29: ='INPUT DAFTAR PESERTA'!C27 -> Sera Ayu Ningsih | D29: 3 | E29: 3 | F29: 3 | G29: 1 | H29: =((D29*$D$5/3)+(E29*$E$5/3)+(F29*$F$5/3)+(G29*$G$5/3))*90 -> 60 | I29: 3 | J29: 3 | K29: 3 | L29: 1 | M29: =((I29*$D$5/3)+(J29*$E$5/3)+(K29*$F$5/3)+(L29*$G$5/3))*90 -> 60 | N29: 2 | O29: 3 | P29: 3 | Q29: 1 | R29: =((N29*$D$5/3)+(O29*$E$5/3)+(P29*$F$5/3)+(Q29*$G$5/3))*90 -> 57 | S29: 2 | T29: 3 | U29: 3 | V29: 3 | W29: =((S29*$D$5/3)+(T29*$E$5/3)+(U29*$F$5/3)+(V29*$G$5/3))*90 -> 87 | X29: 3 | Y29: 3 | Z29: 3 | AA29: 1 | AB29: =((X29*$D$5/3)+(Y29*$E$5/3)+(Z29*$F$5/3)+(AA29*$G$5/3))*90 -> 60 | AC29: 3 | AD29: 2 | AE29: 3 | AF29: 2 | AG29: =((AC29*$D$5/3)+(AD29*$E$5/3)+(AE29*$F$5/3)+(AF29*$G$5/3))*90 -> 69 | AH29: 2 | AI29: 3 | AJ29: 3 | AK29: 2 | AL29: =((AH29*$D$5/3)+(AI29*$E$5/3)+(AJ29*$F$5/3)+(AK29*$G$5/3))*90 -> 72 | AM29: 3 | AN29: 3 | AO29: 3 | AP29: 1 | AQ29: =((AM29*$D$5/3)+(AN29*$E$5/3)+(AO29*$F$5/3)+(AP29*$G$5/3))*90 -> 60
A30: ='INPUT DAFTAR PESERTA'!A28 -> 25 | B30: ='INPUT DAFTAR PESERTA'!B28 -> 2509056013 | C30: ='INPUT DAFTAR PESERTA'!C28 -> Naufal Firdaus Syauqi | D30: 3 | E30: 3 | F30: 3 | G30: 2 | H30: =((D30*$D$5/3)+(E30*$E$5/3)+(F30*$F$5/3)+(G30*$G$5/3))*90 -> 75 | M30: =((I30*$D$5/3)+(J30*$E$5/3)+(K30*$F$5/3)+(L30*$G$5/3))*90 -> 0 | N30: 2 | O30: 3 | P30: 3 | Q30: 1 | R30: =((N30*$D$5/3)+(O30*$E$5/3)+(P30*$F$5/3)+(Q30*$G$5/3))*90 -> 57 | S30: 2 | T30: 3 | U30: 3 | V30: 2 | W30: =((S30*$D$5/3)+(T30*$E$5/3)+(U30*$F$5/3)+(V30*$G$5/3))*90 -> 72 | X30: 3 | Y30: 3 | Z30: 3 | AA30: 1 | AB30: =((X30*$D$5/3)+(Y30*$E$5/3)+(Z30*$F$5/3)+(AA30*$G$5/3))*90 -> 60 | AC30: 3 | AD30: 2 | AE30: 2 | AF30: 2 | AG30: =((AC30*$D$5/3)+(AD30*$E$5/3)+(AE30*$F$5/3)+(AF30*$G$5/3))*90 -> 63 | AH30: 2 | AI30: 3 | AJ30: 3 | AK30: 2 | AL30: =((AH30*$D$5/3)+(AI30*$E$5/3)+(AJ30*$F$5/3)+(AK30*$G$5/3))*90 -> 72 | AM30: 3 | AN30: 3 | AO30: 3 | AP30: 2 | AQ30: =((AM30*$D$5/3)+(AN30*$E$5/3)+(AO30*$F$5/3)+(AP30*$G$5/3))*90 -> 75
A31: ='INPUT DAFTAR PESERTA'!A29 -> 26 | B31: ='INPUT DAFTAR PESERTA'!B29 -> 2509056014 | C31: ='INPUT DAFTAR PESERTA'!C29 -> Alexander Radja Roben Saragih | D31: 3 | E31: 3 | F31: 3 | G31: 3 | H31: =((D31*$D$5/3)+(E31*$E$5/3)+(F31*$F$5/3)+(G31*$G$5/3))*90 -> 90 | I31: 3 | J31: 3 | K31: 3 | L31: 1 | M31: =((I31*$D$5/3)+(J31*$E$5/3)+(K31*$F$5/3)+(L31*$G$5/3))*90 -> 60 | N31: 2 | O31: 3 | P31: 3 | Q31: 3 | R31: =((N31*$D$5/3)+(O31*$E$5/3)+(P31*$F$5/3)+(Q31*$G$5/3))*90 -> 87 | S31: 2 | T31: 3 | U31: 3 | V31: 3 | W31: =((S31*$D$5/3)+(T31*$E$5/3)+(U31*$F$5/3)+(V31*$G$5/3))*90 -> 87 | X31: 3 | Y31: 3 | Z31: 3 | AA31: 3 | AB31: =((X31*$D$5/3)+(Y31*$E$5/3)+(Z31*$F$5/3)+(AA31*$G$5/3))*90 -> 90 | AC31: 3 | AD31: 2 | AE31: 2 | AF31: 2 | AG31: =((AC31*$D$5/3)+(AD31*$E$5/3)+(AE31*$F$5/3)+(AF31*$G$5/3))*90 -> 63 | AH31: 2 | AI31: 3 | AJ31: 3 | AK31: 3 | AL31: =((AH31*$D$5/3)+(AI31*$E$5/3)+(AJ31*$F$5/3)+(AK31*$G$5/3))*90 -> 87 | AM31: 3 | AN31: 3 | AO31: 3 | AP31: 3 | AQ31: =((AM31*$D$5/3)+(AN31*$E$5/3)+(AO31*$F$5/3)+(AP31*$G$5/3))*90 -> 90
A32: ='INPUT DAFTAR PESERTA'!A30 -> 27 | B32: ='INPUT DAFTAR PESERTA'!B30 -> 2509056015 | C32: ='INPUT DAFTAR PESERTA'!C30 -> Tiara Aqila Azzahra | D32: 3 | E32: 3 | F32: 3 | G32: 1 | H32: =((D32*$D$5/3)+(E32*$E$5/3)+(F32*$F$5/3)+(G32*$G$5/3))*90 -> 60 | I32: 3 | J32: 3 | K32: 3 | L32: 2 | M32: =((I32*$D$5/3)+(J32*$E$5/3)+(K32*$F$5/3)+(L32*$G$5/3))*90 -> 75 | N32: 2 | O32: 3 | P32: 3 | Q32: 2 | R32: =((N32*$D$5/3)+(O32*$E$5/3)+(P32*$F$5/3)+(Q32*$G$5/3))*90 -> 72 | S32: 2 | T32: 3 | U32: 3 | V32: 3 | W32: =((S32*$D$5/3)+(T32*$E$5/3)+(U32*$F$5/3)+(V32*$G$5/3))*90 -> 87 | X32: 3 | Y32: 3 | Z32: 3 | AA32: 3 | AB32: =((X32*$D$5/3)+(Y32*$E$5/3)+(Z32*$F$5/3)+(AA32*$G$5/3))*90 -> 90 | AC32: 3 | AD32: 2 | AE32: 2 | AF32: 2 | AG32: =((AC32*$D$5/3)+(AD32*$E$5/3)+(AE32*$F$5/3)+(AF32*$G$5/3))*90 -> 63 | AH32: 2 | AI32: 3 | AJ32: 3 | AK32: 3 | AL32: =((AH32*$D$5/3)+(AI32*$E$5/3)+(AJ32*$F$5/3)+(AK32*$G$5/3))*90 -> 87 | AM32: 3 | AN32: 3 | AO32: 3 | AP32: 2 | AQ32: =((AM32*$D$5/3)+(AN32*$E$5/3)+(AO32*$F$5/3)+(AP32*$G$5/3))*90 -> 75
A33: ='INPUT DAFTAR PESERTA'!A31 -> 28 | B33: ='INPUT DAFTAR PESERTA'!B31 -> 2509056016 | C33: ='INPUT DAFTAR PESERTA'!C31 -> Muhammad Haikal Islamy Saputra | D33: 2 | E33: 2 | F33: 3 | G33: 1 | H33: =((D33*$D$5/3)+(E33*$E$5/3)+(F33*$F$5/3)+(G33*$G$5/3))*90 -> 51 | I33: 3 | J33: 3 | K33: 3 | L33: 1 | M33: =((I33*$D$5/3)+(J33*$E$5/3)+(K33*$F$5/3)+(L33*$G$5/3))*90 -> 60 | N33: 3 | O33: 3 | P33: 3 | Q33: 1 | R33: =((N33*$D$5/3)+(O33*$E$5/3)+(P33*$F$5/3)+(Q33*$G$5/3))*90 -> 60 | S33: 2 | T33: 3 | U33: 3 | V33: 2 | W33: =((S33*$D$5/3)+(T33*$E$5/3)+(U33*$F$5/3)+(V33*$G$5/3))*90 -> 72 | X33: 3 | Y33: 2 | Z33: 2 | AA33: 3 | AB33: =((X33*$D$5/3)+(Y33*$E$5/3)+(Z33*$F$5/3)+(AA33*$G$5/3))*90 -> 78 | AC33: 3 | AD33: 2 | AE33: 2 | AF33: 2 | AG33: =((AC33*$D$5/3)+(AD33*$E$5/3)+(AE33*$F$5/3)+(AF33*$G$5/3))*90 -> 63 | AH33: 2 | AI33: 3 | AJ33: 3 | AK33: 3 | AL33: =((AH33*$D$5/3)+(AI33*$E$5/3)+(AJ33*$F$5/3)+(AK33*$G$5/3))*90 -> 87 | AM33: 3 | AN33: 3 | AO33: 3 | AP33: 2 | AQ33: =((AM33*$D$5/3)+(AN33*$E$5/3)+(AO33*$F$5/3)+(AP33*$G$5/3))*90 -> 75
A34: ='INPUT DAFTAR PESERTA'!A32 -> 29 | B34: ='INPUT DAFTAR PESERTA'!B32 -> 2509056017 | C34: ='INPUT DAFTAR PESERTA'!C32 -> Faatihur Rizki | D34: 2 | E34: 2 | F34: 3 | G34: 1 | H34: =((D34*$D$5/3)+(E34*$E$5/3)+(F34*$F$5/3)+(G34*$G$5/3))*90 -> 51 | I34: 3 | J34: 3 | K34: 3 | L34: 1 | M34: =((I34*$D$5/3)+(J34*$E$5/3)+(K34*$F$5/3)+(L34*$G$5/3))*90 -> 60 | N34: 3 | O34: 3 | P34: 3 | Q34: 1 | R34: =((N34*$D$5/3)+(O34*$E$5/3)+(P34*$F$5/3)+(Q34*$G$5/3))*90 -> 60 | S34: 2 | T34: 3 | U34: 3 | V34: 1 | W34: =((S34*$D$5/3)+(T34*$E$5/3)+(U34*$F$5/3)+(V34*$G$5/3))*90 -> 57 | X34: 3 | Y34: 3 | Z34: 3 | AA34: 1 | AB34: =((X34*$D$5/3)+(Y34*$E$5/3)+(Z34*$F$5/3)+(AA34*$G$5/3))*90 -> 60 | AC34: 3 | AD34: 2 | AE34: 2 | AF34: 2 | AG34: =((AC34*$D$5/3)+(AD34*$E$5/3)+(AE34*$F$5/3)+(AF34*$G$5/3))*90 -> 63 | AH34: 2 | AI34: 3 | AJ34: 3 | AK34: 2 | AL34: =((AH34*$D$5/3)+(AI34*$E$5/3)+(AJ34*$F$5/3)+(AK34*$G$5/3))*90 -> 72 | AM34: 3 | AN34: 3 | AO34: 3 | AP34: 2 | AQ34: =((AM34*$D$5/3)+(AN34*$E$5/3)+(AO34*$F$5/3)+(AP34*$G$5/3))*90 -> 75
A35: ='INPUT DAFTAR PESERTA'!A33 -> 30 | B35: ='INPUT DAFTAR PESERTA'!B33 -> 2509056018 | C35: ='INPUT DAFTAR PESERTA'!C33 -> Rashya Annara Salsabilla Tomasoa | D35: 2 | E35: 2 | F35: 3 | G35: 2 | H35: =((D35*$D$5/3)+(E35*$E$5/3)+(F35*$F$5/3)+(G35*$G$5/3))*90 -> 66 | I35: 3 | J35: 3 | K35: 3 | L35: 3 | M35: =((I35*$D$5/3)+(J35*$E$5/3)+(K35*$F$5/3)+(L35*$G$5/3))*90 -> 90 | N35: 3 | O35: 3 | P35: 3 | Q35: 3 | R35: =((N35*$D$5/3)+(O35*$E$5/3)+(P35*$F$5/3)+(Q35*$G$5/3))*90 -> 90 | S35: 2 | T35: 3 | U35: 3 | V35: 3 | W35: =((S35*$D$5/3)+(T35*$E$5/3)+(U35*$F$5/3)+(V35*$G$5/3))*90 -> 87 | X35: 2 | Y35: 2 | Z35: 2 | AA35: 3 | AB35: =((X35*$D$5/3)+(Y35*$E$5/3)+(Z35*$F$5/3)+(AA35*$G$5/3))*90 -> 75 | AC35: 3 | AD35: 2 | AE35: 2 | AF35: 2 | AG35: =((AC35*$D$5/3)+(AD35*$E$5/3)+(AE35*$F$5/3)+(AF35*$G$5/3))*90 -> 63 | AH35: 2 | AI35: 3 | AJ35: 3 | AK35: 3 | AL35: =((AH35*$D$5/3)+(AI35*$E$5/3)+(AJ35*$F$5/3)+(AK35*$G$5/3))*90 -> 87 | AM35: 3 | AN35: 3 | AO35: 3 | AP35: 1 | AQ35: =((AM35*$D$5/3)+(AN35*$E$5/3)+(AO35*$F$5/3)+(AP35*$G$5/3))*90 -> 60
A36: ='INPUT DAFTAR PESERTA'!A34 -> 31 | B36: ='INPUT DAFTAR PESERTA'!B34 -> 2509056019 | C36: ='INPUT DAFTAR PESERTA'!C34 -> Desta Novie Sulfianie | H36: =((D36*$D$5/3)+(E36*$E$5/3)+(F36*$F$5/3)+(G36*$G$5/3))*90 -> 0 | I36: 3 | J36: 3 | K36: 3 | L36: 1 | M36: =((I36*$D$5/3)+(J36*$E$5/3)+(K36*$F$5/3)+(L36*$G$5/3))*90 -> 60 | R36: =((N36*$D$5/3)+(O36*$E$5/3)+(P36*$F$5/3)+(Q36*$G$5/3))*90 -> 0 | W36: =((S36*$D$5/3)+(T36*$E$5/3)+(U36*$F$5/3)+(V36*$G$5/3))*90 -> 0 | X36: 3 | Y36: 3 | Z36: 3 | AA36: 1 | AB36: =((X36*$D$5/3)+(Y36*$E$5/3)+(Z36*$F$5/3)+(AA36*$G$5/3))*90 -> 60 | AC36: 2 | AD36: 2 | AE36: 2 | AF36: 2 | AG36: =((AC36*$D$5/3)+(AD36*$E$5/3)+(AE36*$F$5/3)+(AF36*$G$5/3))*90 -> 60 | AL36: =((AH36*$D$5/3)+(AI36*$E$5/3)+(AJ36*$F$5/3)+(AK36*$G$5/3))*90 -> 0 | AQ36: =((AM36*$D$5/3)+(AN36*$E$5/3)+(AO36*$F$5/3)+(AP36*$G$5/3))*90 -> 0
A37: ='INPUT DAFTAR PESERTA'!A35 -> 32 | B37: ='INPUT DAFTAR PESERTA'!B35 -> 2509056020 | C37: ='INPUT DAFTAR PESERTA'!C35 -> Chandra Ahmad Dwinata | D37: 3 | E37: 3 | F37: 3 | G37: 1 | H37: =((D37*$D$5/3)+(E37*$E$5/3)+(F37*$F$5/3)+(G37*$G$5/3))*90 -> 60 | M37: =((I37*$D$5/3)+(J37*$E$5/3)+(K37*$F$5/3)+(L37*$G$5/3))*90 -> 0 | N37: 3 | O37: 3 | P37: 3 | Q37: 1 | R37: =((N37*$D$5/3)+(O37*$E$5/3)+(P37*$F$5/3)+(Q37*$G$5/3))*90 -> 60 | S37: 3 | T37: 3 | U37: 3 | V37: 1 | W37: =((S37*$D$5/3)+(T37*$E$5/3)+(U37*$F$5/3)+(V37*$G$5/3))*90 -> 60 | X37: 2 | Y37: 2 | Z37: 3 | AA37: 3 | AB37: =((X37*$D$5/3)+(Y37*$E$5/3)+(Z37*$F$5/3)+(AA37*$G$5/3))*90 -> 81 | AC37: 2 | AD37: 2 | AE37: 2 | AF37: 2 | AG37: =((AC37*$D$5/3)+(AD37*$E$5/3)+(AE37*$F$5/3)+(AF37*$G$5/3))*90 -> 60 | AH37: 3 | AI37: 3 | AJ37: 3 | AK37: 1 | AL37: =((AH37*$D$5/3)+(AI37*$E$5/3)+(AJ37*$F$5/3)+(AK37*$G$5/3))*90 -> 60 | AM37: 3 | AN37: 3 | AO37: 3 | AP37: 1 | AQ37: =((AM37*$D$5/3)+(AN37*$E$5/3)+(AO37*$F$5/3)+(AP37*$G$5/3))*90 -> 60
A38: ='INPUT DAFTAR PESERTA'!A36 -> 33 | B38: ='INPUT DAFTAR PESERTA'!B36 -> 2509056021 | C38: ='INPUT DAFTAR PESERTA'!C36 -> Sopando Imanuel Sipayung | D38: 2 | E38: 3 | F38: 3 | G38: 2 | H38: =((D38*$D$5/3)+(E38*$E$5/3)+(F38*$F$5/3)+(G38*$G$5/3))*90 -> 72 | I38: 3 | J38: 3 | K38: 3 | L38: 3 | M38: =((I38*$D$5/3)+(J38*$E$5/3)+(K38*$F$5/3)+(L38*$G$5/3))*90 -> 90 | N38: 3 | O38: 3 | P38: 3 | Q38: 2 | R38: =((N38*$D$5/3)+(O38*$E$5/3)+(P38*$F$5/3)+(Q38*$G$5/3))*90 -> 75 | S38: 3 | T38: 3 | U38: 3 | V38: 1 | W38: =((S38*$D$5/3)+(T38*$E$5/3)+(U38*$F$5/3)+(V38*$G$5/3))*90 -> 60 | X38: 3 | Y38: 2 | Z38: 3 | AA38: 3 | AB38: =((X38*$D$5/3)+(Y38*$E$5/3)+(Z38*$F$5/3)+(AA38*$G$5/3))*90 -> 84 | AC38: 2 | AD38: 2 | AE38: 2 | AF38: 2 | AG38: =((AC38*$D$5/3)+(AD38*$E$5/3)+(AE38*$F$5/3)+(AF38*$G$5/3))*90 -> 60 | AH38: 2 | AI38: 3 | AJ38: 3 | AK38: 3 | AL38: =((AH38*$D$5/3)+(AI38*$E$5/3)+(AJ38*$F$5/3)+(AK38*$G$5/3))*90 -> 87 | AM38: 3 | AN38: 3 | AO38: 3 | AP38: 1 | AQ38: =((AM38*$D$5/3)+(AN38*$E$5/3)+(AO38*$F$5/3)+(AP38*$G$5/3))*90 -> 60
A39: ='INPUT DAFTAR PESERTA'!A37 -> 34 | B39: ='INPUT DAFTAR PESERTA'!B37 -> 2509056022 | C39: ='INPUT DAFTAR PESERTA'!C37 -> Rayhan Winata Prabowo | D39: 3 | E39: 3 | F39: 3 | G39: 1 | H39: =((D39*$D$5/3)+(E39*$E$5/3)+(F39*$F$5/3)+(G39*$G$5/3))*90 -> 60 | I39: 3 | J39: 3 | K39: 3 | L39: 1 | M39: =((I39*$D$5/3)+(J39*$E$5/3)+(K39*$F$5/3)+(L39*$G$5/3))*90 -> 60 | N39: 3 | O39: 3 | P39: 3 | Q39: 2 | R39: =((N39*$D$5/3)+(O39*$E$5/3)+(P39*$F$5/3)+(Q39*$G$5/3))*90 -> 75 | S39: 3 | T39: 3 | U39: 3 | V39: 3 | W39: =((S39*$D$5/3)+(T39*$E$5/3)+(U39*$F$5/3)+(V39*$G$5/3))*90 -> 90 | X39: 2 | Y39: 3 | Z39: 3 | AA39: 1 | AB39: =((X39*$D$5/3)+(Y39*$E$5/3)+(Z39*$F$5/3)+(AA39*$G$5/3))*90 -> 57 | AC39: 2 | AD39: 2 | AE39: 2 | AF39: 2 | AG39: =((AC39*$D$5/3)+(AD39*$E$5/3)+(AE39*$F$5/3)+(AF39*$G$5/3))*90 -> 60 | AH39: 2 | AI39: 3 | AJ39: 3 | AK39: 1 | AL39: =((AH39*$D$5/3)+(AI39*$E$5/3)+(AJ39*$F$5/3)+(AK39*$G$5/3))*90 -> 57 | AM39: 3 | AN39: 3 | AO39: 3 | AP39: 2 | AQ39: =((AM39*$D$5/3)+(AN39*$E$5/3)+(AO39*$F$5/3)+(AP39*$G$5/3))*90 -> 75
A40: ='INPUT DAFTAR PESERTA'!A38 -> 35 | B40: ='INPUT DAFTAR PESERTA'!B38 -> 2509056023 | C40: ='INPUT DAFTAR PESERTA'!C38 -> Ahmad Din Nejad | D40: 3 | E40: 3 | F40: 3 | G40: 3 | H40: =((D40*$D$5/3)+(E40*$E$5/3)+(F40*$F$5/3)+(G40*$G$5/3))*90 -> 90 | I40: 3 | J40: 3 | K40: 3 | L40: 1 | M40: =((I40*$D$5/3)+(J40*$E$5/3)+(K40*$F$5/3)+(L40*$G$5/3))*90 -> 60 | R40: =((N40*$D$5/3)+(O40*$E$5/3)+(P40*$F$5/3)+(Q40*$G$5/3))*90 -> 0 | W40: =((S40*$D$5/3)+(T40*$E$5/3)+(U40*$F$5/3)+(V40*$G$5/3))*90 -> 0 | X40: 1 | Y40: 1 | Z40: 1 | AA40: 1 | AB40: =((X40*$D$5/3)+(Y40*$E$5/3)+(Z40*$F$5/3)+(AA40*$G$5/3))*90 -> 30 | AC40: 2 | AD40: 2 | AE40: 2 | AF40: 2 | AG40: =((AC40*$D$5/3)+(AD40*$E$5/3)+(AE40*$F$5/3)+(AF40*$G$5/3))*90 -> 60 | AL40: =((AH40*$D$5/3)+(AI40*$E$5/3)+(AJ40*$F$5/3)+(AK40*$G$5/3))*90 -> 0 | AQ40: =((AM40*$D$5/3)+(AN40*$E$5/3)+(AO40*$F$5/3)+(AP40*$G$5/3))*90 -> 0
A41: ='INPUT DAFTAR PESERTA'!A39 -> 36 | B41: ='INPUT DAFTAR PESERTA'!B39 -> 2509056024 | C41: ='INPUT DAFTAR PESERTA'!C39 -> Nabil Candra Hartanto | D41: 3 | E41: 3 | F41: 3 | G41: 3 | H41: =((D41*$D$5/3)+(E41*$E$5/3)+(F41*$F$5/3)+(G41*$G$5/3))*90 -> 90 | I41: 1 | J41: 1 | K41: 1 | L41: 1 | M41: =((I41*$D$5/3)+(J41*$E$5/3)+(K41*$F$5/3)+(L41*$G$5/3))*90 -> 30 | N41: 3 | O41: 3 | P41: 3 | Q41: 3 | R41: =((N41*$D$5/3)+(O41*$E$5/3)+(P41*$F$5/3)+(Q41*$G$5/3))*90 -> 90 | S41: 3 | T41: 3 | U41: 3 | V41: 1 | W41: =((S41*$D$5/3)+(T41*$E$5/3)+(U41*$F$5/3)+(V41*$G$5/3))*90 -> 60 | X41: 2 | Y41: 3 | Z41: 3 | AA41: 0 | AB41: =((X41*$D$5/3)+(Y41*$E$5/3)+(Z41*$F$5/3)+(AA41*$G$5/3))*90 -> 42 | AC41: 2 | AD41: 2 | AE41: 2 | AF41: 2 | AG41: =((AC41*$D$5/3)+(AD41*$E$5/3)+(AE41*$F$5/3)+(AF41*$G$5/3))*90 -> 60 | AH41: 2 | AI41: 3 | AJ41: 3 | AK41: 1 | AL41: =((AH41*$D$5/3)+(AI41*$E$5/3)+(AJ41*$F$5/3)+(AK41*$G$5/3))*90 -> 57 | AM41: 3 | AN41: 3 | AO41: 3 | AP41: 2 | AQ41: =((AM41*$D$5/3)+(AN41*$E$5/3)+(AO41*$F$5/3)+(AP41*$G$5/3))*90 -> 75
...

Sheet NILAI HARIAN
A3: No | B3: NIM | C3: Nama | D3: Afektif | N3: Kognitif | AF3: Psikomotorik
D4: Kehadiran | M4: Laporan | N4: Responsi | W4: Proses Asistensi | AF4: Kemampuan Praktek
D5: 1 | E5: 2 | F5: 3 | G5: 4 | H5: 5 | I5: 6 | J5: 7 | K5: 8 | L5: Rata-rata | M5: Rata-rata | N5: 1 | O5: 2 | P5: 3 | Q5: 4 | R5: 5 | S5: 6 | T5: 7 | U5: 8 | V5: Rata-rata | W5: 1 | X5: 2 | Y5: 3 | Z5: 4 | AA5: 5 | AB5: 6 | AC5: 7 | AD5: 8 | AE5: Rata-rata | AF5: 1 | AG5: 2 | AH5: 3 | AI5: 4 | AJ5: 5 | AK5: 6 | AL5: 7 | AM5: 8 | AN5: Rata-rata
